Workbook

Sheet 工單總覽
A1: BODA 工單總覽
A3: 包套(等級) | B3: B+ 基礎套裝 | E3: MSBN 額度 | F3: =IFERROR(VLOOKUP(B3,設定!$A$2:$B$12,2,FALSE),0) -> 6 | H3: 輸出時間 | I3: 46252.115
A4: 負責人 | E4: 版本 | F4: V1 | H4: 更新重點
A5: 活動時間 | E5: 美術 Deadline | H5: 總製作張數 | I5: =SUM(C19:C30)+9 -> 14
A6: 工作項目名稱 | E6: 行銷目標
A7: 目標客群
A9: 曝光資源共用文案與色彩
A10: 背景顏色 | B10: #ff3322 | E10: 連動規則 | F10: 與「曝光資源」背景色、匯入工單統一背景及 MSBN D 系列卡片背景同步；此處記錄匯出當下色號。
A11: 品牌名 | E11: 上限 9 | F11: 曝光資源品牌名稱；中文 1、英數 0.5。 | I11: =IF(B11="","",IF(LENB(B11)/2<=9,"OK","超過"))
A12: 主標 | B12: 歡慶母親節促銷 | E12: 上限 8 | F12: 曝光資源主標；中文 1、英數 0.5。 | I12: =IF(B12="","",IF(LENB(B12)/2<=8,"OK","超過")) -> OK
A13: 副標 | B13: 滿$299享5折 | E13: 上限 7 | F13: 曝光資源副標；中文 1、英數 0.5。 | I13: =IF(B13="","",IF(LENB(B13)/2<=7,"OK","超過")) -> OK
A14: 日期／警語 | B14: 3/8 只限今天 | E14: 上限 14 | F14: 日期、活動期間或警語；中文 1、英數 0.5。 | I14: =IF(B14="","",IF(LENB(B14)/2<=14,"OK","超過")) -> OK
A15: ICON 獨立文案 | E15: 上限 2 | F15: Search ICON 文字版；也可改用 LOGO／商品圖；中文 1、英數 0.5。 | I15: =IF(B15="","",IF(LENB(B15)/2<=2,"OK","超過"))
A17: 製作曝光資源（依包套／等級自動切換；預設張數可手動調整，選配預設為 0）
A18: 版位 | B18: 類型 | C18: 張數 | D18: 尺寸 | E18: 格式 | F18: 規範字數 | G18: 提醒 | H18: 系統排版 | I18: Check
A19: =IFERROR(INDEX(設定!$C$2:$N$12,MATCH($B$3,設定!$A$2:$A$12,0),1),"") -> DDCard | B19: =IFERROR(INDEX(設定!$O$2:$Z$12,MATCH($B$3,設定!$A$2:$A$12,0),1),"") -> 預設 | C19: =IF(A19="","",IF(B19="預設",1,0)) -> 1 | D19: =IF(A19="","",IFERROR(VLOOKUP(A19,設定!$AB$2:$AJ$13,4,FALSE),"")) -> 531×792 | E19: =IF(A19="","",IFERROR(VLOOKUP(A19,設定!$AB$2:$AJ$13,5,FALSE),"")) -> JPG | F19: =IF(A19="","",IFERROR(VLOOKUP(A19,設定!$AB$2:$AJ$13,6,FALSE),"")) -> 品牌名≤9；主標≤8；副標≤7；日期/警語≤14 | G19: =IF(A19="","",IFERROR(VLOOKUP(A19,設定!$AB$2:$AJ$13,7,FALSE),"")) -> LOGO、商品圖；CTA 依版型 | H19: =IF(A19="","",IFERROR(VLOOKUP(A19,設定!$AB$2:$AJ$13,8,FALSE),"尚未提供版型")) -> ddcard方logo／ddcard橫logo | I19: =IF(A19="","",IF(C19=0,"未選",IF(H19="尚未提供版型","缺版型","待製作"))) -> 待製作
A20: =IFERROR(INDEX(設定!$C$2:$N$12,MATCH($B$3,設定!$A$2:$A$12,0),2),"") -> HBN | B20: =IFERROR(INDEX(設定!$O$2:$Z$12,MATCH($B$3,設定!$A$2:$A$12,0),2),"") -> 預設 | C20: =IF(A20="","",IF(B20="預設",1,0)) -> 1 | D20: =IF(A20="","",IFERROR(VLOOKUP(A20,設定!$AB$2:$AJ$13,4,FALSE),"")) -> 1200×360 | E20: =IF(A20="","",IFERROR(VLOOKUP(A20,設定!$AB$2:$AJ$13,5,FALSE),"")) -> JPG | F20: =IF(A20="","",IFERROR(VLOOKUP(A20,設定!$AB$2:$AJ$13,6,FALSE),"")) -> 品牌名≤9；主標≤8；副標≤7；日期/警語≤14 | G20: =IF(A20="","",IFERROR(VLOOKUP(A20,設定!$AB$2:$AJ$13,7,FALSE),"")) -> 橫式或方形 LOGO 版 | H20: =IF(A20="","",IFERROR(VLOOKUP(A20,設定!$AB$2:$AJ$13,8,FALSE),"尚未提供版型")) -> HBN_橫式LOGO／HBN_方式LOGO | I20: =IF(A20="","",IF(C20=0,"未選",IF(H20="尚未提供版型","缺版型","待製作"))) -> 待製作
A21: =IFERROR(INDEX(設定!$C$2:$N$12,MATCH($B$3,設定!$A$2:$A$12,0),3),"") -> 活動總覽 | B21: =IFERROR(INDEX(設定!$O$2:$Z$12,MATCH($B$3,設定!$A$2:$A$12,0),3),"") -> 預設 | C21: =IF(A21="","",IF(B21="預設",1,0)) -> 1 | D21: =IF(A21="","",IFERROR(VLOOKUP(A21,設定!$AB$2:$AJ$13,4,FALSE),"")) -> 依活動規格 | E21: =IF(A21="","",IFERROR(VLOOKUP(A21,設定!$AB$2:$AJ$13,5,FALSE),"")) -> JPG/PNG | F21: =IF(A21="","",IFERROR(VLOOKUP(A21,設定!$AB$2:$AJ$13,6,FALSE),"")) -> 依活動需求 | G21: =IF(A21="","",IFERROR(VLOOKUP(A21,設定!$AB$2:$AJ$13,7,FALSE),"")) -> 目前系統尚未提供可編輯版型 | H21: =IF(A21="","",IFERROR(VLOOKUP(A21,設定!$AB$2:$AJ$13,8,FALSE),"尚未提供版型")) -> 尚未提供版型 | I21: =IF(A21="","",IF(C21=0,"未選",IF(H21="尚未提供版型","缺版型","待製作"))) -> 缺版型
A22: =IFERROR(INDEX(設定!$C$2:$N$12,MATCH($B$3,設定!$A$2:$A$12,0),4),"") -> 首頁LOGO牆 | B22: =IFERROR(INDEX(設定!$O$2:$Z$12,MATCH($B$3,設定!$A$2:$A$12,0),4),"") -> 預設 | C22: =IF(A22="","",IF(B22="預設",1,0)) -> 1 | D22: =IF(A22="","",IFERROR(VLOOKUP(A22,設定!$AB$2:$AJ$13,4,FALSE),"")) -> 依活動規格 | E22: =IF(A22="","",IFERROR(VLOOKUP(A22,設定!$AB$2:$AJ$13,5,FALSE),"")) -> JPG/PNG | F22: =IF(A22="","",IFERROR(VLOOKUP(A22,設定!$AB$2:$AJ$13,6,FALSE),"")) -> LOGO 依活動規範 | G22: =IF(A22="","",IFERROR(VLOOKUP(A22,設定!$AB$2:$AJ$13,7,FALSE),"")) -> 目前系統尚未提供可編輯版型 | H22: =IF(A22="","",IFERROR(VLOOKUP(A22,設定!$AB$2:$AJ$13,8,FALSE),"尚未提供版型")) -> 尚未提供版型 | I22: =IF(A22="","",IF(C22=0,"未選",IF(H22="尚未提供版型","缺版型","待製作"))) -> 缺版型
A23: =IFERROR(INDEX(設定!$C$2:$N$12,MATCH($B$3,設定!$A$2:$A$12,0),5),"") -> AR | B23: =IFERROR(INDEX(設定!$O$2:$Z$12,MATCH($B$3,設定!$A$2:$A$12,0),5),"") -> 預設 | C23: =IF(A23="","",IF(B23="預設",1,0)) -> 1 | D23: =IF(A23="","",IFERROR(VLOOKUP(A23,設定!$AB$2:$AJ$13,4,FALSE),"")) -> 100×100（依規範） | E23: =IF(A23="","",IFERROR(VLOOKUP(A23,設定!$AB$2:$AJ$13,5,FALSE),"")) -> JPG/PNG | F23: =IF(A23="","",IFERROR(VLOOKUP(A23,設定!$AB$2:$AJ$13,6,FALSE),"")) -> 文案≤6 或 LOGO；2擇1 | G23: =IF(A23="","",IFERROR(VLOOKUP(A23,設定!$AB$2:$AJ$13,7,FALSE),"")) -> 目前系統尚未提供可編輯版型 | H23: =IF(A23="","",IFERROR(VLOOKUP(A23,設定!$AB$2:$AJ$13,8,FALSE),"尚未提供版型")) -> 尚未提供版型 | I23: =IF(A23="","",IF(C23=0,"未選",IF(H23="尚未提供版型","缺版型","待製作"))) -> 缺版型
A24: =IFERROR(INDEX(設定!$C$2:$N$12,MATCH($B$3,設定!$A$2:$A$12,0),6),"") -> FB_Post | B24: =IFERROR(INDEX(設定!$O$2:$Z$12,MATCH($B$3,設定!$A$2:$A$12,0),6),"") -> 選配 | C24: =IF(A24="","",IF(B24="預設",1,0)) -> 0 | D24: =IF(A24="","",IFERROR(VLOOKUP(A24,設定!$AB$2:$AJ$13,4,FALSE),"")) -> 1200×630 | E24: =IF(A24="","",IFERROR(VLOOKUP(A24,設定!$AB$2:$AJ$13,5,FALSE),"")) -> JPG | F24: =IF(A24="","",IFERROR(VLOOKUP(A24,設定!$AB$2:$AJ$13,6,FALSE),"")) -> 品牌名≤9；主標≤8；副標≤7；日期/警語≤14 | G24: =IF(A24="","",IFERROR(VLOOKUP(A24,設定!$AB$2:$AJ$13,7,FALSE),"")) -> 方 LOGO／橫 LOGO | H24: =IF(A24="","",IFERROR(VLOOKUP(A24,設定!$AB$2:$AJ$13,8,FALSE),"尚未提供版型")) -> FB_POST_方LOGO／FB_POST_橫LOGO | I24: =IF(A24="","",IF(C24=0,"未選",IF(H24="尚未提供版型","缺版型","待製作"))) -> 未選
A25: =IFERROR(INDEX(設定!$C$2:$N$12,MATCH($B$3,設定!$A$2:$A$12,0),7),"") -> AMS BN | B25: =IFERROR(INDEX(設定!$O$2:$Z$12,MATCH($B$3,設定!$A$2:$A$12,0),7),"") -> 選配 | C25: =IF(A25="","",IF(B25="預設",1,0)) -> 0 | D25: =IF(A25="","",IFERROR(VLOOKUP(A25,設定!$AB$2:$AJ$13,4,FALSE),"")) -> 1077×264（依規範） | E25: =IF(A25="","",IFERROR(VLOOKUP(A25,設定!$AB$2:$AJ$13,5,FALSE),"")) -> JPG | F25: =IF(A25="","",IFERROR(VLOOKUP(A25,設定!$AB$2:$AJ$13,6,FALSE),"")) -> 依 AMS 規格 | G25: =IF(A25="","",IFERROR(VLOOKUP(A25,設定!$AB$2:$AJ$13,7,FALSE),"")) -> 目前系統尚未提供可編輯版型 | H25: =IF(A25="","",IFERROR(VLOOKUP(A25,設定!$AB$2:$AJ$13,8,FALSE),"尚未提供版型")) -> 尚未提供版型 | I25: =IF(A25="","",IF(C25=0,"未選",IF(H25="尚未提供版型","缺版型","待製作"))) -> 未選
A26: =IFERROR(INDEX(設定!$C$2:$N$12,MATCH($B$3,設定!$A$2:$A$12,0),8),"") -> Coin_page | B26: =IFERROR(INDEX(設定!$O$2:$Z$12,MATCH($B$3,設定!$A$2:$A$12,0),8),"") -> 選配 | C26: =IF(A26="","",IF(B26="預設",1,0)) -> 0 | D26: =IF(A26="","",IFERROR(VLOOKUP(A26,設定!$AB$2:$AJ$13,4,FALSE),"")) -> 1200×391 | E26: =IF(A26="","",IFERROR(VLOOKUP(A26,設定!$AB$2:$AJ$13,5,FALSE),"")) -> JPG | F26: =IF(A26="","",IFERROR(VLOOKUP(A26,設定!$AB$2:$AJ$13,6,FALSE),"")) -> 品牌名≤9；主標≤8；副標≤7；日期/警語≤14 | G26: =IF(A26="","",IFERROR(VLOOKUP(A26,設定!$AB$2:$AJ$13,7,FALSE),"")) -> 方 LOGO／橫 LOGO | H26: =IF(A26="","",IFERROR(VLOOKUP(A26,設定!$AB$2:$AJ$13,8,FALSE),"尚未提供版型")) -> Coin_pageBN_APP方LOGO／Coin_pageBN_APP橫LOGO | I26: =IF(A26="","",IF(C26=0,"未選",IF(H26="尚未提供版型","缺版型","待製作"))) -> 未選
A27: =IFERROR(INDEX(設定!$C$2:$N$12,MATCH($B$3,設定!$A$2:$A$12,0),9),"") -> IG | B27: =IFERROR(INDEX(設定!$O$2:$Z$12,MATCH($B$3,設定!$A$2:$A$12,0),9),"") -> 選配 | C27: =IF(A27="","",IF(B27="預設",1,0)) -> 0 | D27: =IF(A27="","",IFERROR(VLOOKUP(A27,設定!$AB$2:$AJ$13,4,FALSE),"")) -> 900×1600 | E27: =IF(A27="","",IFERROR(VLOOKUP(A27,設定!$AB$2:$AJ$13,5,FALSE),"")) -> JPG | F27: =IF(A27="","",IFERROR(VLOOKUP(A27,設定!$AB$2:$AJ$13,6,FALSE),"")) -> 品牌名≤9；主標≤8；副標≤7；日期/警語≤14 | G27: =IF(A27="","",IFERROR(VLOOKUP(A27,設定!$AB$2:$AJ$13,7,FALSE),"")) -> 方 LOGO／橫 LOGO | H27: =IF(A27="","",IFERROR(VLOOKUP(A27,設定!$AB$2:$AJ$13,8,FALSE),"尚未提供版型")) -> IG方logo排版／IG橫logo排版 | I27: =IF(A27="","",IF(C27=0,"未選",IF(H27="尚未提供版型","缺版型","待製作"))) -> 未選
A28: =IFERROR(INDEX(設定!$C$2:$N$12,MATCH($B$3,設定!$A$2:$A$12,0),10),"") | B28: =IFERROR(INDEX(設定!$O$2:$Z$12,MATCH($B$3,設定!$A$2:$A$12,0),10),"") | C28: =IF(A28="","",IF(B28="預設",1,0)) | D28: =IF(A28="","",IFERROR(VLOOKUP(A28,設定!$AB$2:$AJ$13,4,FALSE),"")) | E28: =IF(A28="","",IFERROR(VLOOKUP(A28,設定!$AB$2:$AJ$13,5,FALSE),"")) | F28: =IF(A28="","",IFERROR(VLOOKUP(A28,設定!$AB$2:$AJ$13,6,FALSE),"")) | G28: =IF(A28="","",IFERROR(VLOOKUP(A28,設定!$AB$2:$AJ$13,7,FALSE),"")) | H28: =IF(A28="","",IFERROR(VLOOKUP(A28,設定!$AB$2:$AJ$13,8,FALSE),"尚未提供版型")) | I28: =IF(A28="","",IF(C28=0,"未選",IF(H28="尚未提供版型","缺版型","待製作")))
A29: =IFERROR(INDEX(設定!$C$2:$N$12,MATCH($B$3,設定!$A$2:$A$12,0),11),"") | B29: =IFERROR(INDEX(設定!$O$2:$Z$12,MATCH($B$3,設定!$A$2:$A$12,0),11),"") | C29: =IF(A29="","",IF(B29="預設",1,0)) | D29: =IF(A29="","",IFERROR(VLOOKUP(A29,設定!$AB$2:$AJ$13,4,FALSE),"")) | E29: =IF(A29="","",IFERROR(VLOOKUP(A29,設定!$AB$2:$AJ$13,5,FALSE),"")) | F29: =IF(A29="","",IFERROR(VLOOKUP(A29,設定!$AB$2:$AJ$13,6,FALSE),"")) | G29: =IF(A29="","",IFERROR(VLOOKUP(A29,設定!$AB$2:$AJ$13,7,FALSE),"")) | H29: =IF(A29="","",IFERROR(VLOOKUP(A29,設定!$AB$2:$AJ$13,8,FALSE),"尚未提供版型")) | I29: =IF(A29="","",IF(C29=0,"未選",IF(H29="尚未提供版型","缺版型","待製作")))
A30: =IFERROR(INDEX(設定!$C$2:$N$12,MATCH($B$3,設定!$A$2:$A$12,0),12),"") | B30: =IFERROR(INDEX(設定!$O$2:$Z$12,MATCH($B$3,設定!$A$2:$A$12,0),12),"") | C30: =IF(A30="","",IF(B30="預設",1,0)) | D30: =IF(A30="","",IFERROR(VLOOKUP(A30,設定!$AB$2:$AJ$13,4,FALSE),"")) | E30: =IF(A30="","",IFERROR(VLOOKUP(A30,設定!$AB$2:$AJ$13,5,FALSE),"")) | F30: =IF(A30="","",IFERROR(VLOOKUP(A30,設定!$AB$2:$AJ$13,6,FALSE),"")) | G30: =IF(A30="","",IFERROR(VLOOKUP(A30,設定!$AB$2:$AJ$13,7,FALSE),"")) | H30: =IF(A30="","",IFERROR(VLOOKUP(A30,設定!$AB$2:$AJ$13,8,FALSE),"尚未提供版型")) | I30: =IF(A30="","",IF(C30=0,"未選",IF(H30="尚未提供版型","缺版型","待製作")))
A33: 本次工單版配（來源：工單生成器畫布；內容欄請至 MS Layout 填寫）
A34: 類型 | B34: 版位名稱 | C34: Band | D34: 位置數 | E34: 素材檔案 | F34: 字數／欄位規則 | G34: 提醒 | H34: MS Layout | I34: Check
A35: 副區 | B35: 款式 1-2 | C35: 1 | D35: 1 | E35: 副區-A-1-2.jpg | F35: 限8個字；(檔名/券名) | G35: 綠色欄位可填；固定欄位已鎖 | H35: 第 3 列 | I35: 待填
A36: 副區 | B36: 款式 2-2 | C36: 1 | D36: 1 | E36: 副區-A-2-2.jpg | F36: 限8個字；(檔名/券名)；限5個字 | G36: 綠色欄位可填；固定欄位已鎖 | H36: 第 12 列 | I36: 待填
A37: 副區 | B37: 款式 4-1 | C37: 1 | D37: 1 | E37: 副區-A-4-1.jpg | F37: 限8個字；(檔名/券名)；限4+4個字；限5個字；限3個字 | G37: 綠色欄位可填；固定欄位已鎖 | H37: 第 21 列 | I37: 待填
A38: MSBN | B38: A-2-3 | C38: 2 | D38: 2 | E38: MSBN-A-2-3.jpg | F38: 促標6個字內；(圖檔名)；品名一排最多8字；圓標05字內 | G38: 綠色欄位可填；固定欄位已鎖 | H38: 第 30 列 | I38: 待填
A39: MSBN | B39: A-3-1 | C39: 3 | D39: 3 | E39: MSBN-A-3-1.jpg | F39: (圖檔名)；(檔名)；圓標05字內；品名一排7字內 | G39: 綠色欄位可填；固定欄位已鎖 | H39: 第 39 列 | I39: 待填
A40: MSBN | B40: B-2-2 | C40: 4 | D40: 2 | E40: MSBN-B-2-2.jpg | F40: 促標最多8個字內；(圖檔名)；品名最多可以放10個字；特色最多放8個字 | G40: 綠色欄位可填；固定欄位已鎖 | H40: 第 48 列 | I40: 待填
A41: MSBN | B41: B-3-3 | C41: 5 | D41: 3 | E41: MSBN-B-3-3.jpg | F41: (檔名/券名)；品名一排7字內；逛逛去 | G41: 綠色欄位可填；固定欄位已鎖 | H41: 第 57 列 | I41: 待填
A42: MSBN | B42: B-4-2 | C42: 6 | D42: 4 | E42: MSBN-B-4-2.jpg | F42: 促標5字內；(圖檔名)；品名5字內；小字警語6字 | G42: 綠色欄位可填；固定欄位已鎖 | H42: 第 66 列 | I42: 待填
A43: MSBN | B43: C-1-4 | C43: 7 | D43: 1 | E43: MSBN-C-1-4.jpg | F43: 促標最多6字；文案一排4字；領券去；(檔名)；刷卡去 | G43: 綠色欄位可填；固定欄位已鎖 | H43: 第 75 列 | I43: 待填

Sheet MS Layout
A1: 素材名稱 | B1: 版位／規格 | C1: Layout（綠色欄位可填；固定欄位與規則已鎖定） | T1: 視覺參考（目前系統實際版位）
C2: 中文 1 字、英數與半形符號 0.5 字；超過限制會阻擋輸入並標紅 | T2: 圖片僅供版配與欄位位置對照，不代表最終正式稿
A3: 副區 | B3: 款式 1-2 A-1-2 Band 1 | C3: 單格 | G3: — | K3: — | O3: — | T3: 款式 1-2
C4: 促標 | D4: 滿$299享8折 | F4: =IF(D4="","",IF(LENB(D4)/2<=8,"OK","超過")) -> OK
C5: LOGO圖 | D5: apple.png | F5: =IF(D5="","待填","OK") -> OK
C6: 商品 (多圖用逗號分開) | D6: 2026-05-19 11 49 59-Photoroom.png | F6: =IF(D6="","待填","OK") -> OK
C7: 品名 | D7: iphone18plus | F7: =IF(D7="","",IF(LENB(D7)/2<=8,"OK","超過")) -> OK
C10: 素材路徑：img/副區-A-1-2.jpg ｜ 字數限制以各欄提示為準；綠色內容欄可編輯，欄位名、Check、固定 icon 與示意圖已鎖定。
A12: 副區 | B12: 款式 2-2 A-2-2 Band 1 | C12: 單格 | G12: — | K12: — | O12: — | T12: 款式 2-2
C13: 促標 | D13: 滿$299享8折 | F13: =IF(D13="","",IF(LENB(D13)/2<=8,"OK","超過")) -> OK
C14: LOGO圖 | D14: POLYWELL logo new.png | F14: =IF(D14="","待填","OK") -> OK
C15: 商品 (多圖用逗號分開) | D15: a.jpg,b.jpg | F15: =IF(D15="","待填","OK") -> OK
C16: 品名 | D16: iphone18plus | F16: =IF(D16="","",IF(LENB(D16)/2<=8,"OK","超過")) -> OK
C17: 圓標 | D17: 享5折 | F17: =IF(D17="","",IF(LENB(D17)/2<=5,"OK","超過")) -> OK
C19: 素材路徑：img/副區-A-2-2.jpg ｜ 字數限制以各欄提示為準；綠色內容欄可編輯，欄位名、Check、固定 icon 與示意圖已鎖定。
A21: 副區 | B21: 款式 4-1 A-4-1 Band 1 | C21: 單格 | G21: — | K21: — | O21: — | T21: 款式 4-1
C22: 促標 | D22: 滿$299享8折 | F22: =IF(D22="","",IF(LENB(D22)/2<=8,"OK","超過")) -> OK
C23: LOGO圖 | D23: SAMPO 640X360-Photoroom.png | F23: =IF(D23="","待填","OK") -> OK
C24: 商品 (多圖用逗號分開) | D24: iphone17.png,iPhone19 PLUS.png | F24: =IF(D24="","待填","OK") -> OK
C25: 品名 | F25: =IF(D25="","",IF(LENB(D25)/2<=4,"OK","超過"))
C26: 警語 | F26: =IF(D26="","",IF(LENB(D26)/2<=5,"OK","超過"))
C27: CTA | F27: =IF(D27="","",IF(LENB(D27)/2<=3,"OK","超過"))
C28: 素材路徑：img/副區-A-4-1.jpg ｜ 字數限制以各欄提示為準；綠色內容欄可編輯，欄位名、Check、固定 icon 與示意圖已鎖定。
A30: MSBN | B30: A-2-3 MSBN-A-2-3 Band 2 | C30: 左 | G30: 右 | K30: — | O30: — | T30: A-2-3
C31: 促標 | F31: =IF(D31="","",IF(LENB(D31)/2<=6,"OK","超過")) | G31: 促標 | J31: =IF(H31="","",IF(LENB(H31)/2<=6,"OK","超過"))
C32: 商品 (多圖用逗號分開) | F32: =IF(D32="","待填","OK") -> 待填 | G32: 商品 (多圖用逗號分開) | J32: =IF(H32="","待填","OK") -> 待填
C33: 品名 | F33: =IF(D33="","",IF(LENB(D33)/2<=8,"OK","超過")) | G33: 品名 | J33: =IF(H33="","",IF(LENB(H33)/2<=8,"OK","超過"))
C34: 品名 | F34: =IF(D34="","",IF(LENB(D34)/2<=8,"OK","超過")) | G34: 品名 | J34: =IF(H34="","",IF(LENB(H34)/2<=8,"OK","超過"))
C35: 圓標 | F35: =IF(D35="","",IF(LENB(D35)/2<=5,"OK","超過")) | G35: 圓標 | J35: =IF(H35="","",IF(LENB(H35)/2<=5,"OK","超過"))
C37: 素材路徑：msbn-img/MSBN-A-2-3.jpg ｜ 字數限制以各欄提示為準；綠色內容欄可編輯，欄位名、Check、固定 icon 與示意圖已鎖定。
A39: MSBN | B39: A-3-1 MSBN-A-3-1 Band 3 | C39: 左 | G39: 中 | K39: 右 | O39: — | T39: A-3-1
C40: 商品 (多圖用逗號分開) | F40: =IF(D40="","待填","OK") -> 待填 | G40: 商品 (多圖用逗號分開) | J40: =IF(H40="","待填","OK") -> 待填 | K40: 商品 (多圖用逗號分開) | N40: =IF(L40="","待填","OK") -> 待填
C41: 贈品圖 | F41: =IF(D41="","待填","OK") -> 待填 | G41: 贈品圖 | J41: =IF(H41="","待填","OK") -> 待填 | K41: 贈品圖 | N41: =IF(L41="","待填","OK") -> 待填
C42: 圓標 | F42: =IF(D42="","",IF(LENB(D42)/2<=5,"OK","超過")) | G42: 圓標 | J42: =IF(H42="","",IF(LENB(H42)/2<=5,"OK","超過")) | K42: 圓標 | N42: =IF(L42="","",IF(LENB(L42)/2<=5,"OK","超過"))
C43: 品名 | F43: =IF(D43="","",IF(LENB(D43)/2<=7,"OK","超過")) | G43: 品名 | J43: =IF(H43="","",IF(LENB(H43)/2<=7,"OK","超過")) | K43: 品名 | N43: =IF(L43="","",IF(LENB(L43)/2<=7,"OK","超過"))
C46: 素材路徑：msbn-img/MSBN-A-3-1.jpg ｜ 字數限制以各欄提示為準；綠色內容欄可編輯，欄位名、Check、固定 icon 與示意圖已鎖定。
A48: MSBN | B48: B-2-2 MSBN-B-2-2 Band 4 | C48: 右 | G48: 左 | K48: — | O48: — | T48: B-2-2
C49: 促標 | F49: =IF(D49="","",IF(LENB(D49)/2<=8,"OK","超過")) | G49: 促標 | J49: =IF(H49="","",IF(LENB(H49)/2<=8,"OK","超過"))
C50: 商品 (多圖用逗號分開) | F50: =IF(D50="","待填","OK") -> 待填 | G50: 商品 (多圖用逗號分開) | J50: =IF(H50="","待填","OK") -> 待填
C51: 品名 | F51: =IF(D51="","",IF(LENB(D51)/2<=10,"OK","超過")) | G51: 品名 | J51: =IF(H51="","",IF(LENB(H51)/2<=10,"OK","超過"))
...

Sheet 設定
A1: 等級 | B1: MSBN額度 | C1: 資源1 | D1: 資源2 | E1: 資源3 | F1: 資源4 | G1: 資源5 | H1: 資源6 | I1: 資源7 | J1: 資源8 | K1: 資源9 | L1: 資源10 | M1: 資源11 | N1: 資源12 | O1: 類型1 | P1: 類型2 | Q1: 類型3 | R1: 類型4 | S1: 類型5 | T1: 類型6 | U1: 類型7 | V1: 類型8 | W1: 類型9 | X1: 類型10 | Y1: 類型11 | Z1: 類型12 | AB1: key | AC1: 顯示名稱 | AD1: 張數 | AE1: 尺寸 | AF1: 格式 | AG1: 規範字數 | AH1: 提醒 | AI1: 系統排版 | AJ1: 可用
A2: A Brand star (Mega) | B2: 8 | AB2: DDCard | AC2: DD Card BN (APP) | AD2: 1 | AE2: 531×792 | AF2: JPG | AG2: 品牌名≤9；主標≤8；副標≤7；日期/警語≤14 | AH2: LOGO、商品圖；CTA 依版型 | AI2: ddcard方logo／ddcard橫logo | AJ2: 是
A3: A Brand star (Mega) 資交 | B3: 4 | AB3: HBN | AC3: HBN (PC) | AD3: 1 | AE3: 1200×360 | AF3: JPG | AG3: 品牌名≤9；主標≤8；副標≤7；日期/警語≤14 | AH3: 橫式或方形 LOGO 版 | AI3: HBN_橫式LOGO／HBN_方式LOGO | AJ3: 是
A4: A 精選套裝 | B4: 4 | AB4: 活動總覽 | AC4: 活動總覽 | AD4: 1 | AE4: 依活動規格 | AF4: JPG/PNG | AG4: 依活動需求 | AH4: 目前系統尚未提供可編輯版型 | AI4: 尚未提供版型 | AJ4: 否
A5: A 品牌旗艦MDD | B5: 6 | AB5: 首頁LOGO牆 | AC5: 首頁 LOGO 牆 | AD5: 1 | AE5: 依活動規格 | AF5: JPG/PNG | AG5: LOGO 依活動規範 | AH5: 目前系統尚未提供可編輯版型 | AI5: 尚未提供版型 | AJ5: 否
A6: A 品牌旗艦MDD 資交 | B6: 0 | AB6: AR | AC6: AR | AD6: 1 | AE6: 100×100（依規範） | AF6: JPG/PNG | AG6: 文案≤6 或 LOGO；2擇1 | AH6: 目前系統尚未提供可編輯版型 | AI6: 尚未提供版型 | AJ6: 否
A7: B+ BOD A | B7: 6 | C7: DDCard | D7: HBN | E7: 活動總覽 | F7: 首頁LOGO牆 | G7: AR | H7: FB_Post | I7: AMS BN | J7: Coin_page | K7: IG | L7: SearchIcon | M7: SearchImage | O7: 預設 | P7: 預設 | Q7: 預設 | R7: 預設 | S7: 預設 | T7: 預設 | U7: 預設 | V7: 選配 | W7: 選配 | X7: 選配 | Y7: 選配 | AB7: FB_Post | AC7: FB POST | AD7: 1 | AE7: 1200×630 | AF7: JPG | AG7: 品牌名≤9；主標≤8；副標≤7；日期/警語≤14 | AH7: 方 LOGO／橫 LOGO | AI7: FB_POST_方LOGO／FB_POST_橫LOGO | AJ7: 是
A8: B+ BOD A 資交 | B8: 0 | C8: DDCard | D8: HBN | E8: 活動總覽 | F8: 首頁LOGO牆 | G8: AR | H8: FB_Post | I8: AMS BN | J8: Coin_page | K8: IG | L8: SearchIcon | M8: SearchImage | O8: 預設 | P8: 預設 | Q8: 預設 | R8: 預設 | S8: 預設 | T8: 預設 | U8: 預設 | V8: 選配 | W8: 選配 | X8: 選配 | Y8: 選配 | AB8: AMS BN | AC8: AMS BN | AD8: 1 | AE8: 1077×264（依規範） | AF8: JPG | AG8: 依 AMS 規格 | AH8: 目前系統尚未提供可編輯版型 | AI8: 尚未提供版型 | AJ8: 否
A9: B+ BOD B (Mega) | B9: 6 | C9: DDCard | D9: HBN | E9: 活動總覽 | F9: 首頁LOGO牆 | G9: AR | H9: FB_Post | I9: AMS BN | J9: Coin_page | K9: IG | O9: 預設 | P9: 預設 | Q9: 預設 | R9: 預設 | S9: 預設 | T9: 選配 | U9: 選配 | V9: 選配 | W9: 選配 | AB9: Coin_page | AC9: Coin Page BN | AD9: 1 | AE9: 1200×391 | AF9: JPG | AG9: 品牌名≤9；主標≤8；副標≤7；日期/警語≤14 | AH9: 方 LOGO／橫 LOGO | AI9: Coin_pageBN_APP方LOGO／Coin_pageBN_APP橫LOGO | AJ9: 是
A10: B+ 基礎套裝 | B10: 6 | C10: DDCard | D10: HBN | E10: 活動總覽 | F10: 首頁LOGO牆 | G10: AR | H10: FB_Post | I10: AMS BN | J10: Coin_page | K10: IG | O10: 預設 | P10: 預設 | Q10: 預設 | R10: 預設 | S10: 預設 | T10: 選配 | U10: 選配 | V10: 選配 | W10: 選配 | AB10: IG | AC10: IG | AD10: 1 | AE10: 900×1600 | AF10: JPG | AG10: 品牌名≤9；主標≤8；副標≤7；日期/警語≤14 | AH10: 方 LOGO／橫 LOGO | AI10: IG方logo排版／IG橫logo排版 | AJ10: 是
A11: B JBP多店 | B11: 3 | C11: IG | D11: HBN | E11: DDCard | F11: Coin_page | G11: FB_Post | H11: SCPN | I11: SearchImage | J11: SearchIcon | O11: 預設 | P11: 預設 | Q11: 預設 | R11: 預設 | S11: 預設 | T11: 預設 | U11: 預設 | V11: 預設 | AB11: SearchIcon | AC11: Search ICON | AD11: 1 | AE11: 120×120＋84×84 | AF11: PNG | AG11: ICON 文案≤2；或 LOGO／商品圖 | AH11: 120×120 建議 <50KB，另輸出 84×84 | AI11: SearchICON_LOGO／PRODUCT／TEXT | AJ11: 是
A12: B 金牌 (Mega) | B12: 3 | C12: DDCard | D12: HBN | E12: 活動總覽 | F12: AR | G12: Coin_page | O12: 預設 | P12: 預設 | Q12: 預設 | R12: 預設 | S12: 選配 | AB12: SearchImage | AC12: Search Image | AD12: 1 | AE12: 1125×156 | AF12: JPG/PNG | AG12: 副標≤7；LOGO 1～3 個 | AH12: 依選用版型提供 1～3 個 LOGO | AI12: Search_Image1logo／2logo／3logo | AJ12: 是
AB13: SCPN | AC13: SCBN／SCPN | AD13: 1 | AE13: 1200×200 | AF13: JPG | AG13: 品牌名≤9；副標≤7；CTA | AH13: 商城橫幅 | AI13: SCBN_APP | AJ13: 是

Sheet _BODA_META
A1: BODA_WORKORDER_V2
A2: kind | B2: sourceKey | C2: band | D2: order | E2: family | F2: variant | G2: combo | H2: msbnFile | I2: position | J2: label | K2: address | L2: header | M2: file | N2: locked | O2: hint
A3: subarea | B3: top:0 | C3: 1 | D3: 1 | E3: A | F3: 1 | G3: 2 | I3: 1 | J3: 促標 | K3: D4 | L3: 款式 1-2 | M3: 副區-A-1-2.jpg | N3: 0 | O3: 限8個字
A4: subarea | B4: top:0 | C4: 1 | D4: 1 | E4: A | F4: 1 | G4: 2 | I4: 1 | J4: LOGO圖 | K4: D5 | L4: 款式 1-2 | M4: 副區-A-1-2.jpg | N4: 0 | O4: (檔名/券名)
A5: subarea | B5: top:0 | C5: 1 | D5: 1 | E5: A | F5: 1 | G5: 2 | I5: 1 | J5: 商品 | K5: D6 | L5: 款式 1-2 | M5: 副區-A-1-2.jpg | N5: 0 | O5: (檔名/券名)
A6: subarea | B6: top:0 | C6: 1 | D6: 1 | E6: A | F6: 1 | G6: 2 | I6: 1 | J6: 品名 | K6: D7 | L6: 款式 1-2 | M6: 副區-A-1-2.jpg | N6: 0 | O6: 限8個字
A7: subarea | B7: top:1 | C7: 1 | D7: 2 | E7: A | F7: 2 | G7: 2 | I7: 1 | J7: 促標 | K7: D13 | L7: 款式 2-2 | M7: 副區-A-2-2.jpg | N7: 0 | O7: 限8個字
A8: subarea | B8: top:1 | C8: 1 | D8: 2 | E8: A | F8: 2 | G8: 2 | I8: 1 | J8: LOGO圖 | K8: D14 | L8: 款式 2-2 | M8: 副區-A-2-2.jpg | N8: 0 | O8: (檔名/券名)
A9: subarea | B9: top:1 | C9: 1 | D9: 2 | E9: A | F9: 2 | G9: 2 | I9: 1 | J9: 商品 | K9: D15 | L9: 款式 2-2 | M9: 副區-A-2-2.jpg | N9: 0 | O9: (檔名/券名)
A10: subarea | B10: top:1 | C10: 1 | D10: 2 | E10: A | F10: 2 | G10: 2 | I10: 1 | J10: 品名 | K10: D16 | L10: 款式 2-2 | M10: 副區-A-2-2.jpg | N10: 0 | O10: 限8個字
A11: subarea | B11: top:1 | C11: 1 | D11: 2 | E11: A | F11: 2 | G11: 2 | I11: 1 | J11: 圓標 | K11: D17 | L11: 款式 2-2 | M11: 副區-A-2-2.jpg | N11: 0 | O11: 限5個字
A12: subarea | B12: top:2 | C12: 1 | D12: 3 | E12: A | F12: 4 | G12: 1 | I12: 1 | J12: 促標 | K12: D22 | L12: 款式 4-1 | M12: 副區-A-4-1.jpg | N12: 0 | O12: 限8個字
A13: subarea | B13: top:2 | C13: 1 | D13: 3 | E13: A | F13: 4 | G13: 1 | I13: 1 | J13: LOGO圖 | K13: D23 | L13: 款式 4-1 | M13: 副區-A-4-1.jpg | N13: 0 | O13: (檔名/券名)
A14: subarea | B14: top:2 | C14: 1 | D14: 3 | E14: A | F14: 4 | G14: 1 | I14: 1 | J14: 商品 | K14: D24 | L14: 款式 4-1 | M14: 副區-A-4-1.jpg | N14: 0 | O14: (檔名/券名)
... A17: subarea | B17: top:2 | C17: 1 | D17: 3 | E17: A | F17: 4 | G17: 1 | I17: 1 | J17: CTA | K17: D27 | L17: 款式 4-1 | M17: 副區-A-4-1.jpg | N17: 0 | O17: 限3個字
A18: msbn | B18: msbn:0 | C18: 2 | D18: 4 | H18: MSBN-A-2-3.jpg | I18: 1 | J18: 促標 | K18: D31 | L18: A-2-3 | M18: MSBN-A-2-3.jpg | N18: 0 | O18: 促標6個字內
A19: msbn | B19: msbn:0 | C19: 2 | D19: 4 | H19: MSBN-A-2-3.jpg | I19: 1 | J19: 商品 | K19: D32 | L19: A-2-3 | M19: MSBN-A-2-3.jpg | N19: 0 | O19: (圖檔名)
A20: msbn | B20: msbn:0 | C20: 2 | D20: 4 | H20: MSBN-A-2-3.jpg | I20: 1 | J20: 品名 | K20: D33 | L20: A-2-3 | M20: MSBN-A-2-3.jpg | N20: 0 | O20: 品名一排最多8字
A21: msbn | B21: msbn:0 | C21: 2 | D21: 4 | H21: MSBN-A-2-3.jpg | I21: 1 | J21: 品名 | K21: D34 | L21: A-2-3 | M21: MSBN-A-2-3.jpg | N21: 0 | O21: 品名一排最多8字
A22: msbn | B22: msbn:0 | C22: 2 | D22: 4 | H22: MSBN-A-2-3.jpg | I22: 1 | J22: 圓標 | K22: D35 | L22: A-2-3 | M22: MSBN-A-2-3.jpg | N22: 0 | O22: 圓標05字內
A23: msbn | B23: msbn:0 | C23: 2 | D23: 4 | H23: MSBN-A-2-3.jpg | I23: 2 | J23: 促標 | K23: H31 | L23: A-2-3 | M23: MSBN-A-2-3.jpg | N23: 0 | O23: 促標6個字內
A24: msbn | B24: msbn:0 | C24: 2 | D24: 4 | H24: MSBN-A-2-3.jpg | I24: 2 | J24: 商品 | K24: H32 | L24: A-2-3 | M24: MSBN-A-2-3.jpg | N24: 0 | O24: (圖檔名)
A25: msbn | B25: msbn:0 | C25: 2 | D25: 4 | H25: MSBN-A-2-3.jpg | I25: 2 | J25: 品名 | K25: H33 | L25: A-2-3 | M25: MSBN-A-2-3.jpg | N25: 0 | O25: 品名一排最多8字
A26: msbn | B26: msbn:0 | C26: 2 | D26: 4 | H26: MSBN-A-2-3.jpg | I26: 2 | J26: 品名 | K26: H34 | L26: A-2-3 | M26: MSBN-A-2-3.jpg | N26: 0 | O26: 品名一排最多8字
A27: msbn | B27: msbn:0 | C27: 2 | D27: 4 | H27: MSBN-A-2-3.jpg | I27: 2 | J27: 圓標 | K27: H35 | L27: A-2-3 | M27: MSBN-A-2-3.jpg | N27: 0 | O27: 圓標05字內
A28: msbn | B28: msbn:1 | C28: 3 | D28: 5 | H28: MSBN-A-3-1.jpg | I28: 1 | J28: 商品 | K28: D40 | L28: A-3-1 | M28: MSBN-A-3-1.jpg | N28: 0 | O28: (圖檔名)
A29: msbn | B29: msbn:1 | C29: 3 | D29: 5 | H29: MSBN-A-3-1.jpg | I29: 1 | J29: 贈品圖 | K29: D41 | L29: A-3-1 | M29: MSBN-A-3-1.jpg | N29: 0 | O29: (檔名)
... A86: msbn | B86: msbn:5 | C86: 7 | D86: 9 | H86: MSBN-C-1-4.jpg | I86: 1 | J86: CTA | K86: D89 | L86: C-1-4 | M86: MSBN-C-1-4.jpg | N86: 0 | O86: 刷卡去
