Workbook

Sheet 工單總覽
A1: BODA 工單總覽
A3: 包套(等級) | B3: A Brand star (Mega) 資交 | E3: MSBN 額度 | F3: =IFERROR(VLOOKUP(B3,設定!$A$2:$B$12,2,FALSE),0) -> 4 | H3: 輸出時間 | I3: 46262.252
A4: 負責人 | E4: 版本 | F4: V1 | H4: 更新重點
A5: 活動時間 | E5: 美術 Deadline | H5: 總製作張數 | I5: =SUM(C19:C30)+7 -> 7
A6: 工作項目名稱 | E6: 行銷目標
A7: 目標客群
A9: 曝光資源共用文案與色彩
A10: 背景顏色 | B10: #26c6da | E10: 連動規則 | F10: 與「曝光資源」背景色、匯入工單統一背景及 MSBN D 系列卡片背景同步；此處記錄匯出當下色號。
A11: 品牌名 | E11: 上限 9 | F11: 曝光資源品牌名稱；中文 1、英數 0.5。 | I11: =IF(B11="","",IF(LENB(B11)/2<=9,"OK","超過"))
A12: 主標 | E12: 上限 8 | F12: 曝光資源主標；中文 1、英數 0.5。 | I12: =IF(B12="","",IF(LENB(B12)/2<=8,"OK","超過"))
A13: 副標 | E13: 上限 7 | F13: 曝光資源副標；中文 1、英數 0.5。 | I13: =IF(B13="","",IF(LENB(B13)/2<=7,"OK","超過"))
A14: 日期／警語 | E14: 上限 14 | F14: 日期、活動期間或警語；中文 1、英數 0.5。 | I14: =IF(B14="","",IF(LENB(B14)/2<=14,"OK","超過"))
A15: ICON 獨立文案 | E15: 上限 2 | F15: Search ICON 文字版；也可改用 LOGO／商品圖；中文 1、英數 0.5。 | I15: =IF(B15="","",IF(LENB(B15)/2<=2,"OK","超過"))
A17: 製作曝光資源（依包套／等級自動切換；預設張數可手動調整，選配預設為 0）
A18: 版位 | B18: 類型 | C18: 張數 | D18: 尺寸 | E18: 格式 | F18: 規範字數 | G18: 提醒 | H18: 系統排版 | I18: Check
A19: =IFERROR(INDEX(設定!$C$2:$N$12,MATCH($B$3,設定!$A$2:$A$12,0),1),"") | B19: =IFERROR(INDEX(設定!$O$2:$Z$12,MATCH($B$3,設定!$A$2:$A$12,0),1),"") | C19: =IF(A19="","",IF(B19="預設",1,0)) | D19: =IF(A19="","",IFERROR(VLOOKUP(A19,設定!$AB$2:$AJ$13,4,FALSE),"")) | E19: =IF(A19="","",IFERROR(VLOOKUP(A19,設定!$AB$2:$AJ$13,5,FALSE),"")) | F19: =IF(A19="","",IFERROR(VLOOKUP(A19,設定!$AB$2:$AJ$13,6,FALSE),"")) | G19: =IF(A19="","",IFERROR(VLOOKUP(A19,設定!$AB$2:$AJ$13,7,FALSE),"")) | H19: =IF(A19="","",IFERROR(VLOOKUP(A19,設定!$AB$2:$AJ$13,8,FALSE),"尚未提供版型")) | I19: =IF(A19="","",IF(C19=0,"未選",IF(H19="尚未提供版型","缺版型","待製作")))
A20: =IFERROR(INDEX(設定!$C$2:$N$12,MATCH($B$3,設定!$A$2:$A$12,0),2),"") | B20: =IFERROR(INDEX(設定!$O$2:$Z$12,MATCH($B$3,設定!$A$2:$A$12,0),2),"") | C20: =IF(A20="","",IF(B20="預設",1,0)) | D20: =IF(A20="","",IFERROR(VLOOKUP(A20,設定!$AB$2:$AJ$13,4,FALSE),"")) | E20: =IF(A20="","",IFERROR(VLOOKUP(A20,設定!$AB$2:$AJ$13,5,FALSE),"")) | F20: =IF(A20="","",IFERROR(VLOOKUP(A20,設定!$AB$2:$AJ$13,6,FALSE),"")) | G20: =IF(A20="","",IFERROR(VLOOKUP(A20,設定!$AB$2:$AJ$13,7,FALSE),"")) | H20: =IF(A20="","",IFERROR(VLOOKUP(A20,設定!$AB$2:$AJ$13,8,FALSE),"尚未提供版型")) | I20: =IF(A20="","",IF(C20=0,"未選",IF(H20="尚未提供版型","缺版型","待製作")))
A21: =IFERROR(INDEX(設定!$C$2:$N$12,MATCH($B$3,設定!$A$2:$A$12,0),3),"") | B21: =IFERROR(INDEX(設定!$O$2:$Z$12,MATCH($B$3,設定!$A$2:$A$12,0),3),"") | C21: =IF(A21="","",IF(B21="預設",1,0)) | D21: =IF(A21="","",IFERROR(VLOOKUP(A21,設定!$AB$2:$AJ$13,4,FALSE),"")) | E21: =IF(A21="","",IFERROR(VLOOKUP(A21,設定!$AB$2:$AJ$13,5,FALSE),"")) | F21: =IF(A21="","",IFERROR(VLOOKUP(A21,設定!$AB$2:$AJ$13,6,FALSE),"")) | G21: =IF(A21="","",IFERROR(VLOOKUP(A21,設定!$AB$2:$AJ$13,7,FALSE),"")) | H21: =IF(A21="","",IFERROR(VLOOKUP(A21,設定!$AB$2:$AJ$13,8,FALSE),"尚未提供版型")) | I21: =IF(A21="","",IF(C21=0,"未選",IF(H21="尚未提供版型","缺版型","待製作")))
A22: =IFERROR(INDEX(設定!$C$2:$N$12,MATCH($B$3,設定!$A$2:$A$12,0),4),"") | B22: =IFERROR(INDEX(設定!$O$2:$Z$12,MATCH($B$3,設定!$A$2:$A$12,0),4),"") | C22: =IF(A22="","",IF(B22="預設",1,0)) | D22: =IF(A22="","",IFERROR(VLOOKUP(A22,設定!$AB$2:$AJ$13,4,FALSE),"")) | E22: =IF(A22="","",IFERROR(VLOOKUP(A22,設定!$AB$2:$AJ$13,5,FALSE),"")) | F22: =IF(A22="","",IFERROR(VLOOKUP(A22,設定!$AB$2:$AJ$13,6,FALSE),"")) | G22: =IF(A22="","",IFERROR(VLOOKUP(A22,設定!$AB$2:$AJ$13,7,FALSE),"")) | H22: =IF(A22="","",IFERROR(VLOOKUP(A22,設定!$AB$2:$AJ$13,8,FALSE),"尚未提供版型")) | I22: =IF(A22="","",IF(C22=0,"未選",IF(H22="尚未提供版型","缺版型","待製作")))
A23: =IFERROR(INDEX(設定!$C$2:$N$12,MATCH($B$3,設定!$A$2:$A$12,0),5),"") | B23: =IFERROR(INDEX(設定!$O$2:$Z$12,MATCH($B$3,設定!$A$2:$A$12,0),5),"") | C23: =IF(A23="","",IF(B23="預設",1,0)) | D23: =IF(A23="","",IFERROR(VLOOKUP(A23,設定!$AB$2:$AJ$13,4,FALSE),"")) | E23: =IF(A23="","",IFERROR(VLOOKUP(A23,設定!$AB$2:$AJ$13,5,FALSE),"")) | F23: =IF(A23="","",IFERROR(VLOOKUP(A23,設定!$AB$2:$AJ$13,6,FALSE),"")) | G23: =IF(A23="","",IFERROR(VLOOKUP(A23,設定!$AB$2:$AJ$13,7,FALSE),"")) | H23: =IF(A23="","",IFERROR(VLOOKUP(A23,設定!$AB$2:$AJ$13,8,FALSE),"尚未提供版型")) | I23: =IF(A23="","",IF(C23=0,"未選",IF(H23="尚未提供版型","缺版型","待製作")))
A24: =IFERROR(INDEX(設定!$C$2:$N$12,MATCH($B$3,設定!$A$2:$A$12,0),6),"") | B24: =IFERROR(INDEX(設定!$O$2:$Z$12,MATCH($B$3,設定!$A$2:$A$12,0),6),"") | C24: =IF(A24="","",IF(B24="預設",1,0)) | D24: =IF(A24="","",IFERROR(VLOOKUP(A24,設定!$AB$2:$AJ$13,4,FALSE),"")) | E24: =IF(A24="","",IFERROR(VLOOKUP(A24,設定!$AB$2:$AJ$13,5,FALSE),"")) | F24: =IF(A24="","",IFERROR(VLOOKUP(A24,設定!$AB$2:$AJ$13,6,FALSE),"")) | G24: =IF(A24="","",IFERROR(VLOOKUP(A24,設定!$AB$2:$AJ$13,7,FALSE),"")) | H24: =IF(A24="","",IFERROR(VLOOKUP(A24,設定!$AB$2:$AJ$13,8,FALSE),"尚未提供版型")) | I24: =IF(A24="","",IF(C24=0,"未選",IF(H24="尚未提供版型","缺版型","待製作")))
A25: =IFERROR(INDEX(設定!$C$2:$N$12,MATCH($B$3,設定!$A$2:$A$12,0),7),"") | B25: =IFERROR(INDEX(設定!$O$2:$Z$12,MATCH($B$3,設定!$A$2:$A$12,0),7),"") | C25: =IF(A25="","",IF(B25="預設",1,0)) | D25: =IF(A25="","",IFERROR(VLOOKUP(A25,設定!$AB$2:$AJ$13,4,FALSE),"")) | E25: =IF(A25="","",IFERROR(VLOOKUP(A25,設定!$AB$2:$AJ$13,5,FALSE),"")) | F25: =IF(A25="","",IFERROR(VLOOKUP(A25,設定!$AB$2:$AJ$13,6,FALSE),"")) | G25: =IF(A25="","",IFERROR(VLOOKUP(A25,設定!$AB$2:$AJ$13,7,FALSE),"")) | H25: =IF(A25="","",IFERROR(VLOOKUP(A25,設定!$AB$2:$AJ$13,8,FALSE),"尚未提供版型")) | I25: =IF(A25="","",IF(C25=0,"未選",IF(H25="尚未提供版型","缺版型","待製作")))
A26: =IFERROR(INDEX(設定!$C$2:$N$12,MATCH($B$3,設定!$A$2:$A$12,0),8),"") | B26: =IFERROR(INDEX(設定!$O$2:$Z$12,MATCH($B$3,設定!$A$2:$A$12,0),8),"") | C26: =IF(A26="","",IF(B26="預設",1,0)) | D26: =IF(A26="","",IFERROR(VLOOKUP(A26,設定!$AB$2:$AJ$13,4,FALSE),"")) | E26: =IF(A26="","",IFERROR(VLOOKUP(A26,設定!$AB$2:$AJ$13,5,FALSE),"")) | F26: =IF(A26="","",IFERROR(VLOOKUP(A26,設定!$AB$2:$AJ$13,6,FALSE),"")) | G26: =IF(A26="","",IFERROR(VLOOKUP(A26,設定!$AB$2:$AJ$13,7,FALSE),"")) | H26: =IF(A26="","",IFERROR(VLOOKUP(A26,設定!$AB$2:$AJ$13,8,FALSE),"尚未提供版型")) | I26: =IF(A26="","",IF(C26=0,"未選",IF(H26="尚未提供版型","缺版型","待製作")))
A27: =IFERROR(INDEX(設定!$C$2:$N$12,MATCH($B$3,設定!$A$2:$A$12,0),9),"") | B27: =IFERROR(INDEX(設定!$O$2:$Z$12,MATCH($B$3,設定!$A$2:$A$12,0),9),"") | C27: =IF(A27="","",IF(B27="預設",1,0)) | D27: =IF(A27="","",IFERROR(VLOOKUP(A27,設定!$AB$2:$AJ$13,4,FALSE),"")) | E27: =IF(A27="","",IFERROR(VLOOKUP(A27,設定!$AB$2:$AJ$13,5,FALSE),"")) | F27: =IF(A27="","",IFERROR(VLOOKUP(A27,設定!$AB$2:$AJ$13,6,FALSE),"")) | G27: =IF(A27="","",IFERROR(VLOOKUP(A27,設定!$AB$2:$AJ$13,7,FALSE),"")) | H27: =IF(A27="","",IFERROR(VLOOKUP(A27,設定!$AB$2:$AJ$13,8,FALSE),"尚未提供版型")) | I27: =IF(A27="","",IF(C27=0,"未選",IF(H27="尚未提供版型","缺版型","待製作")))
A28: =IFERROR(INDEX(設定!$C$2:$N$12,MATCH($B$3,設定!$A$2:$A$12,0),10),"") | B28: =IFERROR(INDEX(設定!$O$2:$Z$12,MATCH($B$3,設定!$A$2:$A$12,0),10),"") | C28: =IF(A28="","",IF(B28="預設",1,0)) | D28: =IF(A28="","",IFERROR(VLOOKUP(A28,設定!$AB$2:$AJ$13,4,FALSE),"")) | E28: =IF(A28="","",IFERROR(VLOOKUP(A28,設定!$AB$2:$AJ$13,5,FALSE),"")) | F28: =IF(A28="","",IFERROR(VLOOKUP(A28,設定!$AB$2:$AJ$13,6,FALSE),"")) | G28: =IF(A28="","",IFERROR(VLOOKUP(A28,設定!$AB$2:$AJ$13,7,FALSE),"")) | H28: =IF(A28="","",IFERROR(VLOOKUP(A28,設定!$AB$2:$AJ$13,8,FALSE),"尚未提供版型")) | I28: =IF(A28="","",IF(C28=0,"未選",IF(H28="尚未提供版型","缺版型","待製作")))
A29: =IFERROR(INDEX(設定!$C$2:$N$12,MATCH($B$3,設定!$A$2:$A$12,0),11),"") | B29: =IFERROR(INDEX(設定!$O$2:$Z$12,MATCH($B$3,設定!$A$2:$A$12,0),11),"") | C29: =IF(A29="","",IF(B29="預設",1,0)) | D29: =IF(A29="","",IFERROR(VLOOKUP(A29,設定!$AB$2:$AJ$13,4,FALSE),"")) | E29: =IF(A29="","",IFERROR(VLOOKUP(A29,設定!$AB$2:$AJ$13,5,FALSE),"")) | F29: =IF(A29="","",IFERROR(VLOOKUP(A29,設定!$AB$2:$AJ$13,6,FALSE),"")) | G29: =IF(A29="","",IFERROR(VLOOKUP(A29,設定!$AB$2:$AJ$13,7,FALSE),"")) | H29: =IF(A29="","",IFERROR(VLOOKUP(A29,設定!$AB$2:$AJ$13,8,FALSE),"尚未提供版型")) | I29: =IF(A29="","",IF(C29=0,"未選",IF(H29="尚未提供版型","缺版型","待製作")))
A30: =IFERROR(INDEX(設定!$C$2:$N$12,MATCH($B$3,設定!$A$2:$A$12,0),12),"") | B30: =IFERROR(INDEX(設定!$O$2:$Z$12,MATCH($B$3,設定!$A$2:$A$12,0),12),"") | C30: =IF(A30="","",IF(B30="預設",1,0)) | D30: =IF(A30="","",IFERROR(VLOOKUP(A30,設定!$AB$2:$AJ$13,4,FALSE),"")) | E30: =IF(A30="","",IFERROR(VLOOKUP(A30,設定!$AB$2:$AJ$13,5,FALSE),"")) | F30: =IF(A30="","",IFERROR(VLOOKUP(A30,設定!$AB$2:$AJ$13,6,FALSE),"")) | G30: =IF(A30="","",IFERROR(VLOOKUP(A30,設定!$AB$2:$AJ$13,7,FALSE),"")) | H30: =IF(A30="","",IFERROR(VLOOKUP(A30,設定!$AB$2:$AJ$13,8,FALSE),"尚未提供版型")) | I30: =IF(A30="","",IF(C30=0,"未選",IF(H30="尚未提供版型","缺版型","待製作")))
A33: 本次工單版配（來源：工單生成器畫布；內容欄請至 MS Layout 填寫）
A34: 類型 | B34: 版位名稱 | C34: Band | D34: 位置數 | E34: 素材檔案 | F34: 字數／欄位規則 | G34: 提醒 | H34: MS Layout | I34: Check
A35: 副區 | B35: 副區 一排3（左／中／右） | C35: 1 | D35: 3 | E35: 副區-A-2-1.jpg / 副區-A-4-1.jpg / 副區-B-4-4.jpg | F35: 限8個字；(檔名/券名)；限10個字；限5個字；限4+4個字；限3個字 | G35: 綠色欄位可填；固定欄位已鎖 | H35: 第 3 列 | I35: 待填
A36: MSBN | B36: A-1-1 | C36: 2 | D36: 1 | E36: MSBN-A-1-1.jpg | F36: 促標最多7字內；品名一排最多8字；圓標05字內；小字最多可9個字內；逛逛去；每行限5字；(圖檔名)；(檔名) | G36: 綠色欄位可填；固定欄位已鎖 | H36: 第 11 列 | I36: 待填
A37: MSBN | B37: C-1-3 | C37: 3 | D37: 1 | E37: MSBN-C-1-3.jpg | F37: 促標最多7字內；文案一排最多6字；小字最多可10個字以內 | G37: 綠色欄位可填；固定欄位已鎖 | H37: 第 20 列 | I37: 待填
A38: MSBN | B38: A-2-3 | C38: 4 | D38: 2 | E38: MSBN-A-2-3.jpg | F38: 促標6個字內；(圖檔名)；品名一排最多8字；圓標05字內 | G38: 綠色欄位可填；固定欄位已鎖 | H38: 第 31 列 | I38: 待填
A39: MSBN | B39: B-3-4 | C39: 5 | D39: 3 | E39: MSBN-B-3-4.jpg | F39: (圖檔名)；品名一排7字內；警語最多放8個字 | G39: 綠色欄位可填；固定欄位已鎖 | H39: 第 39 列 | I39: 待填

Sheet MS Layout
A1: 素材名稱 | B1: 版位／規格 | C1: Layout（綠色欄位可填；固定欄位與規則已鎖定） | T1: 視覺參考（目前系統實際版位）
C2: 中文 1 字、英數與半形符號 0.5 字；純數字自動以 $／千分位顯示；匯入 BODA 後混合文案也會整理；禁用語會阻擋並標紅 | T2: 圖片僅供版配與欄位位置對照，不代表最終正式稿
A3: 副區 | B3: 副區 一排3（左／中／右） 左：款式 2-1（A-2-1） 中：款式 4-1（A-4-1） 右：款式 4-4（B-4-4） Band 1 | C3: 左 | H3: 中 | M3: 右 | T3: 左 | X3: 中 | AC3: 右
C4: 促標 | D4: 滿200送20 | G4: =IF(D4="","",IF(LENB(D4)/2<=8,"OK","超過")) -> OK | H4: 促標 | I4: 滿300送20 | L4: =IF(I4="","",IF(LENB(I4)/2<=8,"OK","超過")) -> OK | M4: 促標 | N4: 買一送一 | R4: =IF(N4="","",IF(LENB(N4)/2<=8,"OK","超過")) -> OK
C5: LOGO圖 | D5: SAMPO 640X360-Photoroom.png | G5: =IF(D5="","待填","OK") -> OK | H5: LOGO圖 | I5: vivo 标志（RGB).jpg | L5: =IF(I5="","待填","OK") -> OK | M5: 商品 (多圖用逗號分開) | N5: 2-(4)-Photoroom.png | R5: =IF(N5="","待填",IF(ISNUMBER(SEARCH(".",N5)),"OK","記得加副檔名")) -> OK
C6: 商品 (多圖用逗號分開) | D6: 1-(4)-(1).jpg,1.png | G6: =IF(D6="","待填",IF(ISNUMBER(SEARCH(".",D6)),"OK","記得加副檔名")) -> OK | H6: 商品 (多圖用逗號分開) | I6: 2026-05-19 11 49 59-Photoroom.png | L6: =IF(I6="","待填",IF(ISNUMBER(SEARCH(".",I6)),"OK","記得加副檔名")) -> OK | M6: CTA | N6: 逛逛去 | R6: =IF(N6="","",IF(LENB(N6)/2<=3,"OK","超過")) -> OK
C7: 品名 | D7: 100W超快速變壓器 | G7: =IF(D7="","",IF(LENB(D7)/2<=8,"OK","超過")) -> OK | H7: 品名 | I7: 抗震耳機 | L7: =IF(I7="","",IF(LENB(I7)/2<=4,"OK","超過")) -> OK
C8: 警語 | D8: 數量有限，送完為止 | G8: =IF(D8="","",IF(LENB(D8)/2<=10,"OK","超過")) -> OK | H8: 警語 | I8: 只限今日 | L8: =IF(I8="","",IF(LENB(I8)/2<=5,"OK","超過")) -> OK
C9: 圓標 | D9: 下殺5折 | G9: =IF(D9="","",IF(LENB(D9)/2<=5,"OK","超過")) -> OK | H9: CTA | I9: 逛逛去 | L9: =IF(I9="","",IF(LENB(I9)/2<=3,"OK","超過")) -> OK
A11: MSBN | B11: A-1-1 MSBN-A-1-1 Band 2 | C11: 左右 | T11: A-1-1
C12: 促標 | D12: 滿200送20 | J12: =IF(D12="","",IF(LENB(D12)/2<=7,"OK","超過")) -> OK | K12: 商品 (多圖用逗號分開) | L12: 1-(4)-(1).jpg,1.png | R12: =IF(L12="","待填",IF(ISNUMBER(SEARCH(".",L12)),"OK","記得加副檔名")) -> OK
C13: 品名 | D13: 100W超快速變壓器 | J13: =IF(D13="","",IF(LENB(D13)/2<=8,"OK","超過")) -> OK | K13: 代言人圖 | L13: 代言人照片.png | R13: =IF(L13="","待填","OK") -> OK
C14: 品名 | D14: 512GB高容量 | J14: =IF(D14="","",IF(LENB(D14)/2<=8,"OK","超過")) -> OK | K14: 圓標 | L14: 下殺5折 | R14: =IF(L14="","",IF(LENB(L14)/2<=5,"OK","超過")) -> OK
C15: 警語 | D15: 數量有限，送完為止 | J15: =IF(D15="","",IF(LENB(D15)/2<=9,"OK","超過")) -> OK | K15: 簽名小字 | L15: 張惠妹推薦 | R15: =IF(L15="","",IF(LENB(L15)/2<=5,"OK","超過")) -> OK
K16: 簽名小字 | R16: =IF(L16="","",IF(LENB(L16)/2<=5,"OK","超過"))
K17: 簽名圖 | L17: 簽名檔.png | R17: =IF(L17="","待填","OK") -> OK
K18: CTA (放03字) | L18: 逛逛去 | R18: =IF(L18="","待填","OK") -> OK
A20: MSBN | B20: C-1-3 MSBN-C-1-3 Band 3 | C20: 左右 | T20: C-1-3
C21: 促標 | D21: 滿200送20 | R21: =IF(D21="","",IF(LENB(D21)/2<=7,"OK","超過")) -> OK
C22: 警語 | D22: 數量有限，送完為止 | R22: =IF(D22="","",IF(LENB(D22)/2<=10,"OK","超過")) -> OK
C23: 分欄 | D23: 左 | K23: 右
C24: 文案 | D24: 滿200送20 | J24: =IF(D24="","",IF(LENB(D24)/2<=6,"OK","超過")) -> OK | K24: 文案 | L24: 滿200送20 | R24: =IF(L24="","",IF(LENB(L24)/2<=6,"OK","超過")) -> OK
C25: 文案 | D25: 再享88折 | J25: =IF(D25="","",IF(LENB(D25)/2<=6,"OK","超過")) -> OK | K25: 文案 | L25: 再享88折 | R25: =IF(L25="","",IF(LENB(L25)/2<=6,"OK","超過")) -> OK
A31: MSBN | B31: A-2-3 MSBN-A-2-3 Band 4 | C31: 左 | G31: 右 | K31: — | O31: — | T31: A-2-3
C32: 促標 | D32: 滿200送20 | F32: =IF(D32="","",IF(LENB(D32)/2<=6,"OK","超過")) -> OK | G32: 促標 | H32: 滿200送20 | J32: =IF(H32="","",IF(LENB(H32)/2<=6,"OK","超過")) -> OK
C33: 商品 (多圖用逗號分開) | D33: 1-(4)-(1).jpg,1.png | F33: =IF(D33="","待填",IF(ISNUMBER(SEARCH(".",D33)),"OK","記得加副檔名")) -> OK | G33: 商品 (多圖用逗號分開) | H33: 1-(4)-(1).jpg,1.png | J33: =IF(H33="","待填",IF(ISNUMBER(SEARCH(".",H33)),"OK","記得加副檔名")) -> OK
C34: 品名 | D34: 100W超快速變壓器 | F34: =IF(D34="","",IF(LENB(D34)/2<=8,"OK","超過")) -> OK | G34: 品名 | H34: 100W超快速變壓器 | J34: =IF(H34="","",IF(LENB(H34)/2<=8,"OK","超過")) -> OK
C35: 品名 | D35: 512GB高容量 | F35: =IF(D35="","",IF(LENB(D35)/2<=8,"OK","超過")) -> OK | G35: 品名 | H35: 512GB高容量 | J35: =IF(H35="","",IF(LENB(H35)/2<=8,"OK","超過")) -> OK
C36: 圓標 | D36: 只限今日 | F36: =IF(D36="","",IF(LENB(D36)/2<=5,"OK","超過")) -> OK | G36: 圓標 | H36: 只限今日 | J36: =IF(H36="","",IF(LENB(H36)/2<=5,"OK","超過")) -> OK
A39: MSBN | B39: B-3-4 MSBN-B-3-4 Band 5 | C39: 右 | G39: 中 | K39: 左 | O39: — | T39: B-3-4
C40: 商品圖 | D40: 1-(4)-(1).jpg,1.png | F40: =IF(D40="","待填",IF(ISNUMBER(SEARCH(".",D40)),"OK","記得加副檔名")) -> OK | G40: 商品圖 | H40: Plainme_YOBI 連帽外套 _1.jpg | J40: =IF(H40="","待填",IF(ISNUMBER(SEARCH(".",H40)),"OK","記得加副檔名")) -> OK | K40: 商品圖 | L40: 1-(4)-(1).jpg,1.png | N40: =IF(L40="","待填",IF(ISNUMBER(SEARCH(".",L40)),"OK","記得加副檔名")) -> OK
C41: 品名 | D41: 100W變壓器 | F41: =IF(D41="","",IF(LENB(D41)/2<=7,"OK","超過")) -> OK | G41: 品名 | H41: 100W變壓器 | J41: =IF(H41="","",IF(LENB(H41)/2<=7,"OK","超過")) -> OK | K41: 品名 | L41: 100W變壓器 | N41: =IF(L41="","",IF(LENB(L41)/2<=7,"OK","超過")) -> OK
C42: 警語 | D42: 只限今日 | F42: =IF(D42="","",IF(LENB(D42)/2<=8,"OK","超過")) -> OK | G42: 警語 | H42: 只限今日 | J42: =IF(H42="","",IF(LENB(H42)/2<=8,"OK","超過")) -> OK | K42: 警語 | L42: 只限今日 | N42: =IF(L42="","",IF(LENB(L42)/2<=8,"OK","超過")) -> OK
C47: 第1顆 | H47: 第2顆 | M47: 第3顆 | R47: 第4顆 | Z47: 第5顆
A48: 吸底圖 | B48: 填你要的資訊 最少2格、最多5格 （不要的不填即可） | C48: Icon與Logo 2選1填即可 | D48: Icon | E48: 房子 | H48: Icon與Logo 2選1填即可 | I48: Icon | J48: (輸入許願的Icon，例：房子) | M48: Icon與Logo 2選1填即可 | N48: Icon | O48: (需要再填即可) | R48: Icon與Logo 2選1填即可 | S48: Icon | T48: (需要再填即可) | Z48: Icon與Logo 2選1填即可 | AA48: Icon | AB48: (需要再填即可)
D49: Logo | E49: (輸入圖檔名，例：三星.png) | I49: Logo | J49: Dyson_Logo480x360去背版.png | N49: Logo | O49: Dyson_Logo480x360去背版.png | S49: Logo | T49: Dyson_Logo480x360去背版.png | AA49: Logo | AB49: (需要再填即可)
C50: 主會場 | G50: =IF(OR(C50="",C50="文案5字內"),"",LENB(C50)/2) -> 3 | H50: Dyson | L50: =IF(OR(H50="",H50="文案5字內"),"",LENB(H50)/2) -> 2.5 | M50: Dyson | Q50: =IF(OR(M50="",M50="(需要再填即可)"),"",LENB(M50)/2) -> 2.5 | R50: Dyson | Y50: =IF(OR(R50="",R50="(需要再填即可)"),"",LENB(R50)/2) -> 2.5 | Z50: (需要再填即可) | AG50: =IF(OR(Z50="",Z50="(需要再填即可)"),"",LENB(Z50)/2)

Sheet 設定
A1: 等級 | B1: MSBN額度 | C1: 資源1 | D1: 資源2 | E1: 資源3 | F1: 資源4 | G1: 資源5 | H1: 資源6 | I1: 資源7 | J1: 資源8 | K1: 資源9 | L1: 資源10 | M1: 資源11 | N1: 資源12 | O1: 類型1 | P1: 類型2 | Q1: 類型3 | R1: 類型4 | S1: 類型5 | T1: 類型6 | U1: 類型7 | V1: 類型8 | W1: 類型9 | X1: 類型10 | Y1: 類型11 | Z1: 類型12 | AB1: key | AC1: 顯示名稱 | AD1: 張數 | AE1: 尺寸 | AF1: 格式 | AG1: 規範字數 | AH1: 提醒 | AI1: 系統排版 | AJ1: 可用
A2: A Brand star (Mega) | B2: 8 | AB2: DDCard | AC2: DD Card BN (APP) | AD2: 1 | AE2: 531×792 | AF2: JPG | AG2: 品牌名≤9；主標≤8；副標≤7；日期/警語≤14 | AH2: LOGO、商品圖；CTA 依版型 | AI2: ddcard方logo／ddcard橫logo | AJ2: 是
A3: A Brand star (Mega) 資交 | B3: 4 | AB3: HBN | AC3: HBN (PC) | AD3: 1 | AE3: 1200×360 | AF3: JPG | AG3: 品牌名≤9；主標≤8；副標≤7；日期/警語≤14 | AH3: 橫式或方形 LOGO 版 | AI3: HBN_橫式LOGO／HBN_方式LOGO | AJ3: 是
A4: A 精選套裝 | B4: 4 | AB4: 活動總覽 | AC4: 活動總覽 | AD4: 1 | AE4: 依活動規格 | AF4: JPG/PNG | AG4: 依活動需求 | AH4: 目前系統尚未提供可編輯版型 | AI4: 尚未提供版型 | AJ4: 否
A5: A 品牌旗艦MDD | B5: 6 | AB5: 首頁LOGO牆 | AC5: 首頁 LOGO 牆 | AD5: 1 | AE5: 依活動規格 | AF5: JPG/PNG | AG5: LOGO 依活動規範 | AH5: 目前系統尚未提供可編輯版型 | AI5: 尚未提供版型 | AJ5: 否
A6: A 品牌旗艦MDD 資交 | B6: 0 | AB6: AR | AC6: AR | AD6: 1 | AE6: 100×100（依規範） | AF6: JPG/PNG | AG6: 文案≤6 或 LOGO；2擇1 | AH6: 目前系統尚未提供可編輯版型 | AI6: 尚未提供版型 | AJ6: 否
A7: B+ BOD A | B7: 6 | C7: DDCard | D7: HBN | E7: 活動總覽 | F7: 首頁LOGO牆 | G7: AR | H7: FB_Post | I7: AMS BN | J7: Coin_page | K7: IG | L7: SearchIcon | M7: SearchImage | O7: 預設 | P7: 預設 | Q7: 預設 | R7: 預設 | S7: 預設 | T7: 預設 | U7: 預設 | V7: 選配 | W7: 選配 | X7: 選配 | Y7: 選配 | AB7: FB_Post | AC7: FB POST | AD7: 1 | AE7: 1200×630 | AF7: JPG | AG7: 品牌名≤9；主標≤8；副標≤7；日期/警語≤14 | AH7: 方 LOGO／橫 LOGO | AI7: FB_POST_方LOGO／FB_POST_橫LOGO | AJ7: 是
A8: B+ BOD A 資交 | B8: 0 | C8: DDCard | D8: HBN | E8: 活動總覽 | F8: 首頁LOGO牆 | G8: AR | H8: FB_Post | I8: AMS BN | J8: Coin_page | K8: IG | L8: SearchIcon | M8: SearchImage | O8: 預設 | P8: 預設 | Q8: 預設 | R8: 預設 | S8: 預設 | T8: 預設 | U8: 預設 | V8: 選配 | W8: 選配 | X8: 選配 | Y8: 選配 | AB8: AMS BN | AC8: AMS BN | AD8: 1 | AE8: 1077×264（依規範） | AF8: JPG | AG8: 依 AMS 規格 | AH8: 目前系統尚未提供可編輯版型 | AI8: 尚未提供版型 | AJ8: 否
A9: B+ BOD B (Mega) | B9: 6 | C9: DDCard | D9: HBN | E9: 活動總覽 | F9: 首頁LOGO牆 | G9: AR | H9: FB_Post | I9: AMS BN | J9: Coin_page | K9: IG | O9: 預設 | P9: 預設 | Q9: 預設 | R9: 預設 | S9: 預設 | T9: 選配 | U9: 選配 | V9: 選配 | W9: 選配 | AB9: Coin_page | AC9: Coin Page BN | AD9: 1 | AE9: 1200×391 | AF9: JPG | AG9: 品牌名≤9；主標≤8；副標≤7；日期/警語≤14 | AH9: 方 LOGO／橫 LOGO | AI9: Coin_pageBN_APP方LOGO／Coin_pageBN_APP橫LOGO | AJ9: 是
A10: B+ 基礎套裝 | B10: 6 | C10: DDCard | D10: HBN | E10: 活動總覽 | F10: 首頁LOGO牆 | G10: AR | H10: FB_Post | I10: AMS BN | J10: Coin_page | K10: IG | O10: 預設 | P10: 預設 | Q10: 預設 | R10: 預設 | S10: 預設 | T10: 選配 | U10: 選配 | V10: 選配 | W10: 選配 | AB10: IG | AC10: IG | AD10: 1 | AE10: 900×1600 | AF10: JPG | AG10: 品牌名≤9；主標≤8；副標≤7；日期/警語≤14 | AH10: 方 LOGO／橫 LOGO | AI10: IG方logo排版／IG橫logo排版 | AJ10: 是
A11: B JBP多店 | B11: 3 | C11: IG | D11: HBN | E11: DDCard | F11: Coin_page | G11: FB_Post | H11: SCPN | I11: SearchImage | J11: SearchIcon | O11: 預設 | P11: 預設 | Q11: 預設 | R11: 預設 | S11: 預設 | T11: 預設 | U11: 預設 | V11: 預設 | AB11: SearchIcon | AC11: Search ICON | AD11: 1 | AE11: 120×120＋84×84 | AF11: PNG | AG11: ICON 文案≤2；或 LOGO／商品圖 | AH11: 120×120 建議 <50KB，另輸出 84×84 | AI11: SearchICON_LOGO／PRODUCT／TEXT | AJ11: 是
A12: B 金牌 (Mega) | B12: 3 | C12: DDCard | D12: HBN | E12: 活動總覽 | F12: AR | G12: Coin_page | O12: 預設 | P12: 預設 | Q12: 預設 | R12: 預設 | S12: 選配 | AB12: SearchImage | AC12: Search Image | AD12: 1 | AE12: 1125×156 | AF12: JPG/PNG | AG12: 副標≤7；LOGO 1～3 個 | AH12: 依選用版型提供 1～3 個 LOGO | AI12: Search_Image1logo／2logo／3logo | AJ12: 是
AB13: SCPN | AC13: SCBN／SCPN | AD13: 1 | AE13: 1200×200 | AF13: JPG | AG13: 品牌名≤9；副標≤7；CTA | AH13: 商城橫幅 | AI13: SCBN_APP | AJ13: 是

Sheet _BODA_META
A1: BODA_WORKORDER_V2
A2: kind | B2: sourceKey | C2: band | D2: order | E2: family | F2: variant | G2: combo | H2: msbnFile | I2: position | J2: label | K2: address | L2: header | M2: file | N2: locked | O2: hint | P2: targetKey
A3: subarea | B3: top:0 | C3: 1 | D3: 1 | E3: A | F3: 2 | G3: 1 | I3: 1 | J3: 促標 | K3: D4 | L3: 款式 2-1 | M3: 副區-A-2-1.jpg | N3: 0 | O3: 限8個字
A4: subarea | B4: top:0 | C4: 1 | D4: 1 | E4: A | F4: 2 | G4: 1 | I4: 1 | J4: LOGO圖 | K4: D5 | L4: 款式 2-1 | M4: 副區-A-2-1.jpg | N4: 0 | O4: (檔名/券名)
A5: subarea | B5: top:0 | C5: 1 | D5: 1 | E5: A | F5: 2 | G5: 1 | I5: 1 | J5: 商品 | K5: D6 | L5: 款式 2-1 | M5: 副區-A-2-1.jpg | N5: 0 | O5: (檔名/券名)
A6: subarea | B6: top:0 | C6: 1 | D6: 1 | E6: A | F6: 2 | G6: 1 | I6: 1 | J6: 品名 | K6: D7 | L6: 款式 2-1 | M6: 副區-A-2-1.jpg | N6: 0 | O6: 限8個字
A7: subarea | B7: top:0 | C7: 1 | D7: 1 | E7: A | F7: 2 | G7: 1 | I7: 1 | J7: 警語 | K7: D8 | L7: 款式 2-1 | M7: 副區-A-2-1.jpg | N7: 0 | O7: 限10個字
A8: subarea | B8: top:0 | C8: 1 | D8: 1 | E8: A | F8: 2 | G8: 1 | I8: 1 | J8: 圓標 | K8: D9 | L8: 款式 2-1 | M8: 副區-A-2-1.jpg | N8: 0 | O8: 限5個字
A9: subarea | B9: top:1 | C9: 1 | D9: 2 | E9: A | F9: 4 | G9: 1 | I9: 2 | J9: 促標 | K9: I4 | L9: 款式 4-1 | M9: 副區-A-4-1.jpg | N9: 0 | O9: 限8個字
A10: subarea | B10: top:1 | C10: 1 | D10: 2 | E10: A | F10: 4 | G10: 1 | I10: 2 | J10: LOGO圖 | K10: I5 | L10: 款式 4-1 | M10: 副區-A-4-1.jpg | N10: 0 | O10: (檔名/券名)
A11: subarea | B11: top:1 | C11: 1 | D11: 2 | E11: A | F11: 4 | G11: 1 | I11: 2 | J11: 商品 | K11: I6 | L11: 款式 4-1 | M11: 副區-A-4-1.jpg | N11: 0 | O11: (檔名/券名)
A12: subarea | B12: top:1 | C12: 1 | D12: 2 | E12: A | F12: 4 | G12: 1 | I12: 2 | J12: 品名 | K12: I7 | L12: 款式 4-1 | M12: 副區-A-4-1.jpg | N12: 0 | O12: 限4+4個字
A13: subarea | B13: top:1 | C13: 1 | D13: 2 | E13: A | F13: 4 | G13: 1 | I13: 2 | J13: 警語 | K13: I8 | L13: 款式 4-1 | M13: 副區-A-4-1.jpg | N13: 0 | O13: 限5個字
A14: subarea | B14: top:1 | C14: 1 | D14: 2 | E14: A | F14: 4 | G14: 1 | I14: 2 | J14: CTA | K14: I9 | L14: 款式 4-1 | M14: 副區-A-4-1.jpg | N14: 0 | O14: 限3個字
... A17: subarea | B17: top:2 | C17: 1 | D17: 3 | E17: B | F17: 4 | G17: 4 | I17: 3 | J17: CTA | K17: N6 | L17: 款式 4-4 | M17: 副區-B-4-4.jpg | N17: 0 | O17: 限3個字
A18: msbn | B18: msbn:0 | C18: 2 | D18: 4 | H18: MSBN-A-1-1.jpg | I18: 1 | J18: 促標 | K18: D12 | L18: A-1-1 | M18: MSBN-A-1-1.jpg | N18: 0 | O18: 促標最多7字內
A19: msbn | B19: msbn:0 | C19: 2 | D19: 4 | H19: MSBN-A-1-1.jpg | I19: 1 | J19: 商品 | K19: L12 | L19: A-1-1 | M19: MSBN-A-1-1.jpg | N19: 0 | O19: (圖檔名)
A20: msbn | B20: msbn:0 | C20: 2 | D20: 4 | H20: MSBN-A-1-1.jpg | I20: 1 | J20: 品名 | K20: D13 | L20: A-1-1 | M20: MSBN-A-1-1.jpg | N20: 0 | O20: 品名一排最多8字
A21: msbn | B21: msbn:0 | C21: 2 | D21: 4 | H21: MSBN-A-1-1.jpg | I21: 1 | J21: 代言人圖 | K21: L13 | L21: A-1-1 | M21: MSBN-A-1-1.jpg | N21: 0 | O21: (圖檔名)
A22: msbn | B22: msbn:0 | C22: 2 | D22: 4 | H22: MSBN-A-1-1.jpg | I22: 1 | J22: 品名 | K22: D14 | L22: A-1-1 | M22: MSBN-A-1-1.jpg | N22: 0 | O22: 品名一排最多8字
A23: msbn | B23: msbn:0 | C23: 2 | D23: 4 | H23: MSBN-A-1-1.jpg | I23: 1 | J23: 圓標 | K23: L14 | L23: A-1-1 | M23: MSBN-A-1-1.jpg | N23: 0 | O23: 圓標05字內
A24: msbn | B24: msbn:0 | C24: 2 | D24: 4 | H24: MSBN-A-1-1.jpg | I24: 1 | J24: 警語 | K24: D15 | L24: A-1-1 | M24: MSBN-A-1-1.jpg | N24: 0 | O24: 小字最多可9個字內
A25: msbn | B25: msbn:0 | C25: 2 | D25: 4 | H25: MSBN-A-1-1.jpg | I25: 1 | J25: 簽名小字 | K25: L15 | L25: A-1-1 | M25: MSBN-A-1-1.jpg | N25: 0 | O25: 每行限5字
A26: msbn | B26: msbn:0 | C26: 2 | D26: 4 | H26: MSBN-A-1-1.jpg | I26: 1 | J26: 簽名小字 | K26: L16 | L26: A-1-1 | M26: MSBN-A-1-1.jpg | N26: 0 | O26: 每行限5字
A27: msbn | B27: msbn:0 | C27: 2 | D27: 4 | H27: MSBN-A-1-1.jpg | I27: 1 | J27: 簽名圖 | K27: L17 | L27: A-1-1 | M27: MSBN-A-1-1.jpg | N27: 0 | O27: (檔名)
A28: msbn | B28: msbn:0 | C28: 2 | D28: 4 | H28: MSBN-A-1-1.jpg | I28: 1 | J28: CTA | K28: L18 | L28: A-1-1 | M28: MSBN-A-1-1.jpg | N28: 0 | O28: 逛逛去
A29: msbn | B29: msbn:1 | C29: 3 | D29: 5 | H29: MSBN-C-1-3.jpg | I29: 1 | J29: 促標 | K29: D21 | L29: C-1-3 | M29: MSBN-C-1-3.jpg | N29: 0 | O29: 促標最多7字內 | P29: promo
A30: msbn | B30: msbn:1 | C30: 3 | D30: 5 | H30: MSBN-C-1-3.jpg | I30: 1 | J30: 警語 | K30: D22 | L30: C-1-3 | M30: MSBN-C-1-3.jpg | N30: 0 | O30: 小字最多可10個字以內 | P30: warn
A31: msbn | B31: msbn:1 | C31: 3 | D31: 5 | H31: MSBN-C-1-3.jpg | I31: 1 | J31: 文案 | K31: D24 | L31: C-1-3 | M31: MSBN-C-1-3.jpg | N31: 0 | O31: 文案一排最多6字 | P31: copy2
A32: msbn | B32: msbn:1 | C32: 3 | D32: 5 | H32: MSBN-C-1-3.jpg | I32: 1 | J32: 文案 | K32: L24 | L32: C-1-3 | M32: MSBN-C-1-3.jpg | N32: 0 | O32: 文案一排最多6字 | P32: copy
A33: msbn | B33: msbn:1 | C33: 3 | D33: 5 | H33: MSBN-C-1-3.jpg | I33: 1 | J33: 文案 | K33: D25 | L33: C-1-3 | M33: MSBN-C-1-3.jpg | N33: 0 | O33: 文案一排最多6字 | P33: copy2
A34: msbn | B34: msbn:1 | C34: 3 | D34: 5 | H34: MSBN-C-1-3.jpg | I34: 1 | J34: 文案 | K34: L25 | L34: C-1-3 | M34: MSBN-C-1-3.jpg | N34: 0 | O34: 文案一排最多6字 | P34: copy
A35: msbn | B35: msbn:2 | C35: 4 | D35: 6 | H35: MSBN-A-2-3.jpg | I35: 1 | J35: 促標 | K35: D32 | L35: A-2-3 | M35: MSBN-A-2-3.jpg | N35: 0 | O35: 促標6個字內
A36: msbn | B36: msbn:2 | C36: 4 | D36: 6 | H36: MSBN-A-2-3.jpg | I36: 1 | J36: 商品 | K36: D33 | L36: A-2-3 | M36: MSBN-A-2-3.jpg | N36: 0 | O36: (圖檔名)
A37: msbn | B37: msbn:2 | C37: 4 | D37: 6 | H37: MSBN-A-2-3.jpg | I37: 1 | J37: 品名 | K37: D34 | L37: A-2-3 | M37: MSBN-A-2-3.jpg | N37: 0 | O37: 品名一排最多8字
A38: msbn | B38: msbn:2 | C38: 4 | D38: 6 | H38: MSBN-A-2-3.jpg | I38: 1 | J38: 品名 | K38: D35 | L38: A-2-3 | M38: MSBN-A-2-3.jpg | N38: 0 | O38: 品名一排最多8字
A39: msbn | B39: msbn:2 | C39: 4 | D39: 6 | H39: MSBN-A-2-3.jpg | I39: 1 | J39: 圓標 | K39: D36 | L39: A-2-3 | M39: MSBN-A-2-3.jpg | N39: 0 | O39: 圓標05字內
A40: msbn | B40: msbn:2 | C40: 4 | D40: 6 | H40: MSBN-A-2-3.jpg | I40: 2 | J40: 促標 | K40: H32 | L40: A-2-3 | M40: MSBN-A-2-3.jpg | N40: 0 | O40: 促標6個字內
A41: msbn | B41: msbn:2 | C41: 4 | D41: 6 | H41: MSBN-A-2-3.jpg | I41: 2 | J41: 商品 | K41: H33 | L41: A-2-3 | M41: MSBN-A-2-3.jpg | N41: 0 | O41: (圖檔名)
A42: msbn | B42: msbn:2 | C42: 4 | D42: 6 | H42: MSBN-A-2-3.jpg | I42: 2 | J42: 品名 | K42: H34 | L42: A-2-3 | M42: MSBN-A-2-3.jpg | N42: 0 | O42: 品名一排最多8字
...

Sheet _BODA_BOTTOM
A1: BODA_BOTTOM_V1 | B1: MS Layout
A2: group | B2: title | C2: iconAddress | D2: logoAddress | E2: textAddress | F2: countAddress | G2: optional
A3: 1 | B3: 第1顆 | C3: E48 | D3: E49 | E3: C50 | F3: G50 | G3: 0
A4: 2 | B4: 第2顆 | C4: J48 | D4: J49 | E4: H50 | F4: L50 | G4: 0
A5: 3 | B5: 第3顆 | C5: O48 | D5: O49 | E5: M50 | F5: Q50 | G5: 1
A6: 4 | B6: 第4顆 | C6: T48 | D6: T49 | E6: R50 | F6: Y50 | G6: 1
A7: 5 | B7: 第5顆 | C7: AB48 | D7: AB49 | E7: Z50 | F7: AG50 | G7: 1

Sheet _BODA_RULES
A1: keyword | B1: replacement | C1: action
A2: 撒 | B2: 自動改成"灑" | C2: replace
A3: 購物金 | B3: 自動改成"優惠券" | C3: replace
A4: 抵用券 | B4: 自動改成"優惠券" | C4: replace
A5: 折價券 | B5: 自動改成"優惠券" | C5: replace
A6: 蝦皮券 | B6: 自動改成"優惠券" | C6: replace
A7: 蝦幣券 | B7: 自動改成"優惠券" | C7: replace
A8: 折扣券 | B8: 自動改成"優惠券" | C8: replace
A9: $蝦幣 | B9: 自動改成"蝦幣" | C9: replace
A10: 蝦幣$ | B10: 自動改成"蝦幣" | C10: replace
A11: \$\d+\s*蝦幣 | B11: 自動改成"蝦幣" | C11: replace
A12: 元 | B12: 直接無法輸入 | C12: block
... A69: 兩 | B69: 自動改成"2" | C69: replace
