Workbook

Sheet 工單總覽
A1: BODA 工單總覽
A3: 包套(等級) | B3: B+ BOD A | E3: MSBN 額度 | F3: =IFERROR(VLOOKUP(B3,設定!$A$2:$B$12,2,FALSE),0) -> 6 | H3: 輸出時間 | I3: 46268.41
A4: 負責人 | E4: 版本 | F4: V1 | H4: 更新重點
A5: 活動時間 | E5: 美術 Deadline | H5: 總製作張數 | I5: =SUM(C20:C31)+13 -> 22
A6: 工作項目名稱 | E6: 行銷目標
A7: 目標客群
A9: 曝光資源共用文案與色彩
A10: 背景顏色 | B10: #ff69b4 | E10: 連動規則 | F10: 與「曝光資源」背景色、匯入工單統一背景及 MSBN D 系列卡片背景同步；此處記錄匯出當下色號。
A11: 品牌名 | E11: 上限 9 | F11: 曝光資源品牌名稱；中文 1、英數 0.5。 | I11: =IF(B11="","限9字",IF(LENB(B11)/2<=9,"OK","超過")) -> 限9字
A12: 主標 | B12: 最強買1送1組 | E12: 上限 8 | F12: 曝光資源主標；中文 1、英數 0.5。 | I12: =IF(B12="","限8字",IF(LENB(B12)/2<=8,"OK","超過")) -> OK
A13: 副標 | B13: 最後超值6折 | E13: 上限 7 | F13: 曝光資源副標；中文 1、英數 0.5。 | I13: =IF(B13="","限7字",IF(LENB(B13)/2<=7,"OK","超過")) -> OK
A14: 日期／警語 | B14: 1/1~1/10 期間限定 | E14: 上限 14 | F14: 日期、活動期間或警語；中文 1、英數 0.5。 | I14: =IF(B14="","限14字",IF(LENB(B14)/2<=14,"OK","超過")) -> OK
A15: ICON 獨立文案 | E15: 上限 2 | F15: Search ICON 文字版；也可改用 LOGO／商品圖；中文 1、英數 0.5。 | I15: =IF(B15="","限2字",IF(LENB(B15)/2<=2,"OK","超過")) -> 限2字
A16: 曝光資源圖片 | B16: 1.png,2.png,3.png | E16: 上限 3張 | F16: 讀取曝品檔名；多張請用逗號分隔。 | I16: =IF(B16="","限3張",IF(LEN(B16)-LEN(SUBSTITUTE(B16,",",""))+1<=3,"OK","超過")) -> OK
A18: 製作曝光資源（依包套／等級自動切換；預設張數可手動調整，選配預設為 0）
A19: 版位 | B19: 類型 | C19: 張數 | D19: 尺寸 | E19: 格式 | F19: 規範字數 | G19: 提醒 | H19: 系統排版 | I19: Check
A20: =IFERROR(INDEX(設定!$C$2:$N$12,MATCH($B$3,設定!$A$2:$A$12,0),1),"") -> LPBN | B20: =IFERROR(INDEX(設定!$O$2:$Z$12,MATCH($B$3,設定!$A$2:$A$12,0),1),"") -> 預設 | C20: =IF(A20="","",IF(B20="預設",IFERROR(VLOOKUP(A20,設定!$AB$2:$AJ$14,3,FALSE),1),0)) -> 2 | D20: =IF(A20="","",IFERROR(VLOOKUP(A20,設定!$AB$2:$AJ$14,4,FALSE),"")) -> APP 1200×550 PC 1200×400 | E20: =IF(A20="","",IFERROR(VLOOKUP(A20,設定!$AB$2:$AJ$14,5,FALSE),"")) -> JPG | F20: =IF(A20="","",IFERROR(VLOOKUP(A20,設定!$AB$2:$AJ$14,6,FALSE),"")) -> 主標≤8；副標≤7；日期／警語≤14 | G20: =IF(A20="","",IFERROR(VLOOKUP(A20,設定!$AB$2:$AJ$14,7,FALSE),"")) -> APP、PC 各 1 張 | H20: =IF(A20="","",IFERROR(VLOOKUP(A20,設定!$AB$2:$AJ$14,8,FALSE),"尚未提供版型")) -> LPBN_APP／LPBN_PC | I20: =IF(A20="","",IF(C20=0,"未選",IF(H20="尚未提供版型","缺版型","待製作"))) -> 待製作
A21: =IFERROR(INDEX(設定!$C$2:$N$12,MATCH($B$3,設定!$A$2:$A$12,0),2),"") -> DDCard | B21: =IFERROR(INDEX(設定!$O$2:$Z$12,MATCH($B$3,設定!$A$2:$A$12,0),2),"") -> 預設 | C21: =IF(A21="","",IF(B21="預設",IFERROR(VLOOKUP(A21,設定!$AB$2:$AJ$14,3,FALSE),1),0)) -> 1 | D21: =IF(A21="","",IFERROR(VLOOKUP(A21,設定!$AB$2:$AJ$14,4,FALSE),"")) -> 531×792 | E21: =IF(A21="","",IFERROR(VLOOKUP(A21,設定!$AB$2:$AJ$14,5,FALSE),"")) -> JPG | F21: =IF(A21="","",IFERROR(VLOOKUP(A21,設定!$AB$2:$AJ$14,6,FALSE),"")) -> 品牌名≤9；主標≤8；副標≤7；日期/警語≤14 | G21: =IF(A21="","",IFERROR(VLOOKUP(A21,設定!$AB$2:$AJ$14,7,FALSE),"")) -> LOGO、商品圖；CTA 依版型 | H21: =IF(A21="","",IFERROR(VLOOKUP(A21,設定!$AB$2:$AJ$14,8,FALSE),"尚未提供版型")) -> ddcard無logo／ddcard方logo／ddcard橫logo | I21: =IF(A21="","",IF(C21=0,"未選",IF(H21="尚未提供版型","缺版型","待製作"))) -> 待製作
A22: =IFERROR(INDEX(設定!$C$2:$N$12,MATCH($B$3,設定!$A$2:$A$12,0),3),"") -> HBN | B22: =IFERROR(INDEX(設定!$O$2:$Z$12,MATCH($B$3,設定!$A$2:$A$12,0),3),"") -> 預設 | C22: =IF(A22="","",IF(B22="預設",IFERROR(VLOOKUP(A22,設定!$AB$2:$AJ$14,3,FALSE),1),0)) -> 1 | D22: =IF(A22="","",IFERROR(VLOOKUP(A22,設定!$AB$2:$AJ$14,4,FALSE),"")) -> 1200×360 | E22: =IF(A22="","",IFERROR(VLOOKUP(A22,設定!$AB$2:$AJ$14,5,FALSE),"")) -> JPG | F22: =IF(A22="","",IFERROR(VLOOKUP(A22,設定!$AB$2:$AJ$14,6,FALSE),"")) -> 品牌名≤9；主標≤8；副標≤7；日期/警語≤14 | G22: =IF(A22="","",IFERROR(VLOOKUP(A22,設定!$AB$2:$AJ$14,7,FALSE),"")) -> 橫式或方形 LOGO 版 | H22: =IF(A22="","",IFERROR(VLOOKUP(A22,設定!$AB$2:$AJ$14,8,FALSE),"尚未提供版型")) -> HBN_橫式LOGO／HBN_方式LOGO | I22: =IF(A22="","",IF(C22=0,"未選",IF(H22="尚未提供版型","缺版型","待製作"))) -> 待製作
A23: =IFERROR(INDEX(設定!$C$2:$N$12,MATCH($B$3,設定!$A$2:$A$12,0),4),"") -> 活動總覽 | B23: =IFERROR(INDEX(設定!$O$2:$Z$12,MATCH($B$3,設定!$A$2:$A$12,0),4),"") -> 預設 | C23: =IF(A23="","",IF(B23="預設",IFERROR(VLOOKUP(A23,設定!$AB$2:$AJ$14,3,FALSE),1),0)) -> 1 | D23: =IF(A23="","",IFERROR(VLOOKUP(A23,設定!$AB$2:$AJ$14,4,FALSE),"")) -> 依活動規格 | E23: =IF(A23="","",IFERROR(VLOOKUP(A23,設定!$AB$2:$AJ$14,5,FALSE),"")) -> JPG/PNG | F23: =IF(A23="","",IFERROR(VLOOKUP(A23,設定!$AB$2:$AJ$14,6,FALSE),"")) -> 依活動需求 | G23: =IF(A23="","",IFERROR(VLOOKUP(A23,設定!$AB$2:$AJ$14,7,FALSE),"")) -> 目前系統尚未提供可編輯版型 | H23: =IF(A23="","",IFERROR(VLOOKUP(A23,設定!$AB$2:$AJ$14,8,FALSE),"尚未提供版型")) -> 尚未提供版型 | I23: =IF(A23="","",IF(C23=0,"未選",IF(H23="尚未提供版型","缺版型","待製作"))) -> 缺版型
A24: =IFERROR(INDEX(設定!$C$2:$N$12,MATCH($B$3,設定!$A$2:$A$12,0),5),"") -> 首頁LOGO牆 | B24: =IFERROR(INDEX(設定!$O$2:$Z$12,MATCH($B$3,設定!$A$2:$A$12,0),5),"") -> 預設 | C24: =IF(A24="","",IF(B24="預設",IFERROR(VLOOKUP(A24,設定!$AB$2:$AJ$14,3,FALSE),1),0)) -> 1 | D24: =IF(A24="","",IFERROR(VLOOKUP(A24,設定!$AB$2:$AJ$14,4,FALSE),"")) -> 402×483 | E24: =IF(A24="","",IFERROR(VLOOKUP(A24,設定!$AB$2:$AJ$14,5,FALSE),"")) -> JPG/PNG | F24: =IF(A24="","",IFERROR(VLOOKUP(A24,設定!$AB$2:$AJ$14,6,FALSE),"")) -> LOGO／人物或商品圖可縮放 | G24: =IF(A24="","",IFERROR(VLOOKUP(A24,設定!$AB$2:$AJ$14,7,FALSE),"")) -> LOGO 位於曝品或人物範圍內，可用滑鼠縮放 | H24: =IF(A24="","",IFERROR(VLOOKUP(A24,設定!$AB$2:$AJ$14,8,FALSE),"尚未提供版型")) -> 首頁LOGO牆 | I24: =IF(A24="","",IF(C24=0,"未選",IF(H24="尚未提供版型","缺版型","待製作"))) -> 待製作
A25: =IFERROR(INDEX(設定!$C$2:$N$12,MATCH($B$3,設定!$A$2:$A$12,0),6),"") -> AR | B25: =IFERROR(INDEX(設定!$O$2:$Z$12,MATCH($B$3,設定!$A$2:$A$12,0),6),"") -> 預設 | C25: =IF(A25="","",IF(B25="預設",IFERROR(VLOOKUP(A25,設定!$AB$2:$AJ$14,3,FALSE),1),0)) -> 1 | D25: =IF(A25="","",IFERROR(VLOOKUP(A25,設定!$AB$2:$AJ$14,4,FALSE),"")) -> 100×100（依規範） | E25: =IF(A25="","",IFERROR(VLOOKUP(A25,設定!$AB$2:$AJ$14,5,FALSE),"")) -> JPG/PNG | F25: =IF(A25="","",IFERROR(VLOOKUP(A25,設定!$AB$2:$AJ$14,6,FALSE),"")) -> 文案≤6 或 LOGO；2擇1 | G25: =IF(A25="","",IFERROR(VLOOKUP(A25,設定!$AB$2:$AJ$14,7,FALSE),"")) -> 目前系統尚未提供可編輯版型 | H25: =IF(A25="","",IFERROR(VLOOKUP(A25,設定!$AB$2:$AJ$14,8,FALSE),"尚未提供版型")) -> 尚未提供版型 | I25: =IF(A25="","",IF(C25=0,"未選",IF(H25="尚未提供版型","缺版型","待製作"))) -> 缺版型
A26: =IFERROR(INDEX(設定!$C$2:$N$12,MATCH($B$3,設定!$A$2:$A$12,0),7),"") -> FB_Post | B26: =IFERROR(INDEX(設定!$O$2:$Z$12,MATCH($B$3,設定!$A$2:$A$12,0),7),"") -> 預設 | C26: =IF(A26="","",IF(B26="預設",IFERROR(VLOOKUP(A26,設定!$AB$2:$AJ$14,3,FALSE),1),0)) -> 1 | D26: =IF(A26="","",IFERROR(VLOOKUP(A26,設定!$AB$2:$AJ$14,4,FALSE),"")) -> 1200×630 | E26: =IF(A26="","",IFERROR(VLOOKUP(A26,設定!$AB$2:$AJ$14,5,FALSE),"")) -> JPG | F26: =IF(A26="","",IFERROR(VLOOKUP(A26,設定!$AB$2:$AJ$14,6,FALSE),"")) -> 品牌名≤9；主標≤8；副標≤7；日期/警語≤14 | G26: =IF(A26="","",IFERROR(VLOOKUP(A26,設定!$AB$2:$AJ$14,7,FALSE),"")) -> 方 LOGO／橫 LOGO | H26: =IF(A26="","",IFERROR(VLOOKUP(A26,設定!$AB$2:$AJ$14,8,FALSE),"尚未提供版型")) -> FB_POST_方LOGO／FB_POST_橫LOGO | I26: =IF(A26="","",IF(C26=0,"未選",IF(H26="尚未提供版型","缺版型","待製作"))) -> 待製作
A27: =IFERROR(INDEX(設定!$C$2:$N$12,MATCH($B$3,設定!$A$2:$A$12,0),8),"") -> AMS BN | B27: =IFERROR(INDEX(設定!$O$2:$Z$12,MATCH($B$3,設定!$A$2:$A$12,0),8),"") -> 預設 | C27: =IF(A27="","",IF(B27="預設",IFERROR(VLOOKUP(A27,設定!$AB$2:$AJ$14,3,FALSE),1),0)) -> 1 | D27: =IF(A27="","",IFERROR(VLOOKUP(A27,設定!$AB$2:$AJ$14,4,FALSE),"")) -> 1077×264（依規範） | E27: =IF(A27="","",IFERROR(VLOOKUP(A27,設定!$AB$2:$AJ$14,5,FALSE),"")) -> JPG | F27: =IF(A27="","",IFERROR(VLOOKUP(A27,設定!$AB$2:$AJ$14,6,FALSE),"")) -> 依 AMS 規格 | G27: =IF(A27="","",IFERROR(VLOOKUP(A27,設定!$AB$2:$AJ$14,7,FALSE),"")) -> 目前系統尚未提供可編輯版型 | H27: =IF(A27="","",IFERROR(VLOOKUP(A27,設定!$AB$2:$AJ$14,8,FALSE),"尚未提供版型")) -> 尚未提供版型 | I27: =IF(A27="","",IF(C27=0,"未選",IF(H27="尚未提供版型","缺版型","待製作"))) -> 缺版型
A28: =IFERROR(INDEX(設定!$C$2:$N$12,MATCH($B$3,設定!$A$2:$A$12,0),9),"") -> Coin_page | B28: =IFERROR(INDEX(設定!$O$2:$Z$12,MATCH($B$3,設定!$A$2:$A$12,0),9),"") -> 選配 | C28: =IF(A28="","",IF(B28="預設",IFERROR(VLOOKUP(A28,設定!$AB$2:$AJ$14,3,FALSE),1),0)) -> 0 | D28: =IF(A28="","",IFERROR(VLOOKUP(A28,設定!$AB$2:$AJ$14,4,FALSE),"")) -> 1200×391 | E28: =IF(A28="","",IFERROR(VLOOKUP(A28,設定!$AB$2:$AJ$14,5,FALSE),"")) -> JPG | F28: =IF(A28="","",IFERROR(VLOOKUP(A28,設定!$AB$2:$AJ$14,6,FALSE),"")) -> 品牌名≤9；主標≤8；副標≤7；日期/警語≤14 | G28: =IF(A28="","",IFERROR(VLOOKUP(A28,設定!$AB$2:$AJ$14,7,FALSE),"")) -> 方 LOGO／橫 LOGO | H28: =IF(A28="","",IFERROR(VLOOKUP(A28,設定!$AB$2:$AJ$14,8,FALSE),"尚未提供版型")) -> Coin_pageBN_APP方LOGO／Coin_pageBN_APP橫LOGO | I28: =IF(A28="","",IF(C28=0,"未選",IF(H28="尚未提供版型","缺版型","待製作"))) -> 未選
A29: =IFERROR(INDEX(設定!$C$2:$N$12,MATCH($B$3,設定!$A$2:$A$12,0),10),"") -> IG | B29: =IFERROR(INDEX(設定!$O$2:$Z$12,MATCH($B$3,設定!$A$2:$A$12,0),10),"") -> 選配 | C29: =IF(A29="","",IF(B29="預設",IFERROR(VLOOKUP(A29,設定!$AB$2:$AJ$14,3,FALSE),1),0)) -> 0 | D29: =IF(A29="","",IFERROR(VLOOKUP(A29,設定!$AB$2:$AJ$14,4,FALSE),"")) -> 900×1600 | E29: =IF(A29="","",IFERROR(VLOOKUP(A29,設定!$AB$2:$AJ$14,5,FALSE),"")) -> JPG | F29: =IF(A29="","",IFERROR(VLOOKUP(A29,設定!$AB$2:$AJ$14,6,FALSE),"")) -> 品牌名≤9；主標≤8；副標≤7；日期/警語≤14 | G29: =IF(A29="","",IFERROR(VLOOKUP(A29,設定!$AB$2:$AJ$14,7,FALSE),"")) -> 方 LOGO／橫 LOGO | H29: =IF(A29="","",IFERROR(VLOOKUP(A29,設定!$AB$2:$AJ$14,8,FALSE),"尚未提供版型")) -> IG方logo排版／IG橫logo排版 | I29: =IF(A29="","",IF(C29=0,"未選",IF(H29="尚未提供版型","缺版型","待製作"))) -> 未選
A30: =IFERROR(INDEX(設定!$C$2:$N$12,MATCH($B$3,設定!$A$2:$A$12,0),11),"") -> SearchIcon | B30: =IFERROR(INDEX(設定!$O$2:$Z$12,MATCH($B$3,設定!$A$2:$A$12,0),11),"") -> 選配 | C30: =IF(A30="","",IF(B30="預設",IFERROR(VLOOKUP(A30,設定!$AB$2:$AJ$14,3,FALSE),1),0)) -> 0 | D30: =IF(A30="","",IFERROR(VLOOKUP(A30,設定!$AB$2:$AJ$14,4,FALSE),"")) -> 120×120＋84×84 | E30: =IF(A30="","",IFERROR(VLOOKUP(A30,設定!$AB$2:$AJ$14,5,FALSE),"")) -> PNG | F30: =IF(A30="","",IFERROR(VLOOKUP(A30,設定!$AB$2:$AJ$14,6,FALSE),"")) -> ICON 文案≤2；或 LOGO／商品圖 | G30: =IF(A30="","",IFERROR(VLOOKUP(A30,設定!$AB$2:$AJ$14,7,FALSE),"")) -> 120×120 建議 <50KB，另輸出 84×84 | H30: =IF(A30="","",IFERROR(VLOOKUP(A30,設定!$AB$2:$AJ$14,8,FALSE),"尚未提供版型")) -> SearchICON_LOGO／PRODUCT／TEXT | I30: =IF(A30="","",IF(C30=0,"未選",IF(H30="尚未提供版型","缺版型","待製作"))) -> 未選
A31: =IFERROR(INDEX(設定!$C$2:$N$12,MATCH($B$3,設定!$A$2:$A$12,0),12),"") -> SearchImage | B31: =IFERROR(INDEX(設定!$O$2:$Z$12,MATCH($B$3,設定!$A$2:$A$12,0),12),"") -> 選配 | C31: =IF(A31="","",IF(B31="預設",IFERROR(VLOOKUP(A31,設定!$AB$2:$AJ$14,3,FALSE),1),0)) -> 0 | D31: =IF(A31="","",IFERROR(VLOOKUP(A31,設定!$AB$2:$AJ$14,4,FALSE),"")) -> 1125×156 | E31: =IF(A31="","",IFERROR(VLOOKUP(A31,設定!$AB$2:$AJ$14,5,FALSE),"")) -> JPG/PNG | F31: =IF(A31="","",IFERROR(VLOOKUP(A31,設定!$AB$2:$AJ$14,6,FALSE),"")) -> 副標≤7；LOGO 1～3 個 | G31: =IF(A31="","",IFERROR(VLOOKUP(A31,設定!$AB$2:$AJ$14,7,FALSE),"")) -> 依選用版型提供 1～3 個 LOGO | H31: =IF(A31="","",IFERROR(VLOOKUP(A31,設定!$AB$2:$AJ$14,8,FALSE),"尚未提供版型")) -> Search_Image1logo／2logo／3logo | I31: =IF(A31="","",IF(C31=0,"未選",IF(H31="尚未提供版型","缺版型","待製作"))) -> 未選
A34: 本次工單版配（來源：工單生成器畫布；內容欄請至 MS Layout 填寫）
A35: 類型 | B35: 版位名稱 | C35: Band | D35: 位置數 | E35: 素材檔案 | F35: 字數／欄位規則 | G35: 提醒 | H35: MS Layout | I35: Check
A36: 副區 | B36: 副區 一排4（左1／左2／右1／右2） | C36: 1 | D36: 4 | E36: 副區-F-1-1.jpg / 副區-F-1-1.jpg / 副區-F-1-1.jpg / 副區-F-1-1.jpg | F36: (檔名/券名)；限5個字；限6個字 | G36: 綠色欄位可填；固定欄位已鎖 | H36: 第 3 列 | I36: 待填
A37: MSBN | B37: A-1-1 | C37: 2 | D37: 1 | E37: MSBN-A-1-1.jpg | F37: 促標最多7字內；品名一排最多8字；圓標05字內；小字最多可9個字內；逛逛去；每行限5字；(圖檔名)；(檔名) | G37: 綠色欄位可填；固定欄位已鎖 | H37: 第 11 列 | I37: 待填
A38: 副區 | B38: 副區 一排4（左1／左2／右1／右2） | C38: 3 | D38: 4 | E38: 副區-F-1-1.jpg / 副區-F-1-1.jpg / 副區-F-1-1.jpg / 副區-F-1-1.jpg | F38: (檔名/券名)；限5個字；限6個字 | G38: 綠色欄位可填；固定欄位已鎖 | H38: 第 20 列 | I38: 待填
A39: MSBN | B39: B-3-3 | C39: 4 | D39: 3 | E39: MSBN-B-3-3.jpg | F39: (檔名/券名)；品名一排7字內；逛逛去 | G39: 綠色欄位可填；固定欄位已鎖 | H39: 第 28 列 | I39: 待填
A40: MSBN | B40: B-1-3 | C40: 5 | D40: 1 | E40: MSBN-B-1-3.jpg | F40: (檔名/券名)；文案最多10個字以內；逛逛去；代言人小字8字內；(圖檔名) | G40: 綠色欄位可填；固定欄位已鎖 | H40: 第 33 列 | I40: 待填
A41: MSBN | B41: C-1-5 | C41: 6 | D41: 1 | E41: MSBN-C-1-5.jpg | F41: (圖檔名)；促標最多6字；文案一排4字；(檔名/券名)；領券去 | G41: 綠色欄位可填；固定欄位已鎖 | H41: 第 38 列 | I41: 待填
A42: MSBN | B42: D-1-3 | C42: 7 | D42: 1 | E42: MSBN-D-1-3.jpg | F42: 內文一排最多09字內；項目文字04字 | G42: 綠色欄位可填；固定欄位已鎖 | H42: 第 45 列 | I42: 待填

Sheet MS Layout
A1: 素材名稱 | B1: 版位／規格 | C1: Layout（綠色欄位可填；固定欄位與規則已鎖定） | T1: 視覺參考（目前系統實際版位）
C2: 中文 1 字、英數與半形符號 0.5 字；純數字自動以 $／千分位顯示；匯入 BODA 後混合文案也會整理；禁用語會阻擋並標紅 | T2: 圖片僅供版配與欄位位置對照，不代表最終正式稿
A3: 副區 | B3: 副區 一排4（左1／左2／右1／右2） 左1：款式 1-1（F-1-1） 左2：款式 1-1（F-1-1） 右1：款式 1-1（F-1-1） 右2：款式 1-1（F-1-1） Band 1 | C3: 左1 | G3: 左2 | K3: 右1 | O3: 右2 | T3: 左1 | W3: 左2 | AA3: 右1 | AD3: 右2
C4: LOGO圖 | D4: GIGASTONE_LOGO.png | F4: =IF(D4="","待填","OK") -> OK | G4: LOGO圖 | H4: Logitech G.png | J4: =IF(H4="","待填","OK") -> OK | K4: LOGO圖 | L4: SAMPO 640X360-Photoroom.png | N4: =IF(L4="","待填","OK") -> OK | O4: LOGO圖 | P4: vivo 标志（RGB).jpg | R4: =IF(P4="","待填","OK") -> OK
C5: 商品 (多圖用逗號分開) | D5: 2026-05-19 11 49 59-Photoroom.png | F5: =IF(D5="","待填",IF(ISNUMBER(SEARCH(".",D5)),"OK","記得加副檔名")) -> OK | G5: 商品 (多圖用逗號分開) | H5: 2026-05-19 11 50 16-Photoroom.png | J5: =IF(H5="","待填",IF(ISNUMBER(SEARCH(".",H5)),"OK","記得加副檔名")) -> OK | K5: 商品 (多圖用逗號分開) | L5: 2-(4)-Photoroom.png | N5: =IF(L5="","待填",IF(ISNUMBER(SEARCH(".",L5)),"OK","記得加副檔名")) -> OK | O5: 商品 (多圖用逗號分開) | P5: 2.png,3.png | R5: =IF(P5="","待填",IF(ISNUMBER(SEARCH(".",P5)),"OK","記得加副檔名")) -> OK
C6: 品名 | D6: 超亮投影機 | F6: =IF(D6="","限5字",IF(LENB(D6)/2<=5,"OK","超過")) -> OK | G6: 品名 | H6: 羅技耳機 | J6: =IF(H6="","限5字",IF(LENB(H6)/2<=5,"OK","超過")) -> OK | K6: 品名 | L6: 60吋大電視 | N6: =IF(L6="","限5字",IF(LENB(L6)/2<=5,"OK","超過")) -> OK | O6: 品名 | P6: 保濕組 | R6: =IF(P6="","限5字",IF(LENB(P6)/2<=5,"OK","超過")) -> OK
C7: 警語 | D7: 只限今日 | F7: =IF(D7="","限6字",IF(LENB(D7)/2<=6,"OK","超過")) -> OK | G7: 警語 | H7: 超值下殺價 | J7: =IF(H7="","限6字",IF(LENB(H7)/2<=6,"OK","超過")) -> OK | K7: 警語 | L7: 只有10台 | N7: =IF(L7="","限6字",IF(LENB(L7)/2<=6,"OK","超過")) -> OK | O7: 警語 | P7: 買一送一 | R7: =IF(P7="","限6字",IF(LENB(P7)/2<=6,"OK","超過")) -> OK
A11: MSBN | B11: A-1-1 MSBN-A-1-1 Band 2 | C11: 左右 | T11: A-1-1
C12: 促標 | D12: 超值組下殺 | F12: =IF(D12="","限7字",IF(LENB(D12)/2<=7,"OK","超過")) -> OK | G12: 商品 (多圖用逗號分開) | H12: 2026-05-19 11 49 59-Photoroom.png,2026-05-19 11 50 16-Photoroom.png,1.png | J12: =IF(H12="","待填",IF(ISNUMBER(SEARCH(".",H12)),"OK","記得加副檔名")) -> OK
C13: 品名 | D13: 保濕組 | F13: =IF(D13="","限8字",IF(LENB(D13)/2<=8,"OK","超過")) -> OK | G13: 代言人圖 | J13: =IF(H13="","待填","OK") -> 待填
C14: 品名 | D14: 買1送1 | F14: =IF(D14="","限8字",IF(LENB(D14)/2<=8,"OK","超過")) -> OK | G14: 圓標 | H14: 下殺五折起 | J14: =IF(H14="","限5字",IF(LENB(H14)/2<=5,"OK","超過")) -> OK
C15: 警語 | D15: 只有今天限50組 | F15: =IF(D15="","限9字",IF(LENB(D15)/2<=9,"OK","超過")) -> OK | G15: 簽名小字 | J15: =IF(H15="","限5字",IF(LENB(H15)/2<=5,"OK","超過")) -> 限5字
G16: 簽名小字 | J16: =IF(H16="","限5字",IF(LENB(H16)/2<=5,"OK","超過")) -> 限5字
G17: 簽名圖 | J17: =IF(H17="","待填","OK") -> 待填
G18: CTA (放03字) | H18: 逛逛去 | J18: =IF(H18="","待填","OK") -> OK
A20: 副區 | B20: 副區 一排4（左1／左2／右1／右2） 左1：款式 1-1（F-1-1） 左2：款式 1-1（F-1-1） 右1：款式 1-1（F-1-1） 右2：款式 1-1（F-1-1） Band 3 | C20: 左1 | G20: 左2 | K20: 右1 | O20: 右2 | T20: 左1 | W20: 左2 | AA20: 右1 | AD20: 右2
C21: LOGO圖 | D21: Logitech G.png | F21: =IF(D21="","待填","OK") -> OK | G21: LOGO圖 | H21: GIGASTONE_LOGO.png | J21: =IF(H21="","待填","OK") -> OK | K21: LOGO圖 | L21: vivo 标志（RGB).jpg | N21: =IF(L21="","待填","OK") -> OK | O21: LOGO圖 | P21: SAMPO 640X360-Photoroom.png | R21: =IF(P21="","待填","OK") -> OK
C22: 商品 (多圖用逗號分開) | D22: 2026-05-19 11 50 16-Photoroom.png | F22: =IF(D22="","待填",IF(ISNUMBER(SEARCH(".",D22)),"OK","記得加副檔名")) -> OK | G22: 商品 (多圖用逗號分開) | H22: 2026-05-19 11 49 59-Photoroom.png | J22: =IF(H22="","待填",IF(ISNUMBER(SEARCH(".",H22)),"OK","記得加副檔名")) -> OK | K22: 商品 (多圖用逗號分開) | L22: 2.png,3.png | N22: =IF(L22="","待填",IF(ISNUMBER(SEARCH(".",L22)),"OK","記得加副檔名")) -> OK | O22: 商品 (多圖用逗號分開) | P22: 2-(4)-Photoroom.png | R22: =IF(P22="","待填",IF(ISNUMBER(SEARCH(".",P22)),"OK","記得加副檔名")) -> OK
C23: 品名 | D23: 羅技耳機 | F23: =IF(D23="","限5字",IF(LENB(D23)/2<=5,"OK","超過")) -> OK | G23: 品名 | H23: 超亮投影機 | J23: =IF(H23="","限5字",IF(LENB(H23)/2<=5,"OK","超過")) -> OK | K23: 品名 | L23: 保濕組 | N23: =IF(L23="","限5字",IF(LENB(L23)/2<=5,"OK","超過")) -> OK | O23: 品名 | P23: 60吋大電視 | R23: =IF(P23="","限5字",IF(LENB(P23)/2<=5,"OK","超過")) -> OK
C24: 警語 | D24: 超值下殺價 | F24: =IF(D24="","限6字",IF(LENB(D24)/2<=6,"OK","超過")) -> OK | G24: 警語 | H24: 只限今日 | J24: =IF(H24="","限6字",IF(LENB(H24)/2<=6,"OK","超過")) -> OK | K24: 警語 | L24: 買一送一 | N24: =IF(L24="","限6字",IF(LENB(L24)/2<=6,"OK","超過")) -> OK | O24: 警語 | P24: 只有10台 | R24: =IF(P24="","限6字",IF(LENB(P24)/2<=6,"OK","超過")) -> OK
A28: MSBN | B28: B-3-3 MSBN-B-3-3 Band 4 | C28: 右 | G28: 中 | K28: 左 | O28: — | T28: B-3-3
C29: LOGO圖 | D29: Copy of SF_logo_596x596.png | F29: =IF(D29="","待填","OK") -> OK | G29: LOGO圖 | H29: Dyson_Logo480x360去背版.png | J29: =IF(H29="","待填","OK") -> OK | K29: LOGO圖 | L29: SAMPO 640X360-Photoroom.png | N29: =IF(L29="","待填","OK") -> OK
C30: 品名 | D30: 羅技耳機 | F30: =IF(D30="","限7字",IF(LENB(D30)/2<=7,"OK","超過")) -> OK | G30: 品名 | H30: 超亮投影機 | J30: =IF(H30="","限7字",IF(LENB(H30)/2<=7,"OK","超過")) -> OK | K30: 品名 | L30: 保濕組 | N30: =IF(L30="","限7字",IF(LENB(L30)/2<=7,"OK","超過")) -> OK
C31: CTA (放03字) | D31: 逛逛去 | F31: =IF(D31="","待填","OK") -> OK | G31: CTA (放03字) | H31: 逛逛去 | J31: =IF(H31="","待填","OK") -> OK | K31: CTA (放03字) | L31: 逛逛去 | N31: =IF(L31="","待填","OK") -> OK
A33: MSBN | B33: B-1-3 MSBN-B-1-3 Band 5 | C33: 左右 | T33: B-1-3
C34: 代言人小字 | F34: =IF(D34="","限8字",IF(LENB(D34)/2<=8,"OK","超過")) -> 限8字 | G34: LOGO圖 | H34: SAMPO 640X360-Photoroom.png | J34: =IF(H34="","待填","OK") -> OK
C35: 代言人小字 | F35: =IF(D35="","限8字",IF(LENB(D35)/2<=8,"OK","超過")) -> 限8字 | G35: 文案 | H35: 買一送一超值組 | J35: =IF(H35="","限10字",IF(LENB(H35)/2<=10,"OK","超過")) -> OK
C36: 商品圖 | D36: KI60415GG-1.JPG | F36: =IF(D36="","待填",IF(ISNUMBER(SEARCH(".",D36)),"OK","記得加副檔名")) -> OK | G36: CTA (放03字) | H36: 逛逛去 | J36: =IF(H36="","待填","OK") -> OK
A38: MSBN | B38: C-1-5 MSBN-C-1-5 Band 6 | C38: 左右 | T38: C-1-5
C39: 分欄 | D39: 左 | I39: 中 | N39: 右
C40: 商品圖 | D40: KI60415GG-1.JPG | G40: =IF(D40="","待填",IF(ISNUMBER(SEARCH(".",D40)),"OK","記得加副檔名")) -> OK | H40: 促標 | I40: 滿299享折扣 | L40: =IF(I40="","限6字",IF(LENB(I40)/2<=6,"OK","超過")) -> OK | M40: 促標 | N40: 滿299享折扣 | R40: =IF(N40="","限6字",IF(LENB(N40)/2<=6,"OK","超過")) -> OK
H41: 文案 | I41: 滿額送 | L41: =IF(I41="","限4字",IF(LENB(I41)/2<=4,"OK","超過")) -> OK | M41: 文案 | N41: 超值組 | R41: =IF(N41="","限4字",IF(LENB(N41)/2<=4,"OK","超過")) -> OK
M42: LOGO圖 | N42: Copy of SF_logo_596x596.png | R42: =IF(N42="","待填","OK") -> OK
M43: CTA (放03字) | N43: 逛逛去 | R43: =IF(N43="","待填","OK") -> OK
A45: MSBN | B45: D-1-3 MSBN-D-1-3 Band 7 | C45: 左右 | T45: D-1-3
C46: 項目文字 | D46: 記憶體 | G46: =IF(D46="","限4字",IF(LENB(D46)/2<=4,"OK","超過")) -> OK | H46: 內文 | I46: 128GB | L46: =IF(I46="","限9字",IF(LENB(I46)/2<=9,"OK","超過")) -> OK | M46: 內文 | N46: 256GB | R46: =IF(N46="","限9字",IF(LENB(N46)/2<=9,"OK","超過")) -> OK
C47: 項目文字 | D47: 營幕尺寸 | G47: =IF(D47="","限4字",IF(LENB(D47)/2<=4,"OK","超過")) -> OK | H47: 內文 | I47: 60吋 | L47: =IF(I47="","限9字",IF(LENB(I47)/2<=9,"OK","超過")) -> OK | M47: 內文 | N47: 80吋 | R47: =IF(N47="","限9字",IF(LENB(N47)/2<=9,"OK","超過")) -> OK
C48: 項目文字 | D48: 顏色 | G48: =IF(D48="","限4字",IF(LENB(D48)/2<=4,"OK","超過")) -> OK | H48: 內文 | I48: 紅 | L48: =IF(I48="","限9字",IF(LENB(I48)/2<=9,"OK","超過")) -> OK | M48: 內文 | N48: 白 | R48: =IF(N48="","限9字",IF(LENB(N48)/2<=9,"OK","超過")) -> OK
C49: 項目文字 | G49: =IF(D49="","限4字",IF(LENB(D49)/2<=4,"OK","超過")) -> 限4字 | H49: 內文 | L49: =IF(I49="","限9字",IF(LENB(I49)/2<=9,"OK","超過")) -> 限9字 | M49: 內文 | R49: =IF(N49="","限9字",IF(LENB(N49)/2<=9,"OK","超過")) -> 限9字
C50: 項目文字 | G50: =IF(D50="","限4字",IF(LENB(D50)/2<=4,"OK","超過")) -> 限4字 | H50: 內文 | L50: =IF(I50="","限9字",IF(LENB(I50)/2<=9,"OK","超過")) -> 限9字 | M50: 內文 | R50: =IF(N50="","限9字",IF(LENB(N50)/2<=9,"OK","超過")) -> 限9字
...

Sheet 設定
A1: 等級 | B1: MSBN額度 | C1: 資源1 | D1: 資源2 | E1: 資源3 | F1: 資源4 | G1: 資源5 | H1: 資源6 | I1: 資源7 | J1: 資源8 | K1: 資源9 | L1: 資源10 | M1: 資源11 | N1: 資源12 | O1: 類型1 | P1: 類型2 | Q1: 類型3 | R1: 類型4 | S1: 類型5 | T1: 類型6 | U1: 類型7 | V1: 類型8 | W1: 類型9 | X1: 類型10 | Y1: 類型11 | Z1: 類型12 | AB1: key | AC1: 顯示名稱 | AD1: 張數 | AE1: 尺寸 | AF1: 格式 | AG1: 規範字數 | AH1: 提醒 | AI1: 系統排版 | AJ1: 可用
A2: A Brand star (Mega) | B2: 8 | C2: LPBN | O2: 預設 | AB2: LPBN | AC2: LPBN | AD2: 2 | AE2: APP 1200×550 PC 1200×400 | AF2: JPG | AG2: 主標≤8；副標≤7；日期／警語≤14 | AH2: APP、PC 各 1 張 | AI2: LPBN_APP／LPBN_PC | AJ2: 是
A3: A Brand star (Mega) 資交 | B3: 4 | C3: LPBN | O3: 預設 | AB3: DDCard | AC3: DD Card BN (APP) | AD3: 1 | AE3: 531×792 | AF3: JPG | AG3: 品牌名≤9；主標≤8；副標≤7；日期/警語≤14 | AH3: LOGO、商品圖；CTA 依版型 | AI3: ddcard無logo／ddcard方logo／ddcard橫logo | AJ3: 是
A4: A 精選套裝 | B4: 4 | C4: LPBN | O4: 預設 | AB4: HBN | AC4: HBN (PC) | AD4: 1 | AE4: 1200×360 | AF4: JPG | AG4: 品牌名≤9；主標≤8；副標≤7；日期/警語≤14 | AH4: 橫式或方形 LOGO 版 | AI4: HBN_橫式LOGO／HBN_方式LOGO | AJ4: 是
A5: A 品牌旗艦MDD | B5: 6 | C5: LPBN | O5: 預設 | AB5: 活動總覽 | AC5: 活動總覽 | AD5: 1 | AE5: 依活動規格 | AF5: JPG/PNG | AG5: 依活動需求 | AH5: 目前系統尚未提供可編輯版型 | AI5: 尚未提供版型 | AJ5: 否
A6: A 品牌旗艦MDD 資交 | B6: 0 | C6: LPBN | O6: 預設 | AB6: 首頁LOGO牆 | AC6: 首頁 LOGO 牆 | AD6: 1 | AE6: 402×483 | AF6: JPG/PNG | AG6: LOGO／人物或商品圖可縮放 | AH6: LOGO 位於曝品或人物範圍內，可用滑鼠縮放 | AI6: 首頁LOGO牆 | AJ6: 是
A7: B+ BOD A | B7: 6 | C7: LPBN | D7: DDCard | E7: HBN | F7: 活動總覽 | G7: 首頁LOGO牆 | H7: AR | I7: FB_Post | J7: AMS BN | K7: Coin_page | L7: IG | M7: SearchIcon | N7: SearchImage | O7: 預設 | P7: 預設 | Q7: 預設 | R7: 預設 | S7: 預設 | T7: 預設 | U7: 預設 | V7: 預設 | W7: 選配 | X7: 選配 | Y7: 選配 | Z7: 選配 | AB7: AR | AC7: AR | AD7: 1 | AE7: 100×100（依規範） | AF7: JPG/PNG | AG7: 文案≤6 或 LOGO；2擇1 | AH7: 目前系統尚未提供可編輯版型 | AI7: 尚未提供版型 | AJ7: 否
A8: B+ BOD A 資交 | B8: 0 | C8: LPBN | D8: DDCard | E8: HBN | F8: 活動總覽 | G8: 首頁LOGO牆 | H8: AR | I8: FB_Post | J8: AMS BN | K8: Coin_page | L8: IG | M8: SearchIcon | N8: SearchImage | O8: 預設 | P8: 預設 | Q8: 預設 | R8: 預設 | S8: 預設 | T8: 預設 | U8: 預設 | V8: 預設 | W8: 選配 | X8: 選配 | Y8: 選配 | Z8: 選配 | AB8: FB_Post | AC8: FB POST | AD8: 1 | AE8: 1200×630 | AF8: JPG | AG8: 品牌名≤9；主標≤8；副標≤7；日期/警語≤14 | AH8: 方 LOGO／橫 LOGO | AI8: FB_POST_方LOGO／FB_POST_橫LOGO | AJ8: 是
A9: B+ BOD B (Mega) | B9: 6 | C9: LPBN | D9: DDCard | E9: HBN | F9: 活動總覽 | G9: 首頁LOGO牆 | H9: AR | I9: FB_Post | J9: AMS BN | K9: Coin_page | L9: IG | O9: 預設 | P9: 預設 | Q9: 預設 | R9: 預設 | S9: 預設 | T9: 預設 | U9: 選配 | V9: 選配 | W9: 選配 | X9: 選配 | AB9: AMS BN | AC9: AMS BN | AD9: 1 | AE9: 1077×264（依規範） | AF9: JPG | AG9: 依 AMS 規格 | AH9: 目前系統尚未提供可編輯版型 | AI9: 尚未提供版型 | AJ9: 否
A10: B+ 基礎套裝 | B10: 6 | C10: LPBN | D10: DDCard | E10: HBN | F10: 活動總覽 | G10: 首頁LOGO牆 | H10: AR | I10: FB_Post | J10: AMS BN | K10: Coin_page | L10: IG | O10: 預設 | P10: 預設 | Q10: 預設 | R10: 預設 | S10: 預設 | T10: 預設 | U10: 選配 | V10: 選配 | W10: 選配 | X10: 選配 | AB10: Coin_page | AC10: Coin Page BN | AD10: 1 | AE10: 1200×391 | AF10: JPG | AG10: 品牌名≤9；主標≤8；副標≤7；日期/警語≤14 | AH10: 方 LOGO／橫 LOGO | AI10: Coin_pageBN_APP方LOGO／Coin_pageBN_APP橫LOGO | AJ10: 是
A11: B JBP多店 | B11: 3 | C11: LPBN | D11: IG | E11: HBN | F11: DDCard | G11: Coin_page | H11: FB_Post | I11: SCPN | J11: SearchImage | K11: SearchIcon | O11: 預設 | P11: 預設 | Q11: 預設 | R11: 預設 | S11: 預設 | T11: 預設 | U11: 預設 | V11: 預設 | W11: 預設 | AB11: IG | AC11: IG | AD11: 1 | AE11: 900×1600 | AF11: JPG | AG11: 品牌名≤9；主標≤8；副標≤7；日期/警語≤14 | AH11: 方 LOGO／橫 LOGO | AI11: IG方logo排版／IG橫logo排版 | AJ11: 是
A12: B 金牌 (Mega) | B12: 3 | C12: LPBN | D12: DDCard | E12: HBN | F12: 活動總覽 | G12: AR | H12: Coin_page | O12: 預設 | P12: 預設 | Q12: 預設 | R12: 預設 | S12: 預設 | T12: 選配 | AB12: SearchIcon | AC12: Search ICON | AD12: 1 | AE12: 120×120＋84×84 | AF12: PNG | AG12: ICON 文案≤2；或 LOGO／商品圖 | AH12: 120×120 建議 <50KB，另輸出 84×84 | AI12: SearchICON_LOGO／PRODUCT／TEXT | AJ12: 是
AB13: SearchImage | AC13: Search Image | AD13: 1 | AE13: 1125×156 | AF13: JPG/PNG | AG13: 副標≤7；LOGO 1～3 個 | AH13: 依選用版型提供 1～3 個 LOGO | AI13: Search_Image1logo／2logo／3logo | AJ13: 是
AB14: SCPN | AC14: SCBN／SCPN | AD14: 1 | AE14: 1200×200 | AF14: JPG | AG14: 品牌名≤9；副標≤7；CTA | AH14: 商城橫幅 | AI14: SCBN_APP | AJ14: 是

Sheet _BODA_META
A1: BODA_WORKORDER_V2
A2: kind | B2: sourceKey | C2: band | D2: order | E2: family | F2: variant | G2: combo | H2: msbnFile | I2: position | J2: label | K2: address | L2: header | M2: file | N2: locked | O2: hint | P2: targetKey
A3: subarea | B3: top:0 | C3: 1 | D3: 1 | E3: F | F3: 1 | G3: 1 | I3: 1 | J3: LOGO圖 | K3: D4 | L3: 款式 1-1 | M3: 副區-F-1-1.jpg | N3: 0 | O3: (檔名/券名)
A4: subarea | B4: top:0 | C4: 1 | D4: 1 | E4: F | F4: 1 | G4: 1 | I4: 1 | J4: 商品 | K4: D5 | L4: 款式 1-1 | M4: 副區-F-1-1.jpg | N4: 0 | O4: (檔名/券名)
A5: subarea | B5: top:0 | C5: 1 | D5: 1 | E5: F | F5: 1 | G5: 1 | I5: 1 | J5: 品名 | K5: D6 | L5: 款式 1-1 | M5: 副區-F-1-1.jpg | N5: 0 | O5: 限5個字
A6: subarea | B6: top:0 | C6: 1 | D6: 1 | E6: F | F6: 1 | G6: 1 | I6: 1 | J6: 警語 | K6: D7 | L6: 款式 1-1 | M6: 副區-F-1-1.jpg | N6: 0 | O6: 限6個字
A7: subarea | B7: top:1 | C7: 1 | D7: 2 | E7: F | F7: 1 | G7: 1 | I7: 2 | J7: LOGO圖 | K7: H4 | L7: 款式 1-1 | M7: 副區-F-1-1.jpg | N7: 0 | O7: (檔名/券名)
A8: subarea | B8: top:1 | C8: 1 | D8: 2 | E8: F | F8: 1 | G8: 1 | I8: 2 | J8: 商品 | K8: H5 | L8: 款式 1-1 | M8: 副區-F-1-1.jpg | N8: 0 | O8: (檔名/券名)
A9: subarea | B9: top:1 | C9: 1 | D9: 2 | E9: F | F9: 1 | G9: 1 | I9: 2 | J9: 品名 | K9: H6 | L9: 款式 1-1 | M9: 副區-F-1-1.jpg | N9: 0 | O9: 限5個字
A10: subarea | B10: top:1 | C10: 1 | D10: 2 | E10: F | F10: 1 | G10: 1 | I10: 2 | J10: 警語 | K10: H7 | L10: 款式 1-1 | M10: 副區-F-1-1.jpg | N10: 0 | O10: 限6個字
A11: subarea | B11: top:2 | C11: 1 | D11: 3 | E11: F | F11: 1 | G11: 1 | I11: 3 | J11: LOGO圖 | K11: L4 | L11: 款式 1-1 | M11: 副區-F-1-1.jpg | N11: 0 | O11: (檔名/券名)
A12: subarea | B12: top:2 | C12: 1 | D12: 3 | E12: F | F12: 1 | G12: 1 | I12: 3 | J12: 商品 | K12: L5 | L12: 款式 1-1 | M12: 副區-F-1-1.jpg | N12: 0 | O12: (檔名/券名)
A13: subarea | B13: top:2 | C13: 1 | D13: 3 | E13: F | F13: 1 | G13: 1 | I13: 3 | J13: 品名 | K13: L6 | L13: 款式 1-1 | M13: 副區-F-1-1.jpg | N13: 0 | O13: 限5個字
A14: subarea | B14: top:2 | C14: 1 | D14: 3 | E14: F | F14: 1 | G14: 1 | I14: 3 | J14: 警語 | K14: L7 | L14: 款式 1-1 | M14: 副區-F-1-1.jpg | N14: 0 | O14: 限6個字
... A18: subarea | B18: top:3 | C18: 1 | D18: 4 | E18: F | F18: 1 | G18: 1 | I18: 4 | J18: 警語 | K18: P7 | L18: 款式 1-1 | M18: 副區-F-1-1.jpg | N18: 0 | O18: 限6個字
A19: msbn | B19: msbn:0 | C19: 2 | D19: 5 | H19: MSBN-A-1-1.jpg | I19: 1 | J19: 促標 | K19: D12 | L19: A-1-1 | M19: MSBN-A-1-1.jpg | N19: 0 | O19: 促標最多7字內
A20: msbn | B20: msbn:0 | C20: 2 | D20: 5 | H20: MSBN-A-1-1.jpg | I20: 1 | J20: 商品 | K20: H12 | L20: A-1-1 | M20: MSBN-A-1-1.jpg | N20: 0 | O20: (圖檔名)
A21: msbn | B21: msbn:0 | C21: 2 | D21: 5 | H21: MSBN-A-1-1.jpg | I21: 1 | J21: 品名 | K21: D13 | L21: A-1-1 | M21: MSBN-A-1-1.jpg | N21: 0 | O21: 品名一排最多8字
A22: msbn | B22: msbn:0 | C22: 2 | D22: 5 | H22: MSBN-A-1-1.jpg | I22: 1 | J22: 代言人圖 | K22: H13 | L22: A-1-1 | M22: MSBN-A-1-1.jpg | N22: 0 | O22: (圖檔名)
A23: msbn | B23: msbn:0 | C23: 2 | D23: 5 | H23: MSBN-A-1-1.jpg | I23: 1 | J23: 品名 | K23: D14 | L23: A-1-1 | M23: MSBN-A-1-1.jpg | N23: 0 | O23: 品名一排最多8字
A24: msbn | B24: msbn:0 | C24: 2 | D24: 5 | H24: MSBN-A-1-1.jpg | I24: 1 | J24: 圓標 | K24: H14 | L24: A-1-1 | M24: MSBN-A-1-1.jpg | N24: 0 | O24: 圓標05字內
A25: msbn | B25: msbn:0 | C25: 2 | D25: 5 | H25: MSBN-A-1-1.jpg | I25: 1 | J25: 警語 | K25: D15 | L25: A-1-1 | M25: MSBN-A-1-1.jpg | N25: 0 | O25: 小字最多可9個字內
A26: msbn | B26: msbn:0 | C26: 2 | D26: 5 | H26: MSBN-A-1-1.jpg | I26: 1 | J26: 簽名小字 | K26: H15 | L26: A-1-1 | M26: MSBN-A-1-1.jpg | N26: 0 | O26: 每行限5字
A27: msbn | B27: msbn:0 | C27: 2 | D27: 5 | H27: MSBN-A-1-1.jpg | I27: 1 | J27: 簽名小字 | K27: H16 | L27: A-1-1 | M27: MSBN-A-1-1.jpg | N27: 0 | O27: 每行限5字
A28: msbn | B28: msbn:0 | C28: 2 | D28: 5 | H28: MSBN-A-1-1.jpg | I28: 1 | J28: 簽名圖 | K28: H17 | L28: A-1-1 | M28: MSBN-A-1-1.jpg | N28: 0 | O28: (檔名)
A29: msbn | B29: msbn:0 | C29: 2 | D29: 5 | H29: MSBN-A-1-1.jpg | I29: 1 | J29: CTA | K29: H18 | L29: A-1-1 | M29: MSBN-A-1-1.jpg | N29: 0 | O29: 逛逛去
A30: subarea | B30: msbn-sub:1:0 | C30: 3 | D30: 6 | E30: F | F30: 1 | G30: 1 | I30: 1 | J30: LOGO圖 | K30: D21 | L30: 款式 1-1 | M30: 副區-F-1-1.jpg | N30: 0 | O30: (檔名/券名)
A31: subarea | B31: msbn-sub:1:0 | C31: 3 | D31: 6 | E31: F | F31: 1 | G31: 1 | I31: 1 | J31: 商品 | K31: D22 | L31: 款式 1-1 | M31: 副區-F-1-1.jpg | N31: 0 | O31: (檔名/券名)
A32: subarea | B32: msbn-sub:1:0 | C32: 3 | D32: 6 | E32: F | F32: 1 | G32: 1 | I32: 1 | J32: 品名 | K32: D23 | L32: 款式 1-1 | M32: 副區-F-1-1.jpg | N32: 0 | O32: 限5個字
A33: subarea | B33: msbn-sub:1:0 | C33: 3 | D33: 6 | E33: F | F33: 1 | G33: 1 | I33: 1 | J33: 警語 | K33: D24 | L33: 款式 1-1 | M33: 副區-F-1-1.jpg | N33: 0 | O33: 限6個字
A34: subarea | B34: msbn-sub:1:1 | C34: 3 | D34: 7 | E34: F | F34: 1 | G34: 1 | I34: 2 | J34: LOGO圖 | K34: H21 | L34: 款式 1-1 | M34: 副區-F-1-1.jpg | N34: 0 | O34: (檔名/券名)
A35: subarea | B35: msbn-sub:1:1 | C35: 3 | D35: 7 | E35: F | F35: 1 | G35: 1 | I35: 2 | J35: 商品 | K35: H22 | L35: 款式 1-1 | M35: 副區-F-1-1.jpg | N35: 0 | O35: (檔名/券名)
A36: subarea | B36: msbn-sub:1:1 | C36: 3 | D36: 7 | E36: F | F36: 1 | G36: 1 | I36: 2 | J36: 品名 | K36: H23 | L36: 款式 1-1 | M36: 副區-F-1-1.jpg | N36: 0 | O36: 限5個字
A37: subarea | B37: msbn-sub:1:1 | C37: 3 | D37: 7 | E37: F | F37: 1 | G37: 1 | I37: 2 | J37: 警語 | K37: H24 | L37: 款式 1-1 | M37: 副區-F-1-1.jpg | N37: 0 | O37: 限6個字
A38: subarea | B38: msbn-sub:1:2 | C38: 3 | D38: 8 | E38: F | F38: 1 | G38: 1 | I38: 3 | J38: LOGO圖 | K38: L21 | L38: 款式 1-1 | M38: 副區-F-1-1.jpg | N38: 0 | O38: (檔名/券名)
A39: subarea | B39: msbn-sub:1:2 | C39: 3 | D39: 8 | E39: F | F39: 1 | G39: 1 | I39: 3 | J39: 商品 | K39: L22 | L39: 款式 1-1 | M39: 副區-F-1-1.jpg | N39: 0 | O39: (檔名/券名)
A40: subarea | B40: msbn-sub:1:2 | C40: 3 | D40: 8 | E40: F | F40: 1 | G40: 1 | I40: 3 | J40: 品名 | K40: L23 | L40: 款式 1-1 | M40: 副區-F-1-1.jpg | N40: 0 | O40: 限5個字
A41: subarea | B41: msbn-sub:1:2 | C41: 3 | D41: 8 | E41: F | F41: 1 | G41: 1 | I41: 3 | J41: 警語 | K41: L24 | L41: 款式 1-1 | M41: 副區-F-1-1.jpg | N41: 0 | O41: 限6個字
... A45: subarea | B45: msbn-sub:1:3 | C45: 3 | D45: 9 | E45: F | F45: 1 | G45: 1 | I45: 4 | J45: 警語 | K45: P24 | L45: 款式 1-1 | M45: 副區-F-1-1.jpg | N45: 0 | O45: 限6個字
A46: msbn | B46: msbn:2 | C46: 4 | D46: 10 | H46: MSBN-B-3-3.jpg | I46: 1 | J46: LOGO圖 | K46: D29 | L46: B-3-3 | M46: MSBN-B-3-3.jpg | N46: 0 | O46: (檔名/券名)
...

Sheet _BODA_BOTTOM
A1: BODA_BOTTOM_V1 | B1: MS Layout
A2: group | B2: title | C2: iconAddress | D2: logoAddress | E2: textAddress | F2: countAddress | G2: optional
A3: 1 | B3: 第1顆 | C3: E53 | D3: E54 | E3: C55 | F3: G55 | G3: 0
A4: 2 | B4: 第2顆 | C4: J53 | D4: J54 | E4: H55 | F4: L55 | G4: 0
A5: 3 | B5: 第3顆 | C5: O53 | D5: O54 | E5: M55 | F5: Q55 | G5: 1
A6: 4 | B6: 第4顆 | C6: T53 | D6: T54 | E6: R55 | F6: Y55 | G6: 1
A7: 5 | B7: 第5顆 | C7: AB53 | D7: AB54 | E7: Z55 | F7: AG55 | G7: 1

Sheet _BODA_BOTTOM_STATE
A1: BODA_BOTTOM_STATE_V1 | B1: 1 | C1: JSON chunks
A3: 1 | B3: { "format": "sticky-banner-project", "version": 2, "activeBannerIndex": 0, "sharpen": true, "banners": [ { "slotCount": 5, "activeSlotIndex": 0, "accentColor": "red", "slots": [ { "text": "主會場", "iconId": "bod-logo", "iconText": null }, { "text": "", "iconId": null, "iconText": null }, { "text": "", "iconId": null, "iconText": null }, { "text": "", "iconId": null, "iconText": null }, { "text": "", "iconId": null, "iconText": null } ] } ], "customIcons": [] }

Sheet _BODA_RULES
A1: keyword | B1: replacement | C1: action
A2: 撒 | B2: 自動改成"灑" | C2: replace
A3: 購物金 | B3: 自動改成"優惠券" | C3: replace
A4: 抵用券 | B4: 自動改成"優惠券" | C4: replace
A5: 折價券 | B5: 自動改成"優惠券" | C5: replace
A6: 蝦皮券 | B6: 自動改成"優惠券" | C6: replace
A7: 蝦幣券 | B7: 自動改成"優惠券" | C7: replace
A8: 折扣券 | B8: 自動改成"優惠券" | C8: replace
A9: $蝦幣 | B9: 自動改成"蝦幣" | C9: replace
A10: 蝦幣$ | B10: 自動改成"蝦幣" | C10: replace
A11: \$\d+\s*蝦幣 | B11: 自動改成"蝦幣" | C11: replace
A12: 元 | B12: 直接無法輸入 | C12: block
... A69: 兩 | B69: 自動改成"2" | C69: replace
