Workbook

Sheet 工單總覽
A1: BODA 工單總覽
A3: 包套(等級) | B3: B+ BOD A | E3: MSBN 額度 | F3: =IFERROR(VLOOKUP(B3,'設定'!$A$2:$B$12,2,FALSE),0) -> 6 | H3: 輸出時間 | I3: 46269.385
A4: 負責人 | E4: 版本 | F4: V1 | H4: 更新重點
A5: 活動時間 | E5: 美術 Deadline | H5: 總製作張數 | I5: =SUM(C21:C32)+107 -> 116
A6: 工作項目名稱 | E6: 行銷目標
A7: 目標客群
A9: 曝光資源共用文案與色彩
A10: 背景顏色 | B10: #ff69b4 | E10: 連動規則 | F10: 與「曝光資源」背景色、匯入工單統一背景及 MSBN D 系列卡片背景同步；此處記錄匯出當下色號。
A11: 品牌名 | E11: 上限 9 | F11: 曝光資源品牌名稱；中文 1、英數 0.5。 | I11: =IF(B11="","限9字",IF(LENB(B11)/2<=9,"OK","超過")) -> 限9字
A12: 主標 | E12: 上限 8 | F12: 曝光資源主標；中文 1、英數 0.5。 | I12: =IF(B12="","限8字",IF(LENB(B12)/2<=8,"OK","超過")) -> 限8字
A13: 副標 | E13: 上限 7 | F13: 曝光資源副標；中文 1、英數 0.5。 | I13: =IF(B13="","限7字",IF(LENB(B13)/2<=7,"OK","超過")) -> 限7字
A14: 日期／警語 | E14: 上限 14 | F14: 日期、活動期間或警語；中文 1、英數 0.5。 | I14: =IF(B14="","限14字",IF(LENB(B14)/2<=14,"OK","超過")) -> 限14字
A15: ICON 獨立文案 | E15: 上限 2 | F15: Search ICON 文字版；也可改用 LOGO／商品圖；中文 1、英數 0.5。 | I15: =IF(B15="","限2字",IF(LENB(B15)/2<=2,"OK","超過")) -> 限2字
A16: LOGO圖（多圖用逗號分開） | E16: LOGO圖片最多3張 | F16: 讀取 LOGO 檔名；多張請用逗號分隔。 | I16: =IF(B16="","限3張",IF(LEN(B16)-LEN(SUBSTITUTE(B16,",",""))+1<=3,"OK","超過")) -> 限3張
A17: 曝光資源圖片 | B17: 1.png, 2.png, 3.png | E17: 上限 3張 | F17: 讀取曝品檔名；多張請用逗號分隔。 | I17: =IF(B17="","限3張",IF(LEN(B17)-LEN(SUBSTITUTE(B17,",",""))+1<=3,"OK","超過")) -> OK
A19: 製作曝光資源（依包套／等級自動切換；預設張數可手動調整，選配預設為 0）
A20: 版位 | B20: 類型 | C20: 張數 | D20: 尺寸 | E20: 格式 | F20: 規範字數 | G20: 提醒 | H20: 系統排版 | I20: Check
A21: {=IFERROR(INDEX('設定'!$C$2:$N$12,MATCH($B$3,'設定'!$A$2:$A$12,0),1),"")} -> LPBN | B21: {=IFERROR(INDEX('設定'!$O$2:$Z$12,MATCH($B$3,'設定'!$A$2:$A$12,0),1),"")} -> 預設 | C21: =IF(A21="","",IF(B21="預設",IFERROR(VLOOKUP(A21,'設定'!$AB$2:$AJ$14,3,FALSE),1),0)) -> 2 | D21: =IF(A21="","",IFERROR(VLOOKUP(A21,'設定'!$AB$2:$AJ$14,4,FALSE),"")) -> APP 1200×550 PC 1200×400 | E21: =IF(A21="","",IFERROR(VLOOKUP(A21,'設定'!$AB$2:$AJ$14,5,FALSE),"")) -> JPG | F21: =IF(A21="","",IFERROR(VLOOKUP(A21,'設定'!$AB$2:$AJ$14,6,FALSE),"")) -> 主標≤8；副標≤7；日期／警語≤14 | G21: =IF(A21="","",IFERROR(VLOOKUP(A21,'設定'!$AB$2:$AJ$14,7,FALSE),"")) -> APP、PC 各 1 張 | H21: =IF(A21="","",IFERROR(VLOOKUP(A21,'設定'!$AB$2:$AJ$14,8,FALSE),"尚未提供版型")) -> LPBN_APP／LPBN_PC | I21: =IF(A21="","",IF(C21=0,"未選",IF(H21="尚未提供版型","缺版型","待製作"))) -> 待製作
A22: {=IFERROR(INDEX('設定'!$C$2:$N$12,MATCH($B$3,'設定'!$A$2:$A$12,0),2),"")} -> DDCard | B22: {=IFERROR(INDEX('設定'!$O$2:$Z$12,MATCH($B$3,'設定'!$A$2:$A$12,0),2),"")} -> 預設 | C22: =IF(A22="","",IF(B22="預設",IFERROR(VLOOKUP(A22,'設定'!$AB$2:$AJ$14,3,FALSE),1),0)) -> 1 | D22: =IF(A22="","",IFERROR(VLOOKUP(A22,'設定'!$AB$2:$AJ$14,4,FALSE),"")) -> 531×792 | E22: =IF(A22="","",IFERROR(VLOOKUP(A22,'設定'!$AB$2:$AJ$14,5,FALSE),"")) -> JPG | F22: =IF(A22="","",IFERROR(VLOOKUP(A22,'設定'!$AB$2:$AJ$14,6,FALSE),"")) -> 品牌名≤9；主標≤8；副標≤7；日期/警語≤14 | G22: =IF(A22="","",IFERROR(VLOOKUP(A22,'設定'!$AB$2:$AJ$14,7,FALSE),"")) -> LOGO、商品圖；CTA 依版型 | H22: =IF(A22="","",IFERROR(VLOOKUP(A22,'設定'!$AB$2:$AJ$14,8,FALSE),"尚未提供版型")) -> ddcard無logo／ddcard方logo／ddcard橫logo | I22: =IF(A22="","",IF(C22=0,"未選",IF(H22="尚未提供版型","缺版型","待製作"))) -> 待製作
A23: {=IFERROR(INDEX('設定'!$C$2:$N$12,MATCH($B$3,'設定'!$A$2:$A$12,0),3),"")} -> HBN | B23: {=IFERROR(INDEX('設定'!$O$2:$Z$12,MATCH($B$3,'設定'!$A$2:$A$12,0),3),"")} -> 預設 | C23: =IF(A23="","",IF(B23="預設",IFERROR(VLOOKUP(A23,'設定'!$AB$2:$AJ$14,3,FALSE),1),0)) -> 1 | D23: =IF(A23="","",IFERROR(VLOOKUP(A23,'設定'!$AB$2:$AJ$14,4,FALSE),"")) -> 1200×360 | E23: =IF(A23="","",IFERROR(VLOOKUP(A23,'設定'!$AB$2:$AJ$14,5,FALSE),"")) -> JPG | F23: =IF(A23="","",IFERROR(VLOOKUP(A23,'設定'!$AB$2:$AJ$14,6,FALSE),"")) -> 品牌名≤9；主標≤8；副標≤7；日期/警語≤14 | G23: =IF(A23="","",IFERROR(VLOOKUP(A23,'設定'!$AB$2:$AJ$14,7,FALSE),"")) -> 橫式或方形 LOGO 版 | H23: =IF(A23="","",IFERROR(VLOOKUP(A23,'設定'!$AB$2:$AJ$14,8,FALSE),"尚未提供版型")) -> HBN_橫式LOGO／HBN_方式LOGO | I23: =IF(A23="","",IF(C23=0,"未選",IF(H23="尚未提供版型","缺版型","待製作"))) -> 待製作
A24: {=IFERROR(INDEX('設定'!$C$2:$N$12,MATCH($B$3,'設定'!$A$2:$A$12,0),4),"")} -> 活動總覽 | B24: {=IFERROR(INDEX('設定'!$O$2:$Z$12,MATCH($B$3,'設定'!$A$2:$A$12,0),4),"")} -> 預設 | C24: =IF(A24="","",IF(B24="預設",IFERROR(VLOOKUP(A24,'設定'!$AB$2:$AJ$14,3,FALSE),1),0)) -> 1 | D24: =IF(A24="","",IFERROR(VLOOKUP(A24,'設定'!$AB$2:$AJ$14,4,FALSE),"")) -> 依活動規格 | E24: =IF(A24="","",IFERROR(VLOOKUP(A24,'設定'!$AB$2:$AJ$14,5,FALSE),"")) -> JPG/PNG | F24: =IF(A24="","",IFERROR(VLOOKUP(A24,'設定'!$AB$2:$AJ$14,6,FALSE),"")) -> 依活動需求 | G24: =IF(A24="","",IFERROR(VLOOKUP(A24,'設定'!$AB$2:$AJ$14,7,FALSE),"")) -> 目前系統尚未提供可編輯版型 | H24: =IF(A24="","",IFERROR(VLOOKUP(A24,'設定'!$AB$2:$AJ$14,8,FALSE),"尚未提供版型")) -> 尚未提供版型 | I24: =IF(A24="","",IF(C24=0,"未選",IF(H24="尚未提供版型","缺版型","待製作"))) -> 缺版型
A25: {=IFERROR(INDEX('設定'!$C$2:$N$12,MATCH($B$3,'設定'!$A$2:$A$12,0),5),"")} -> 首頁LOGO牆 | B25: {=IFERROR(INDEX('設定'!$O$2:$Z$12,MATCH($B$3,'設定'!$A$2:$A$12,0),5),"")} -> 預設 | C25: =IF(A25="","",IF(B25="預設",IFERROR(VLOOKUP(A25,'設定'!$AB$2:$AJ$14,3,FALSE),1),0)) -> 1 | D25: =IF(A25="","",IFERROR(VLOOKUP(A25,'設定'!$AB$2:$AJ$14,4,FALSE),"")) -> 402×483 | E25: =IF(A25="","",IFERROR(VLOOKUP(A25,'設定'!$AB$2:$AJ$14,5,FALSE),"")) -> JPG/PNG | F25: =IF(A25="","",IFERROR(VLOOKUP(A25,'設定'!$AB$2:$AJ$14,6,FALSE),"")) -> LOGO／人物或商品圖可縮放 | G25: =IF(A25="","",IFERROR(VLOOKUP(A25,'設定'!$AB$2:$AJ$14,7,FALSE),"")) -> LOGO 位於曝品或人物範圍內，可用滑鼠縮放 | H25: =IF(A25="","",IFERROR(VLOOKUP(A25,'設定'!$AB$2:$AJ$14,8,FALSE),"尚未提供版型")) -> 首頁LOGO牆 | I25: =IF(A25="","",IF(C25=0,"未選",IF(H25="尚未提供版型","缺版型","待製作"))) -> 待製作
A26: {=IFERROR(INDEX('設定'!$C$2:$N$12,MATCH($B$3,'設定'!$A$2:$A$12,0),6),"")} -> AR | B26: {=IFERROR(INDEX('設定'!$O$2:$Z$12,MATCH($B$3,'設定'!$A$2:$A$12,0),6),"")} -> 預設 | C26: =IF(A26="","",IF(B26="預設",IFERROR(VLOOKUP(A26,'設定'!$AB$2:$AJ$14,3,FALSE),1),0)) -> 1 | D26: =IF(A26="","",IFERROR(VLOOKUP(A26,'設定'!$AB$2:$AJ$14,4,FALSE),"")) -> 100×100（依規範） | E26: =IF(A26="","",IFERROR(VLOOKUP(A26,'設定'!$AB$2:$AJ$14,5,FALSE),"")) -> JPG/PNG | F26: =IF(A26="","",IFERROR(VLOOKUP(A26,'設定'!$AB$2:$AJ$14,6,FALSE),"")) -> 文案≤6 或 LOGO；2擇1 | G26: =IF(A26="","",IFERROR(VLOOKUP(A26,'設定'!$AB$2:$AJ$14,7,FALSE),"")) -> 目前系統尚未提供可編輯版型 | H26: =IF(A26="","",IFERROR(VLOOKUP(A26,'設定'!$AB$2:$AJ$14,8,FALSE),"尚未提供版型")) -> 尚未提供版型 | I26: =IF(A26="","",IF(C26=0,"未選",IF(H26="尚未提供版型","缺版型","待製作"))) -> 缺版型
A27: {=IFERROR(INDEX('設定'!$C$2:$N$12,MATCH($B$3,'設定'!$A$2:$A$12,0),7),"")} -> FB_Post | B27: {=IFERROR(INDEX('設定'!$O$2:$Z$12,MATCH($B$3,'設定'!$A$2:$A$12,0),7),"")} -> 預設 | C27: =IF(A27="","",IF(B27="預設",IFERROR(VLOOKUP(A27,'設定'!$AB$2:$AJ$14,3,FALSE),1),0)) -> 1 | D27: =IF(A27="","",IFERROR(VLOOKUP(A27,'設定'!$AB$2:$AJ$14,4,FALSE),"")) -> 1200×630 | E27: =IF(A27="","",IFERROR(VLOOKUP(A27,'設定'!$AB$2:$AJ$14,5,FALSE),"")) -> JPG | F27: =IF(A27="","",IFERROR(VLOOKUP(A27,'設定'!$AB$2:$AJ$14,6,FALSE),"")) -> 品牌名≤9；主標≤8；副標≤7；日期/警語≤14 | G27: =IF(A27="","",IFERROR(VLOOKUP(A27,'設定'!$AB$2:$AJ$14,7,FALSE),"")) -> 方 LOGO／橫 LOGO | H27: =IF(A27="","",IFERROR(VLOOKUP(A27,'設定'!$AB$2:$AJ$14,8,FALSE),"尚未提供版型")) -> FB_POST_方LOGO／FB_POST_橫LOGO | I27: =IF(A27="","",IF(C27=0,"未選",IF(H27="尚未提供版型","缺版型","待製作"))) -> 待製作
A28: {=IFERROR(INDEX('設定'!$C$2:$N$12,MATCH($B$3,'設定'!$A$2:$A$12,0),8),"")} -> AMS BN | B28: {=IFERROR(INDEX('設定'!$O$2:$Z$12,MATCH($B$3,'設定'!$A$2:$A$12,0),8),"")} -> 預設 | C28: =IF(A28="","",IF(B28="預設",IFERROR(VLOOKUP(A28,'設定'!$AB$2:$AJ$14,3,FALSE),1),0)) -> 1 | D28: =IF(A28="","",IFERROR(VLOOKUP(A28,'設定'!$AB$2:$AJ$14,4,FALSE),"")) -> 1077×264（依規範） | E28: =IF(A28="","",IFERROR(VLOOKUP(A28,'設定'!$AB$2:$AJ$14,5,FALSE),"")) -> JPG | F28: =IF(A28="","",IFERROR(VLOOKUP(A28,'設定'!$AB$2:$AJ$14,6,FALSE),"")) -> 依 AMS 規格 | G28: =IF(A28="","",IFERROR(VLOOKUP(A28,'設定'!$AB$2:$AJ$14,7,FALSE),"")) -> 目前系統尚未提供可編輯版型 | H28: =IF(A28="","",IFERROR(VLOOKUP(A28,'設定'!$AB$2:$AJ$14,8,FALSE),"尚未提供版型")) -> 尚未提供版型 | I28: =IF(A28="","",IF(C28=0,"未選",IF(H28="尚未提供版型","缺版型","待製作"))) -> 缺版型
A29: {=IFERROR(INDEX('設定'!$C$2:$N$12,MATCH($B$3,'設定'!$A$2:$A$12,0),9),"")} -> Coin_page | B29: {=IFERROR(INDEX('設定'!$O$2:$Z$12,MATCH($B$3,'設定'!$A$2:$A$12,0),9),"")} -> 選配 | C29: =IF(A29="","",IF(B29="預設",IFERROR(VLOOKUP(A29,'設定'!$AB$2:$AJ$14,3,FALSE),1),0)) -> 0 | D29: =IF(A29="","",IFERROR(VLOOKUP(A29,'設定'!$AB$2:$AJ$14,4,FALSE),"")) -> 1200×391 | E29: =IF(A29="","",IFERROR(VLOOKUP(A29,'設定'!$AB$2:$AJ$14,5,FALSE),"")) -> JPG | F29: =IF(A29="","",IFERROR(VLOOKUP(A29,'設定'!$AB$2:$AJ$14,6,FALSE),"")) -> 品牌名≤9；主標≤8；副標≤7；日期/警語≤14 | G29: =IF(A29="","",IFERROR(VLOOKUP(A29,'設定'!$AB$2:$AJ$14,7,FALSE),"")) -> 方 LOGO／橫 LOGO | H29: =IF(A29="","",IFERROR(VLOOKUP(A29,'設定'!$AB$2:$AJ$14,8,FALSE),"尚未提供版型")) -> Coin_pageBN_APP方LOGO／Coin_pageBN_APP橫LOGO | I29: =IF(A29="","",IF(C29=0,"未選",IF(H29="尚未提供版型","缺版型","待製作"))) -> 未選
A30: {=IFERROR(INDEX('設定'!$C$2:$N$12,MATCH($B$3,'設定'!$A$2:$A$12,0),10),"")} -> IG | B30: {=IFERROR(INDEX('設定'!$O$2:$Z$12,MATCH($B$3,'設定'!$A$2:$A$12,0),10),"")} -> 選配 | C30: =IF(A30="","",IF(B30="預設",IFERROR(VLOOKUP(A30,'設定'!$AB$2:$AJ$14,3,FALSE),1),0)) -> 0 | D30: =IF(A30="","",IFERROR(VLOOKUP(A30,'設定'!$AB$2:$AJ$14,4,FALSE),"")) -> 900×1600 | E30: =IF(A30="","",IFERROR(VLOOKUP(A30,'設定'!$AB$2:$AJ$14,5,FALSE),"")) -> JPG | F30: =IF(A30="","",IFERROR(VLOOKUP(A30,'設定'!$AB$2:$AJ$14,6,FALSE),"")) -> 品牌名≤9；主標≤8；副標≤7；日期/警語≤14 | G30: =IF(A30="","",IFERROR(VLOOKUP(A30,'設定'!$AB$2:$AJ$14,7,FALSE),"")) -> 方 LOGO／橫 LOGO | H30: =IF(A30="","",IFERROR(VLOOKUP(A30,'設定'!$AB$2:$AJ$14,8,FALSE),"尚未提供版型")) -> IG方logo排版／IG橫logo排版 | I30: =IF(A30="","",IF(C30=0,"未選",IF(H30="尚未提供版型","缺版型","待製作"))) -> 未選
A31: {=IFERROR(INDEX('設定'!$C$2:$N$12,MATCH($B$3,'設定'!$A$2:$A$12,0),11),"")} -> SearchIcon | B31: {=IFERROR(INDEX('設定'!$O$2:$Z$12,MATCH($B$3,'設定'!$A$2:$A$12,0),11),"")} -> 選配 | C31: =IF(A31="","",IF(B31="預設",IFERROR(VLOOKUP(A31,'設定'!$AB$2:$AJ$14,3,FALSE),1),0)) -> 0 | D31: =IF(A31="","",IFERROR(VLOOKUP(A31,'設定'!$AB$2:$AJ$14,4,FALSE),"")) -> 120×120＋84×84 | E31: =IF(A31="","",IFERROR(VLOOKUP(A31,'設定'!$AB$2:$AJ$14,5,FALSE),"")) -> PNG | F31: =IF(A31="","",IFERROR(VLOOKUP(A31,'設定'!$AB$2:$AJ$14,6,FALSE),"")) -> ICON 文案≤2；或 LOGO／商品圖 | G31: =IF(A31="","",IFERROR(VLOOKUP(A31,'設定'!$AB$2:$AJ$14,7,FALSE),"")) -> 120×120 建議 <50KB，另輸出 84×84 | H31: =IF(A31="","",IFERROR(VLOOKUP(A31,'設定'!$AB$2:$AJ$14,8,FALSE),"尚未提供版型")) -> SearchICON_LOGO／PRODUCT／TEXT | I31: =IF(A31="","",IF(C31=0,"未選",IF(H31="尚未提供版型","缺版型","待製作"))) -> 未選
A32: {=IFERROR(INDEX('設定'!$C$2:$N$12,MATCH($B$3,'設定'!$A$2:$A$12,0),12),"")} -> SearchImage | B32: {=IFERROR(INDEX('設定'!$O$2:$Z$12,MATCH($B$3,'設定'!$A$2:$A$12,0),12),"")} -> 選配 | C32: =IF(A32="","",IF(B32="預設",IFERROR(VLOOKUP(A32,'設定'!$AB$2:$AJ$14,3,FALSE),1),0)) -> 0 | D32: =IF(A32="","",IFERROR(VLOOKUP(A32,'設定'!$AB$2:$AJ$14,4,FALSE),"")) -> 1125×156 | E32: =IF(A32="","",IFERROR(VLOOKUP(A32,'設定'!$AB$2:$AJ$14,5,FALSE),"")) -> JPG/PNG | F32: =IF(A32="","",IFERROR(VLOOKUP(A32,'設定'!$AB$2:$AJ$14,6,FALSE),"")) -> 副標≤7；LOGO 1～3 個 | G32: =IF(A32="","",IFERROR(VLOOKUP(A32,'設定'!$AB$2:$AJ$14,7,FALSE),"")) -> 依選用版型提供 1～3 個 LOGO | H32: =IF(A32="","",IFERROR(VLOOKUP(A32,'設定'!$AB$2:$AJ$14,8,FALSE),"尚未提供版型")) -> Search_Image1logo／2logo／3logo | I32: =IF(A32="","",IF(C32=0,"未選",IF(H32="尚未提供版型","缺版型","待製作"))) -> 未選
A35: 全版位排版檢查（副區＋MSBN；內容欄與視覺參考請至 MS Layout 查看）
A36: 類型 | B36: 版位名稱 | C36: Band | D36: 位置數 | E36: 素材檔案 | F36: 字數／欄位規則 | G36: 提醒 | H36: MS Layout | I36: Check
A37: 副區 | B37: 副區 一排3（左／中／右） | C37: 1 | D37: 3 | E37: 副區-A-1-1.jpg / 副區-A-1-2.jpg / 副區-A-1-3.jpg | F37: 限8個字；(檔名/券名)；限10個字 | G37: 綠色欄位可填；固定欄位已鎖 | H37: 第 3 列 | I37: 待填
A38: 副區 | B38: 副區 一排3（左／中／右） | C38: 2 | D38: 3 | E38: 副區-A-1-4.jpg / 副區-A-2-1.jpg / 副區-A-2-2.jpg | F38: 限8個字；(檔名/券名)；限10個字；限5個字 | G38: 綠色欄位可填；固定欄位已鎖 | H38: 第 11 列 | I38: 待填
A39: 副區 | B39: 副區 一排3（左／中／右） | C39: 3 | D39: 3 | E39: 副區-A-2-3.jpg / 副區-A-2-4.jpg / 副區-A-3-1.jpg | F39: 限8個字；(檔名/券名)；限10個字；限5個字；(icon圖，無文字) | G39: 綠色欄位可填；固定欄位已鎖 | H39: 第 19 列 | I39: 待填
A40: 副區 | B40: 副區 一排3（左／中／右） | C40: 4 | D40: 3 | E40: 副區-A-3-2.jpg / 副區-A-3-3.jpg / 副區-A-3-4.jpg | F40: 限8個字；(檔名/券名)；(icon圖，無文字)；限10個字 | G40: 綠色欄位可填；固定欄位已鎖 | H40: 第 27 列 | I40: 待填
A41: 副區 | B41: 副區 一排3（左／中／右） | C41: 5 | D41: 3 | E41: 副區-A-4-1.jpg / 副區-A-4-2.jpg / 副區-A-4-3.jpg | F41: 限8個字；(檔名/券名)；限4+4個字；限5個字；限3個字；限10個字 | G41: 綠色欄位可填；固定欄位已鎖 | H41: 第 35 列 | I41: 待填
A42: 副區 | B42: 副區 一排3（左／中／右） | C42: 6 | D42: 3 | E42: 副區-A-4-4.jpg / 副區-A-5-1.jpg / 副區-A-5-2.jpg | F42: 限8個字；(檔名/券名)；限3個字；限4+4個字；限5個字 | G42: 綠色欄位可填；固定欄位已鎖 | H42: 第 43 列 | I42: 待填
A43: 副區 | B43: 副區 一排3（左／中／右） | C43: 7 | D43: 1 | E43: 副區-A-5-3.jpg | F43: 限8個字；(檔名/券名)；限4+4個字；限5個字；(icon圖，無文字) | G43: 綠色欄位可填；固定欄位已鎖 | H43: 第 51 列 | I43: 待填
A44: 副區 | B44: 副區 一排3（左／中／右） | C44: 8 | D44: 3 | E44: 副區-B-1-1.jpg / 副區-B-1-2.jpg / 副區-B-1-3.jpg | F44: 限8個字；(檔名/券名)；限10個字 | G44: 綠色欄位可填；固定欄位已鎖 | H44: 第 59 列 | I44: 待填
A45: 副區 | B45: 副區 一排3（左／中／右） | C45: 9 | D45: 3 | E45: 副區-B-1-4.jpg / 副區-B-2-1.jpg / 副區-B-2-2.jpg | F45: 限8個字；(檔名/券名)；限10個字；限5個字 | G45: 綠色欄位可填；固定欄位已鎖 | H45: 第 67 列 | I45: 待填
...

Sheet MS Layout
A1: 素材名稱 | B1: 版位／規格 | C1: Layout（綠色欄位可填；固定欄位與規則已鎖定） | T1: 視覺參考（目前系統實際版位）
C2: 中文 1 字、英數與半形符號 0.5 字；純數字自動以 $／千分位顯示；匯入 BODA 後混合文案也會整理；禁用語會阻擋並標紅 | T2: 圖片僅供版配與欄位位置對照，不代表最終正式稿
A3: 副區 | B3: 副區 一排3（左／中／右） 左：款式 1-1（A-1-1） 中：款式 1-2（A-1-2） 右：款式 1-3（A-1-3） Band 1 | C3: 左 | H3: 中 | M3: 右 | T3: 左 | X3: 中 | AC3: 右
C4: 促標 | G4: =IF(D4="","限8字",IF(LENB(D4)/2<=8,"OK","超過")) -> 限8字 | H4: 促標 | L4: =IF(I4="","限8字",IF(LENB(I4)/2<=8,"OK","超過")) -> 限8字 | M4: 促標 | R4: =IF(N4="","限8字",IF(LENB(N4)/2<=8,"OK","超過")) -> 限8字
C5: LOGO圖 (多圖用逗號分開) | G5: =IF(D5="","待填","OK") -> 待填 | H5: LOGO圖 (多圖用逗號分開) | L5: =IF(I5="","待填","OK") -> 待填 | M5: LOGO圖 (多圖用逗號分開) | R5: =IF(N5="","待填","OK") -> 待填
C6: 商品圖 (多圖用逗號分開) | G6: =IF(D6="","待填",IF(ISNUMBER(SEARCH(".",D6)),"OK","記得加副檔名")) -> 待填 | H6: 商品圖 (多圖用逗號分開) | L6: =IF(I6="","待填",IF(ISNUMBER(SEARCH(".",I6)),"OK","記得加副檔名")) -> 待填 | M6: 商品圖 (多圖用逗號分開) | R6: =IF(N6="","待填",IF(ISNUMBER(SEARCH(".",N6)),"OK","記得加副檔名")) -> 待填
C7: 品名 | G7: =IF(D7="","限8字",IF(LENB(D7)/2<=8,"OK","超過")) -> 限8字 | H7: 品名 | L7: =IF(I7="","限8字",IF(LENB(I7)/2<=8,"OK","超過")) -> 限8字 | M7: 警語 | R7: =IF(N7="","限10字",IF(LENB(N7)/2<=10,"OK","超過")) -> 限10字
C8: 警語 | G8: =IF(D8="","限10字",IF(LENB(D8)/2<=10,"OK","超過")) -> 限10字
A10: 副區 | B10: 副區 一排3（左／中／右） 左：款式 1-4（A-1-4） 中：款式 2-1（A-2-1） 右：款式 2-2（A-2-2） Band 2 | C10: 左 | H10: 中 | M10: 右 | T10: 左 | X10: 中 | AC10: 右
C11: 促標 | G11: =IF(D11="","限8字",IF(LENB(D11)/2<=8,"OK","超過")) -> 限8字 | H11: 促標 | L11: =IF(I11="","限8字",IF(LENB(I11)/2<=8,"OK","超過")) -> 限8字 | M11: 促標 | R11: =IF(N11="","限8字",IF(LENB(N11)/2<=8,"OK","超過")) -> 限8字
C12: LOGO圖 (多圖用逗號分開) | G12: =IF(D12="","待填","OK") -> 待填 | H12: LOGO圖 (多圖用逗號分開) | L12: =IF(I12="","待填","OK") -> 待填 | M12: LOGO圖 (多圖用逗號分開) | R12: =IF(N12="","待填","OK") -> 待填
C13: 商品圖 (多圖用逗號分開) | G13: =IF(D13="","待填",IF(ISNUMBER(SEARCH(".",D13)),"OK","記得加副檔名")) -> 待填 | H13: 商品圖 (多圖用逗號分開) | L13: =IF(I13="","待填",IF(ISNUMBER(SEARCH(".",I13)),"OK","記得加副檔名")) -> 待填 | M13: 商品圖 (多圖用逗號分開) | R13: =IF(N13="","待填",IF(ISNUMBER(SEARCH(".",N13)),"OK","記得加副檔名")) -> 待填
H14: 品名 | L14: =IF(I14="","限8字",IF(LENB(I14)/2<=8,"OK","超過")) -> 限8字 | M14: 品名 | R14: =IF(N14="","限8字",IF(LENB(N14)/2<=8,"OK","超過")) -> 限8字
H15: 警語 | L15: =IF(I15="","限10字",IF(LENB(I15)/2<=10,"OK","超過")) -> 限10字 | M15: 圓標 | R15: =IF(N15="","限5字",IF(LENB(N15)/2<=5,"OK","超過")) -> 限5字
H16: 圓標 | L16: =IF(I16="","限5字",IF(LENB(I16)/2<=5,"OK","超過")) -> 限5字
A18: 副區 | B18: 副區 一排3（左／中／右） 左：款式 2-3（A-2-3） 中：款式 2-4（A-2-4） 右：款式 3-1（A-3-1） Band 3 | C18: 左 | H18: 中 | M18: 右 | T18: 左 | X18: 中 | AC18: 右
C19: 促標 | G19: =IF(D19="","限8字",IF(LENB(D19)/2<=8,"OK","超過")) -> 限8字 | H19: 促標 | L19: =IF(I19="","限8字",IF(LENB(I19)/2<=8,"OK","超過")) -> 限8字 | M19: 促標 | R19: =IF(N19="","限8字",IF(LENB(N19)/2<=8,"OK","超過")) -> 限8字
C20: LOGO圖 (多圖用逗號分開) | G20: =IF(D20="","待填","OK") -> 待填 | H20: LOGO圖 (多圖用逗號分開) | L20: =IF(I20="","待填","OK") -> 待填 | M20: LOGO圖 (多圖用逗號分開) | R20: =IF(N20="","待填","OK") -> 待填
C21: 商品圖 (多圖用逗號分開) | G21: =IF(D21="","待填",IF(ISNUMBER(SEARCH(".",D21)),"OK","記得加副檔名")) -> 待填 | H21: 商品圖 (多圖用逗號分開) | L21: =IF(I21="","待填",IF(ISNUMBER(SEARCH(".",I21)),"OK","記得加副檔名")) -> 待填 | M21: 商品圖 (多圖用逗號分開) | R21: =IF(N21="","待填",IF(ISNUMBER(SEARCH(".",N21)),"OK","記得加副檔名")) -> 待填
C22: 警語 | G22: =IF(D22="","限10字",IF(LENB(D22)/2<=10,"OK","超過")) -> 限10字 | H22: 圓標 | L22: =IF(I22="","限5字",IF(LENB(I22)/2<=5,"OK","超過")) -> 限5字 | M22: 品名 | R22: =IF(N22="","限8字",IF(LENB(N22)/2<=8,"OK","超過")) -> 限8字
C23: 圓標 | G23: =IF(D23="","限5字",IF(LENB(D23)/2<=5,"OK","超過")) -> 限5字 | M23: 警語 | R23: =IF(N23="","限10字",IF(LENB(N23)/2<=10,"OK","超過")) -> 限10字
A25: 副區 | B25: 副區 一排3（左／中／右） 左：款式 3-2（A-3-2） 中：款式 3-3（A-3-3） 右：款式 3-4（A-3-4） Band 4 | C25: 左 | H25: 中 | M25: 右 | T25: 左 | X25: 中 | AC25: 右
C26: 促標 | G26: =IF(D26="","限8字",IF(LENB(D26)/2<=8,"OK","超過")) -> 限8字 | H26: 促標 | L26: =IF(I26="","限8字",IF(LENB(I26)/2<=8,"OK","超過")) -> 限8字 | M26: 促標 | R26: =IF(N26="","限8字",IF(LENB(N26)/2<=8,"OK","超過")) -> 限8字
C27: LOGO圖 (多圖用逗號分開) | G27: =IF(D27="","待填","OK") -> 待填 | H27: LOGO圖 (多圖用逗號分開) | L27: =IF(I27="","待填","OK") -> 待填 | M27: LOGO圖 (多圖用逗號分開) | R27: =IF(N27="","待填","OK") -> 待填
C28: 商品圖 (多圖用逗號分開) | G28: =IF(D28="","待填",IF(ISNUMBER(SEARCH(".",D28)),"OK","記得加副檔名")) -> 待填 | H28: 商品圖 (多圖用逗號分開) | L28: =IF(I28="","待填",IF(ISNUMBER(SEARCH(".",I28)),"OK","記得加副檔名")) -> 待填 | M28: 商品圖 (多圖用逗號分開) | R28: =IF(N28="","待填",IF(ISNUMBER(SEARCH(".",N28)),"OK","記得加副檔名")) -> 待填
C29: 品名 | G29: =IF(D29="","限8字",IF(LENB(D29)/2<=8,"OK","超過")) -> 限8字 | H29: 警語 | L29: =IF(I29="","限10字",IF(LENB(I29)/2<=10,"OK","超過")) -> 限10字
A31: 副區 | B31: 副區 一排3（左／中／右） 左：款式 4-1（A-4-1） 中：款式 4-2（A-4-2） 右：款式 4-3（A-4-3） Band 5 | C31: 左 | H31: 中 | M31: 右 | T31: 左 | X31: 中 | AC31: 右
C32: 促標 | G32: =IF(D32="","限8字",IF(LENB(D32)/2<=8,"OK","超過")) -> 限8字 | H32: 促標 | L32: =IF(I32="","限8字",IF(LENB(I32)/2<=8,"OK","超過")) -> 限8字 | M32: 促標 | R32: =IF(N32="","限8字",IF(LENB(N32)/2<=8,"OK","超過")) -> 限8字
C33: LOGO圖 (多圖用逗號分開) | G33: =IF(D33="","待填","OK") -> 待填 | H33: LOGO圖 (多圖用逗號分開) | L33: =IF(I33="","待填","OK") -> 待填 | M33: LOGO圖 (多圖用逗號分開) | R33: =IF(N33="","待填","OK") -> 待填
C34: 商品圖 (多圖用逗號分開) | G34: =IF(D34="","待填",IF(ISNUMBER(SEARCH(".",D34)),"OK","記得加副檔名")) -> 待填 | H34: 商品圖 (多圖用逗號分開) | L34: =IF(I34="","待填",IF(ISNUMBER(SEARCH(".",I34)),"OK","記得加副檔名")) -> 待填 | M34: 商品圖 (多圖用逗號分開) | R34: =IF(N34="","待填",IF(ISNUMBER(SEARCH(".",N34)),"OK","記得加副檔名")) -> 待填
C35: 品名 | G35: =IF(D35="","限4字",IF(LENB(D35)/2<=4,"OK","超過")) -> 限4字 | H35: 品名 | L35: =IF(I35="","限8字",IF(LENB(I35)/2<=8,"OK","超過")) -> 限8字 | M35: 警語 | R35: =IF(N35="","限10字",IF(LENB(N35)/2<=10,"OK","超過")) -> 限10字
C36: 品名 | G36: =IF(D36="","限4字",IF(LENB(D36)/2<=4,"OK","超過")) -> 限4字 | H36: CTA | L36: =IF(I36="","限3字",IF(LENB(I36)/2<=3,"OK","超過")) -> 限3字 | M36: CTA | R36: =IF(N36="","限3字",IF(LENB(N36)/2<=3,"OK","超過")) -> 限3字
C37: 警語 | G37: =IF(D37="","限5字",IF(LENB(D37)/2<=5,"OK","超過")) -> 限5字
C38: CTA | G38: =IF(D38="","限3字",IF(LENB(D38)/2<=3,"OK","超過")) -> 限3字
A40: 副區 | B40: 副區 一排3（左／中／右） 左：款式 4-4（A-4-4） 中：款式 5-1（A-5-1） 右：款式 5-2（A-5-2） Band 6 | C40: 左 | H40: 中 | M40: 右 | T40: 左 | X40: 中 | AC40: 右
C41: 促標 | G41: =IF(D41="","限8字",IF(LENB(D41)/2<=8,"OK","超過")) -> 限8字 | H41: 促標 | L41: =IF(I41="","限8字",IF(LENB(I41)/2<=8,"OK","超過")) -> 限8字 | M41: 促標 | R41: =IF(N41="","限8字",IF(LENB(N41)/2<=8,"OK","超過")) -> 限8字
C42: LOGO圖 (多圖用逗號分開) | G42: =IF(D42="","待填","OK") -> 待填 | H42: LOGO圖 (多圖用逗號分開) | L42: =IF(I42="","待填","OK") -> 待填 | M42: LOGO圖 (多圖用逗號分開) | R42: =IF(N42="","待填","OK") -> 待填
C43: 商品圖 (多圖用逗號分開) | G43: =IF(D43="","待填",IF(ISNUMBER(SEARCH(".",D43)),"OK","記得加副檔名")) -> 待填 | H43: 商品圖 (多圖用逗號分開) | L43: =IF(I43="","待填",IF(ISNUMBER(SEARCH(".",I43)),"OK","記得加副檔名")) -> 待填 | M43: 商品圖 (多圖用逗號分開) | R43: =IF(N43="","待填",IF(ISNUMBER(SEARCH(".",N43)),"OK","記得加副檔名")) -> 待填
C44: CTA | G44: =IF(D44="","限3字",IF(LENB(D44)/2<=3,"OK","超過")) -> 限3字 | H44: 品名 | L44: =IF(I44="","限4字",IF(LENB(I44)/2<=4,"OK","超過")) -> 限4字 | M44: 品名 | R44: =IF(N44="","限4字",IF(LENB(N44)/2<=4,"OK","超過")) -> 限4字
H45: 品名 | L45: =IF(I45="","限4字",IF(LENB(I45)/2<=4,"OK","超過")) -> 限4字 | M45: 品名 | R45: =IF(N45="","限4字",IF(LENB(N45)/2<=4,"OK","超過")) -> 限4字
...

Sheet 設定
A1: 等級 | B1: MSBN額度 | C1: 資源1 | D1: 資源2 | E1: 資源3 | F1: 資源4 | G1: 資源5 | H1: 資源6 | I1: 資源7 | J1: 資源8 | K1: 資源9 | L1: 資源10 | M1: 資源11 | N1: 資源12 | O1: 類型1 | P1: 類型2 | Q1: 類型3 | R1: 類型4 | S1: 類型5 | T1: 類型6 | U1: 類型7 | V1: 類型8 | W1: 類型9 | X1: 類型10 | Y1: 類型11 | Z1: 類型12 | AB1: key | AC1: 顯示名稱 | AD1: 張數 | AE1: 尺寸 | AF1: 格式 | AG1: 規範字數 | AH1: 提醒 | AI1: 系統排版 | AJ1: 可用
A2: A Brand star (Mega) | B2: 8 | C2: LPBN | O2: 預設 | AB2: LPBN | AC2: LPBN | AD2: 2 | AE2: APP 1200×550 PC 1200×400 | AF2: JPG | AG2: 主標≤8；副標≤7；日期／警語≤14 | AH2: APP、PC 各 1 張 | AI2: LPBN_APP／LPBN_PC | AJ2: 是
A3: A Brand star (Mega) 資交 | B3: 4 | C3: LPBN | O3: 預設 | AB3: DDCard | AC3: DD Card BN (APP) | AD3: 1 | AE3: 531×792 | AF3: JPG | AG3: 品牌名≤9；主標≤8；副標≤7；日期/警語≤14 | AH3: LOGO、商品圖；CTA 依版型 | AI3: ddcard無logo／ddcard方logo／ddcard橫logo | AJ3: 是
A4: A 精選套裝 | B4: 4 | C4: LPBN | O4: 預設 | AB4: HBN | AC4: HBN (PC) | AD4: 1 | AE4: 1200×360 | AF4: JPG | AG4: 品牌名≤9；主標≤8；副標≤7；日期/警語≤14 | AH4: 橫式或方形 LOGO 版 | AI4: HBN_橫式LOGO／HBN_方式LOGO | AJ4: 是
A5: A 品牌旗艦MDD | B5: 6 | C5: LPBN | O5: 預設 | AB5: 活動總覽 | AC5: 活動總覽 | AD5: 1 | AE5: 依活動規格 | AF5: JPG/PNG | AG5: 依活動需求 | AH5: 目前系統尚未提供可編輯版型 | AI5: 尚未提供版型 | AJ5: 否
A6: A 品牌旗艦MDD 資交 | B6: 0 | C6: LPBN | O6: 預設 | AB6: 首頁LOGO牆 | AC6: 首頁 LOGO 牆 | AD6: 1 | AE6: 402×483 | AF6: JPG/PNG | AG6: LOGO／人物或商品圖可縮放 | AH6: LOGO 位於曝品或人物範圍內，可用滑鼠縮放 | AI6: 首頁LOGO牆 | AJ6: 是
A7: B+ BOD A | B7: 6 | C7: LPBN | D7: DDCard | E7: HBN | F7: 活動總覽 | G7: 首頁LOGO牆 | H7: AR | I7: FB_Post | J7: AMS BN | K7: Coin_page | L7: IG | M7: SearchIcon | N7: SearchImage | O7: 預設 | P7: 預設 | Q7: 預設 | R7: 預設 | S7: 預設 | T7: 預設 | U7: 預設 | V7: 預設 | W7: 選配 | X7: 選配 | Y7: 選配 | Z7: 選配 | AB7: AR | AC7: AR | AD7: 1 | AE7: 100×100（依規範） | AF7: JPG/PNG | AG7: 文案≤6 或 LOGO；2擇1 | AH7: 目前系統尚未提供可編輯版型 | AI7: 尚未提供版型 | AJ7: 否
A8: B+ BOD A 資交 | B8: 0 | C8: LPBN | D8: DDCard | E8: HBN | F8: 活動總覽 | G8: 首頁LOGO牆 | H8: AR | I8: FB_Post | J8: AMS BN | K8: Coin_page | L8: IG | M8: SearchIcon | N8: SearchImage | O8: 預設 | P8: 預設 | Q8: 預設 | R8: 預設 | S8: 預設 | T8: 預設 | U8: 預設 | V8: 預設 | W8: 選配 | X8: 選配 | Y8: 選配 | Z8: 選配 | AB8: FB_Post | AC8: FB POST | AD8: 1 | AE8: 1200×630 | AF8: JPG | AG8: 品牌名≤9；主標≤8；副標≤7；日期/警語≤14 | AH8: 方 LOGO／橫 LOGO | AI8: FB_POST_方LOGO／FB_POST_橫LOGO | AJ8: 是
A9: B+ BOD B (Mega) | B9: 6 | C9: LPBN | D9: DDCard | E9: HBN | F9: 活動總覽 | G9: 首頁LOGO牆 | H9: AR | I9: FB_Post | J9: AMS BN | K9: Coin_page | L9: IG | O9: 預設 | P9: 預設 | Q9: 預設 | R9: 預設 | S9: 預設 | T9: 預設 | U9: 選配 | V9: 選配 | W9: 選配 | X9: 選配 | AB9: AMS BN | AC9: AMS BN | AD9: 1 | AE9: 1077×264（依規範） | AF9: JPG | AG9: 依 AMS 規格 | AH9: 目前系統尚未提供可編輯版型 | AI9: 尚未提供版型 | AJ9: 否
A10: B+ 基礎套裝 | B10: 6 | C10: LPBN | D10: DDCard | E10: HBN | F10: 活動總覽 | G10: 首頁LOGO牆 | H10: AR | I10: FB_Post | J10: AMS BN | K10: Coin_page | L10: IG | O10: 預設 | P10: 預設 | Q10: 預設 | R10: 預設 | S10: 預設 | T10: 預設 | U10: 選配 | V10: 選配 | W10: 選配 | X10: 選配 | AB10: Coin_page | AC10: Coin Page BN | AD10: 1 | AE10: 1200×391 | AF10: JPG | AG10: 品牌名≤9；主標≤8；副標≤7；日期/警語≤14 | AH10: 方 LOGO／橫 LOGO | AI10: Coin_pageBN_APP方LOGO／Coin_pageBN_APP橫LOGO | AJ10: 是
A11: B JBP多店 | B11: 3 | C11: LPBN | D11: IG | E11: HBN | F11: DDCard | G11: Coin_page | H11: FB_Post | I11: SCPN | J11: SearchImage | K11: SearchIcon | O11: 預設 | P11: 預設 | Q11: 預設 | R11: 預設 | S11: 預設 | T11: 預設 | U11: 預設 | V11: 預設 | W11: 預設 | AB11: IG | AC11: IG | AD11: 1 | AE11: 900×1600 | AF11: JPG | AG11: 品牌名≤9；主標≤8；副標≤7；日期/警語≤14 | AH11: 方 LOGO／橫 LOGO | AI11: IG方logo排版／IG橫logo排版 | AJ11: 是
A12: B 金牌 (Mega) | B12: 3 | C12: LPBN | D12: DDCard | E12: HBN | F12: 活動總覽 | G12: AR | H12: Coin_page | O12: 預設 | P12: 預設 | Q12: 預設 | R12: 預設 | S12: 預設 | T12: 選配 | AB12: SearchIcon | AC12: Search ICON | AD12: 1 | AE12: 120×120＋84×84 | AF12: PNG | AG12: ICON 文案≤2；或 LOGO／商品圖 | AH12: 120×120 建議 <50KB，另輸出 84×84 | AI12: SearchICON_LOGO／PRODUCT／TEXT | AJ12: 是
AB13: SearchImage | AC13: Search Image | AD13: 1 | AE13: 1125×156 | AF13: JPG/PNG | AG13: 副標≤7；LOGO 1～3 個 | AH13: 依選用版型提供 1～3 個 LOGO | AI13: Search_Image1logo／2logo／3logo | AJ13: 是
AB14: SCPN | AC14: SCBN／SCPN | AD14: 1 | AE14: 1200×200 | AF14: JPG | AG14: 品牌名≤9；副標≤7；CTA | AH14: 商城橫幅 | AI14: SCBN_APP | AJ14: 是

Sheet _BODA_META
A1: BODA_WORKORDER_V2
A2: kind | B2: sourceKey | C2: band | D2: order | E2: family | F2: variant | G2: combo | H2: msbnFile | I2: position | J2: label | K2: address | L2: header | M2: file | N2: locked | O2: hint | P2: targetKey
A3: subarea | B3: msbn-sub:0:0 | C3: 1 | D3: 1 | E3: A | F3: 1 | G3: 1 | I3: 1 | J3: 促標 | K3: D4 | L3: 款式 1-1 | M3: 副區-A-1-1.jpg | N3: 0 | O3: 限8個字
A4: subarea | B4: msbn-sub:0:0 | C4: 1 | D4: 1 | E4: A | F4: 1 | G4: 1 | I4: 1 | J4: LOGO圖 | K4: D5 | L4: 款式 1-1 | M4: 副區-A-1-1.jpg | N4: 0 | O4: (檔名/券名)
A5: subarea | B5: msbn-sub:0:0 | C5: 1 | D5: 1 | E5: A | F5: 1 | G5: 1 | I5: 1 | J5: 商品 | K5: D6 | L5: 款式 1-1 | M5: 副區-A-1-1.jpg | N5: 0 | O5: (檔名/券名)
A6: subarea | B6: msbn-sub:0:0 | C6: 1 | D6: 1 | E6: A | F6: 1 | G6: 1 | I6: 1 | J6: 品名 | K6: D7 | L6: 款式 1-1 | M6: 副區-A-1-1.jpg | N6: 0 | O6: 限8個字
A7: subarea | B7: msbn-sub:0:0 | C7: 1 | D7: 1 | E7: A | F7: 1 | G7: 1 | I7: 1 | J7: 警語 | K7: D8 | L7: 款式 1-1 | M7: 副區-A-1-1.jpg | N7: 0 | O7: 限10個字
A8: subarea | B8: msbn-sub:0:1 | C8: 1 | D8: 2 | E8: A | F8: 1 | G8: 2 | I8: 2 | J8: 促標 | K8: I4 | L8: 款式 1-2 | M8: 副區-A-1-2.jpg | N8: 0 | O8: 限8個字
A9: subarea | B9: msbn-sub:0:1 | C9: 1 | D9: 2 | E9: A | F9: 1 | G9: 2 | I9: 2 | J9: LOGO圖 | K9: I5 | L9: 款式 1-2 | M9: 副區-A-1-2.jpg | N9: 0 | O9: (檔名/券名)
A10: subarea | B10: msbn-sub:0:1 | C10: 1 | D10: 2 | E10: A | F10: 1 | G10: 2 | I10: 2 | J10: 商品 | K10: I6 | L10: 款式 1-2 | M10: 副區-A-1-2.jpg | N10: 0 | O10: (檔名/券名)
A11: subarea | B11: msbn-sub:0:1 | C11: 1 | D11: 2 | E11: A | F11: 1 | G11: 2 | I11: 2 | J11: 品名 | K11: I7 | L11: 款式 1-2 | M11: 副區-A-1-2.jpg | N11: 0 | O11: 限8個字
A12: subarea | B12: msbn-sub:0:2 | C12: 1 | D12: 3 | E12: A | F12: 1 | G12: 3 | I12: 3 | J12: 促標 | K12: N4 | L12: 款式 1-3 | M12: 副區-A-1-3.jpg | N12: 0 | O12: 限8個字
A13: subarea | B13: msbn-sub:0:2 | C13: 1 | D13: 3 | E13: A | F13: 1 | G13: 3 | I13: 3 | J13: LOGO圖 | K13: N5 | L13: 款式 1-3 | M13: 副區-A-1-3.jpg | N13: 0 | O13: (檔名/券名)
A14: subarea | B14: msbn-sub:0:2 | C14: 1 | D14: 3 | E14: A | F14: 1 | G14: 3 | I14: 3 | J14: 商品 | K14: N6 | L14: 款式 1-3 | M14: 副區-A-1-3.jpg | N14: 0 | O14: (檔名/券名)
... A352: subarea | B352: msbn-sub:31:3 | C352: 32 | D352: 75 | E352: F | F352: 1 | G352: 1 | I352: 4 | J352: 警語 | K352: P258 | L352: 款式 1-1 | M352: 副區-F-1-1.jpg | N352: 0 | O352: 限6個字
A353: msbn | B353: msbn:32 | C353: 33 | D353: 76 | H353: MSBN-A-1-1.jpg | I353: 1 | J353: 促標 | K353: D263 | L353: MSBN-A-1-1 | M353: MSBN-A-1-1.jpg | N353: 0 | O353: 促標最多7字內
A354: msbn | B354: msbn:32 | C354: 33 | D354: 76 | H354: MSBN-A-1-1.jpg | I354: 1 | J354: 商品 | K354: H263 | L354: MSBN-A-1-1 | M354: MSBN-A-1-1.jpg | N354: 0 | O354: (圖檔名)
A355: msbn | B355: msbn:32 | C355: 33 | D355: 76 | H355: MSBN-A-1-1.jpg | I355: 1 | J355: 品名 | K355: D264 | L355: MSBN-A-1-1 | M355: MSBN-A-1-1.jpg | N355: 0 | O355: 品名一排最多8字
A356: msbn | B356: msbn:32 | C356: 33 | D356: 76 | H356: MSBN-A-1-1.jpg | I356: 1 | J356: 代言人圖 | K356: H264 | L356: MSBN-A-1-1 | M356: MSBN-A-1-1.jpg | N356: 0 | O356: (圖檔名)
A357: msbn | B357: msbn:32 | C357: 33 | D357: 76 | H357: MSBN-A-1-1.jpg | I357: 1 | J357: 品名 | K357: D265 | L357: MSBN-A-1-1 | M357: MSBN-A-1-1.jpg | N357: 0 | O357: 品名一排最多8字
A358: msbn | B358: msbn:32 | C358: 33 | D358: 76 | H358: MSBN-A-1-1.jpg | I358: 1 | J358: 圓標 | K358: H265 | L358: MSBN-A-1-1 | M358: MSBN-A-1-1.jpg | N358: 0 | O358: 圓標05字內
A359: msbn | B359: msbn:32 | C359: 33 | D359: 76 | H359: MSBN-A-1-1.jpg | I359: 1 | J359: 警語 | K359: D266 | L359: MSBN-A-1-1 | M359: MSBN-A-1-1.jpg | N359: 0 | O359: 小字最多可9個字內
A360: msbn | B360: msbn:32 | C360: 33 | D360: 76 | H360: MSBN-A-1-1.jpg | I360: 1 | J360: 簽名小字 | K360: H266 | L360: MSBN-A-1-1 | M360: MSBN-A-1-1.jpg | N360: 0 | O360: 每行限5字
A361: msbn | B361: msbn:32 | C361: 33 | D361: 76 | H361: MSBN-A-1-1.jpg | I361: 1 | J361: 簽名小字 | K361: H267 | L361: MSBN-A-1-1 | M361: MSBN-A-1-1.jpg | N361: 0 | O361: 每行限5字
A362: msbn | B362: msbn:32 | C362: 33 | D362: 76 | H362: MSBN-A-1-1.jpg | I362: 1 | J362: 簽名圖 | K362: H268 | L362: MSBN-A-1-1 | M362: MSBN-A-1-1.jpg | N362: 0 | O362: (檔名)
A363: msbn | B363: msbn:32 | C363: 33 | D363: 76 | H363: MSBN-A-1-1.jpg | I363: 1 | J363: CTA | K363: H269 | L363: MSBN-A-1-1 | M363: MSBN-A-1-1.jpg | N363: 0 | O363: 逛逛去
A364: msbn | B364: msbn:33 | C364: 34 | D364: 77 | H364: MSBN-A-1-2.jpg | I364: 1 | J364: 商品 | K364: D272 | L364: MSBN-A-1-2 | M364: MSBN-A-1-2.jpg | N364: 0 | O364: (圖檔名)
... A406: msbn | B406: msbn:36 | C406: 37 | D406: 80 | H406: MSBN-A-2-3.jpg | I406: 1 | J406: 圓標 | K406: D302 | L406: MSBN-A-2-3 | M406: MSBN-A-2-3.jpg | N406: 0 | O406: 圓標05字內
A407: msbn | B407: msbn:36 | C407: 37 | D407: 80 | H407: MSBN-A-2-3.jpg | I407: 1 | J407: 色塊 | K407: D303 | L407: MSBN-A-2-3 | M407: MSBN-A-2-3.jpg | N407: 0 | P407: bgColor2
A408: msbn | B408: msbn:36 | C408: 37 | D408: 80 | H408: MSBN-A-2-3.jpg | I408: 1 | J408: 色塊 | K408: D304 | L408: MSBN-A-2-3 | M408: MSBN-A-2-3.jpg | N408: 0 | P408: bgColor
A409: msbn | B409: msbn:36 | C409: 37 | D409: 80 | H409: MSBN-A-2-3.jpg | I409: 2 | J409: 促標 | K409: H299 | L409: MSBN-A-2-3 | M409: MSBN-A-2-3.jpg | N409: 0 | O409: 促標6個字內
A410: msbn | B410: msbn:36 | C410: 37 | D410: 80 | H410: MSBN-A-2-3.jpg | I410: 2 | J410: 商品 | K410: H300 | L410: MSBN-A-2-3 | M410: MSBN-A-2-3.jpg | N410: 0 | O410: (圖檔名)
A411: msbn | B411: msbn:36 | C411: 37 | D411: 80 | H411: MSBN-A-2-3.jpg | I411: 2 | J411: 品名 | K411: H301 | L411: MSBN-A-2-3 | M411: MSBN-A-2-3.jpg | N411: 0 | O411: 品名一排最多8字
A412: msbn | B412: msbn:36 | C412: 37 | D412: 80 | H412: MSBN-A-2-3.jpg | I412: 2 | J412: 圓標 | K412: H302 | L412: MSBN-A-2-3 | M412: MSBN-A-2-3.jpg | N412: 0 | O412: 圓標05字內
A413: msbn | B413: msbn:36 | C413: 37 | D413: 80 | H413: MSBN-A-2-3.jpg | I413: 2 | J413: 色塊 | K413: H303 | L413: MSBN-A-2-3 | M413: MSBN-A-2-3.jpg | N413: 0 | P413: bgColor2
A414: msbn | B414: msbn:36 | C414: 37 | D414: 80 | H414: MSBN-A-2-3.jpg | I414: 2 | J414: 色塊 | K414: H304 | L414: MSBN-A-2-3 | M414: MSBN-A-2-3.jpg | N414: 0 | P414: bgColor
A415: msbn | B415: msbn:37 | C415: 38 | D415: 81 | H415: MSBN-A-2-4.jpg | I415: 1 | J415: LOGO圖 | K415: D307 | L415: MSBN-A-2-4 | M415: MSBN-A-2-4.jpg | N415: 0 | O415: (檔名/券名)
A416: msbn | B416: msbn:37 | C416: 38 | D416: 81 | H416: MSBN-A-2-4.jpg | I416: 2 | J416: LOGO圖 | K416: H307 | L416: MSBN-A-2-4 | M416: MSBN-A-2-4.jpg | N416: 0 | O416: (檔名/券名)
A417: msbn | B417: msbn:38 | C417: 39 | D417: 82 | H417: MSBN-A-3-1.jpg | I417: 1 | J417: 商品 | K417: D310 | L417: MSBN-A-3-1 | M417: MSBN-A-3-1.jpg | N417: 0 | O417: (圖檔名)
A418: msbn | B418: msbn:38 | C418: 39 | D418: 82 | H418: MSBN-A-3-1.jpg | I418: 1 | J418: 贈品圖 | K418: D311 | L418: MSBN-A-3-1 | M418: MSBN-A-3-1.jpg | N418: 0 | O418: (檔名)
...

Sheet _BODA_BOTTOM
A1: BODA_BOTTOM_V1 | B1: MS Layout
A2: group | B2: title | C2: iconAddress | D2: logoAddress | E2: textAddress | F2: countAddress | G2: optional
A3: 1 | B3: 第1顆 | C3: E489 | D3: E490 | E3: C491 | F3: G491 | G3: 0
A4: 2 | B4: 第2顆 | C4: J489 | D4: J490 | E4: H491 | F4: L491 | G4: 0
A5: 3 | B5: 第3顆 | C5: O489 | D5: O490 | E5: M491 | F5: Q491 | G5: 1
A6: 4 | B6: 第4顆 | C6: T489 | D6: T490 | E6: R491 | F6: Y491 | G6: 1
A7: 5 | B7: 第5顆 | C7: AB489 | D7: AB490 | E7: Z491 | F7: AG491 | G7: 1

Sheet _BODA_BOTTOM_STATE
A1: BODA_BOTTOM_STATE_V1 | B1: 1 | C1: JSON chunks
A3: 1 | B3: { "format": "sticky-banner-project", "version": 2, "activeBannerIndex": 0, "sharpen": true, "banners": [ { "slotCount": 5, "activeSlotIndex": 0, "accentColor": "red", "slots": [ { "text": "主會場", "iconId": "bod-logo", "iconText": null }, { "text": "", "iconId": null, "iconText": null }, { "text": "", "iconId": null, "iconText": null }, { "text": "", "iconId": null, "iconText": null }, { "text": "", "iconId": null, "iconText": null } ] } ], "customIcons": [] }

Sheet _BODA_RULES
A1: keyword | B1: replacement | C1: action
A2: 撒 | B2: 自動改成"灑" | C2: replace
A3: 購物金 | B3: 自動改成"優惠券" | C3: replace
A4: 抵用券 | B4: 自動改成"優惠券" | C4: replace
A5: 折價券 | B5: 自動改成"優惠券" | C5: replace
A6: 蝦皮券 | B6: 自動改成"優惠券" | C6: replace
A7: 蝦幣券 | B7: 自動改成"優惠券" | C7: replace
A8: 折扣券 | B8: 自動改成"優惠券" | C8: replace
A9: $蝦幣 | B9: 自動改成"蝦幣" | C9: replace
A10: 蝦幣$ | B10: 自動改成"蝦幣" | C10: replace
A11: \$\d+\s*蝦幣 | B11: 自動改成"蝦幣" | C11: replace
A12: 元 | B12: 直接無法輸入 | C12: block
... A69: 兩 | B69: 自動改成"2" | C69: replace
