Workbook

Sheet 工單總覽
A1: BODA 工單總覽
A3: 包套(等級) | B3: B+ 基礎套裝 | E3: MSBN 額度 | F3: =IFERROR(VLOOKUP(B3,'設定'!$A$2:$B$12,2,FALSE),0) -> 6 | H3: 輸出時間 | I3: 46283.043
A4: 負責人 | E4: 版本 | F4: V1 | H4: 更新重點
A5: 活動時間 | E5: 美術 Deadline | H5: 總製作張數 | I5: =SUM(C23:C32)+107 -> 114
A6: 工作項目名稱 | E6: 行銷目標
A7: 目標客群
A9: BN曝光資源文案
A10: 主標 | E10: 上限 8
A11: 副標 | E11: 上限 7
A12: 日期／警語 | E12: 上限 14
A13: 曝光資源圖片 | B13: 圖片1,圖片2,圖片3 | E13: 上限 3張 | F13: 多圖用逗號分開，例如：圖片1,圖片2,圖片3
A14: 背景顏色 | B14: #733c90
A16: 其他曝光資源文案
A17: 品牌名 | E17: 上限 9
A18: SearchICON文案 | E18: 上限 2
A19: AR文案 | E19: 上限 6
A21: BN曝光資源
A22: 版位 | B22: 類型 | C22: 張數 | D22: 尺寸
A23: {=IFERROR(INDEX('設定'!$C$2:$N$12,MATCH($B$3,'設定'!$A$2:$A$12,0),1),"")} -> LPBN | B23: {=IFERROR(INDEX('設定'!$O$2:$Z$12,MATCH($B$3,'設定'!$A$2:$A$12,0),1),"")} -> 預設 | C23: =IF(A23="","",IF(B23="預設",IFERROR(VLOOKUP(A23,'設定'!$AB$2:$AJ$14,3,FALSE),1),0)) -> 2 | D23: =IF(A23="","",IFERROR(VLOOKUP(A23,'設定'!$AB$2:$AJ$14,4,FALSE),"")) -> APP 1200×550 PC 1200×400
A24: {=IFERROR(INDEX('設定'!$C$2:$N$12,MATCH($B$3,'設定'!$A$2:$A$12,0),2),"")} -> DDCard | B24: {=IFERROR(INDEX('設定'!$O$2:$Z$12,MATCH($B$3,'設定'!$A$2:$A$12,0),2),"")} -> 預設 | C24: =IF(A24="","",IF(B24="預設",IFERROR(VLOOKUP(A24,'設定'!$AB$2:$AJ$14,3,FALSE),1),0)) -> 1 | D24: =IF(A24="","",IFERROR(VLOOKUP(A24,'設定'!$AB$2:$AJ$14,4,FALSE),"")) -> 531×792
A25: {=IFERROR(INDEX('設定'!$C$2:$N$12,MATCH($B$3,'設定'!$A$2:$A$12,0),3),"")} -> HBN | B25: {=IFERROR(INDEX('設定'!$O$2:$Z$12,MATCH($B$3,'設定'!$A$2:$A$12,0),3),"")} -> 預設 | C25: =IF(A25="","",IF(B25="預設",IFERROR(VLOOKUP(A25,'設定'!$AB$2:$AJ$14,3,FALSE),1),0)) -> 1 | D25: =IF(A25="","",IFERROR(VLOOKUP(A25,'設定'!$AB$2:$AJ$14,4,FALSE),"")) -> 1200×360
A26: {=IFERROR(INDEX('設定'!$C$2:$N$12,MATCH($B$3,'設定'!$A$2:$A$12,0),4),"")} -> 活動總覽 | B26: {=IFERROR(INDEX('設定'!$O$2:$Z$12,MATCH($B$3,'設定'!$A$2:$A$12,0),4),"")} -> 預設 | C26: =IF(A26="","",IF(B26="預設",IFERROR(VLOOKUP(A26,'設定'!$AB$2:$AJ$14,3,FALSE),1),0)) -> 1 | D26: =IF(A26="","",IFERROR(VLOOKUP(A26,'設定'!$AB$2:$AJ$14,4,FALSE),"")) -> 1200x360
A27: {=IFERROR(INDEX('設定'!$C$2:$N$12,MATCH($B$3,'設定'!$A$2:$A$12,0),5),"")} -> 首頁LOGO牆 | B27: {=IFERROR(INDEX('設定'!$O$2:$Z$12,MATCH($B$3,'設定'!$A$2:$A$12,0),5),"")} -> 預設 | C27: =IF(A27="","",IF(B27="預設",IFERROR(VLOOKUP(A27,'設定'!$AB$2:$AJ$14,3,FALSE),1),0)) -> 1 | D27: =IF(A27="","",IFERROR(VLOOKUP(A27,'設定'!$AB$2:$AJ$14,4,FALSE),"")) -> 402×483
A28: {=IFERROR(INDEX('設定'!$C$2:$N$12,MATCH($B$3,'設定'!$A$2:$A$12,0),6),"")} -> AR | B28: {=IFERROR(INDEX('設定'!$O$2:$Z$12,MATCH($B$3,'設定'!$A$2:$A$12,0),6),"")} -> 預設 | C28: =IF(A28="","",IF(B28="預設",IFERROR(VLOOKUP(A28,'設定'!$AB$2:$AJ$14,3,FALSE),1),0)) -> 1 | D28: =IF(A28="","",IFERROR(VLOOKUP(A28,'設定'!$AB$2:$AJ$14,4,FALSE),"")) -> 100×100（依規範）
A29: {=IFERROR(INDEX('設定'!$C$2:$N$12,MATCH($B$3,'設定'!$A$2:$A$12,0),7),"")} -> FB_Post | B29: {=IFERROR(INDEX('設定'!$O$2:$Z$12,MATCH($B$3,'設定'!$A$2:$A$12,0),7),"")} -> 選配 | C29: =IF(A29="","",IF(B29="預設",IFERROR(VLOOKUP(A29,'設定'!$AB$2:$AJ$14,3,FALSE),1),0)) -> 0 | D29: =IF(A29="","",IFERROR(VLOOKUP(A29,'設定'!$AB$2:$AJ$14,4,FALSE),"")) -> 1200×630
A30: {=IFERROR(INDEX('設定'!$C$2:$N$12,MATCH($B$3,'設定'!$A$2:$A$12,0),8),"")} -> AMS BN | B30: {=IFERROR(INDEX('設定'!$O$2:$Z$12,MATCH($B$3,'設定'!$A$2:$A$12,0),8),"")} -> 選配 | C30: =IF(A30="","",IF(B30="預設",IFERROR(VLOOKUP(A30,'設定'!$AB$2:$AJ$14,3,FALSE),1),0)) -> 0 | D30: =IF(A30="","",IFERROR(VLOOKUP(A30,'設定'!$AB$2:$AJ$14,4,FALSE),"")) -> 1077×264（依規範）
A31: {=IFERROR(INDEX('設定'!$C$2:$N$12,MATCH($B$3,'設定'!$A$2:$A$12,0),9),"")} -> Coin_page | B31: {=IFERROR(INDEX('設定'!$O$2:$Z$12,MATCH($B$3,'設定'!$A$2:$A$12,0),9),"")} -> 選配 | C31: =IF(A31="","",IF(B31="預設",IFERROR(VLOOKUP(A31,'設定'!$AB$2:$AJ$14,3,FALSE),1),0)) -> 0 | D31: =IF(A31="","",IFERROR(VLOOKUP(A31,'設定'!$AB$2:$AJ$14,4,FALSE),"")) -> 1200×391
A32: {=IFERROR(INDEX('設定'!$C$2:$N$12,MATCH($B$3,'設定'!$A$2:$A$12,0),10),"")} -> IG | B32: {=IFERROR(INDEX('設定'!$O$2:$Z$12,MATCH($B$3,'設定'!$A$2:$A$12,0),10),"")} -> 選配 | C32: =IF(A32="","",IF(B32="預設",IFERROR(VLOOKUP(A32,'設定'!$AB$2:$AJ$14,3,FALSE),1),0)) -> 0 | D32: =IF(A32="","",IFERROR(VLOOKUP(A32,'設定'!$AB$2:$AJ$14,4,FALSE),"")) -> 900×1600

Sheet MS Layout
A1: 素材 | B1: Layout（綠色欄位可填；固定欄位與規則已鎖定） | O1: 視覺參考（目前系統實際版位）
B2: 款式 1-1（A-1-1） | E2: 款式 1-2（A-1-2） | H2: 款式 1-3（A-1-3）
A3: 副區 | B3: LOGO圖 (多圖用逗號分開) | D3: =IF(C3="","待填","OK") -> 待填 | E3: LOGO圖 (多圖用逗號分開) | G3: =IF(F3="","待填","OK") -> 待填 | H3: LOGO圖 (多圖用逗號分開) | J3: =IF(I3="","待填","OK") -> 待填
B4: 促標 | D4: =IF(C4="","限5字",IF(LENB(C4)/2<=5,"OK","超過")) -> 限5字 | E4: 促標 | G4: =IF(F4="","限5字",IF(LENB(F4)/2<=5,"OK","超過")) -> 限5字 | H4: 促標 | J4: =IF(I4="","限5字",IF(LENB(I4)/2<=5,"OK","超過")) -> 限5字
B5: 商品圖 (多圖用逗號分開) | D5: =IF(C5="","待填","OK") -> 待填 | E5: 商品圖 (多圖用逗號分開) | G5: =IF(F5="","待填","OK") -> 待填 | H5: 商品圖 (多圖用逗號分開) | J5: =IF(I5="","待填","OK") -> 待填
B6: 品名 | D6: =IF(C6="","限8字",IF(LENB(C6)/2<=8,"OK","超過")) -> 限8字 | E6: 品名 | G6: =IF(F6="","限8字",IF(LENB(F6)/2<=8,"OK","超過")) -> 限8字 | H6: 小字 | J6: =IF(I6="","限10字",IF(LENB(I6)/2<=10,"OK","超過")) -> 限10字
B7: 小字 | D7: =IF(C7="","限10字",IF(LENB(C7)/2<=10,"OK","超過")) -> 限10字
B11: 款式 1-4（A-1-4） | E11: 款式 2-1（A-2-1） | H11: 款式 2-2（A-2-2）
A12: 副區 | B12: LOGO圖 (多圖用逗號分開) | D12: =IF(C12="","待填","OK") -> 待填 | E12: LOGO圖 (多圖用逗號分開) | G12: =IF(F12="","待填","OK") -> 待填 | H12: LOGO圖 (多圖用逗號分開) | J12: =IF(I12="","待填","OK") -> 待填
B13: 促標 | D13: =IF(C13="","限5字",IF(LENB(C13)/2<=5,"OK","超過")) -> 限5字 | E13: 促標 | G13: =IF(F13="","限5字",IF(LENB(F13)/2<=5,"OK","超過")) -> 限5字 | H13: 促標 | J13: =IF(I13="","限5字",IF(LENB(I13)/2<=5,"OK","超過")) -> 限5字
B14: 商品圖 (多圖用逗號分開) | D14: =IF(C14="","待填","OK") -> 待填 | E14: 圓標 | G14: =IF(F14="","限5字",IF(LENB(F14)/2<=7,"OK","超過")) -> 限5字 | H14: 圓標 | J14: =IF(I14="","限5字",IF(LENB(I14)/2<=7,"OK","超過")) -> 限5字
E15: 商品圖 (多圖用逗號分開) | G15: =IF(F15="","待填","OK") -> 待填 | H15: 商品圖 (多圖用逗號分開) | J15: =IF(I15="","待填","OK") -> 待填
E16: 品名 | G16: =IF(F16="","限8字",IF(LENB(F16)/2<=8,"OK","超過")) -> 限8字 | H16: 品名 | J16: =IF(I16="","限8字",IF(LENB(I16)/2<=8,"OK","超過")) -> 限8字
E17: 小字 | G17: =IF(F17="","限10字",IF(LENB(F17)/2<=10,"OK","超過")) -> 限10字
B20: 款式 2-3（A-2-3） | E20: 款式 2-4（A-2-4） | H20: 款式 3-1（A-3-1）
A21: 副區 | B21: LOGO圖 (多圖用逗號分開) | D21: =IF(C21="","待填","OK") -> 待填 | E21: LOGO圖 (多圖用逗號分開) | G21: =IF(F21="","待填","OK") -> 待填 | H21: LOGO圖 (多圖用逗號分開) | J21: =IF(I21="","待填","OK") -> 待填
B22: 促標 | D22: =IF(C22="","限5字",IF(LENB(C22)/2<=5,"OK","超過")) -> 限5字 | E22: 促標 | G22: =IF(F22="","限5字",IF(LENB(F22)/2<=5,"OK","超過")) -> 限5字 | H22: 促標 | J22: =IF(I22="","限5字",IF(LENB(I22)/2<=5,"OK","超過")) -> 限5字
B23: 圓標 | D23: =IF(C23="","限5字",IF(LENB(C23)/2<=7,"OK","超過")) -> 限5字 | E23: 圓標 | G23: =IF(F23="","限5字",IF(LENB(F23)/2<=7,"OK","超過")) -> 限5字 | H23: 商品圖 (多圖用逗號分開) | J23: =IF(I23="","待填","OK") -> 待填
B24: 商品圖 (多圖用逗號分開) | D24: =IF(C24="","待填","OK") -> 待填 | E24: 商品圖 (多圖用逗號分開) | G24: =IF(F24="","待填","OK") -> 待填 | H24: 品名 | J24: =IF(I24="","限8字",IF(LENB(I24)/2<=8,"OK","超過")) -> 限8字
B25: 小字 | D25: =IF(C25="","限10字",IF(LENB(C25)/2<=10,"OK","超過")) -> 限10字 | H25: 小字 | J25: =IF(I25="","限10字",IF(LENB(I25)/2<=10,"OK","超過")) -> 限10字
H26: CTA | I26: ▶ | J26: =IF(I26="","限3字",IF(LENB(I26)/2<=3,"OK","超過")) -> OK
B29: 款式 3-2（A-3-2） | E29: 款式 3-3（A-3-3） | H29: 款式 3-4（A-3-4）
A30: 副區 | B30: LOGO圖 (多圖用逗號分開) | D30: =IF(C30="","待填","OK") -> 待填 | E30: LOGO圖 (多圖用逗號分開) | G30: =IF(F30="","待填","OK") -> 待填 | H30: LOGO圖 (多圖用逗號分開) | J30: =IF(I30="","待填","OK") -> 待填
B31: 促標 | D31: =IF(C31="","限5字",IF(LENB(C31)/2<=5,"OK","超過")) -> 限5字 | E31: 促標 | G31: =IF(F31="","限5字",IF(LENB(F31)/2<=5,"OK","超過")) -> 限5字 | H31: 促標 | J31: =IF(I31="","限5字",IF(LENB(I31)/2<=5,"OK","超過")) -> 限5字
B32: 商品圖 (多圖用逗號分開) | D32: =IF(C32="","待填","OK") -> 待填 | E32: 商品圖 (多圖用逗號分開) | G32: =IF(F32="","待填","OK") -> 待填 | H32: 商品圖 (多圖用逗號分開) | J32: =IF(I32="","待填","OK") -> 待填
B33: CTA | C33: ▶ | D33: =IF(C33="","限3字",IF(LENB(C33)/2<=3,"OK","超過")) -> OK | E33: CTA | F33: ▶ | G33: =IF(F33="","限3字",IF(LENB(F33)/2<=3,"OK","超過")) -> OK | H33: CTA | I33: ▶ | J33: =IF(I33="","限3字",IF(LENB(I33)/2<=3,"OK","超過")) -> OK
B34: 品名 | D34: =IF(C34="","限8字",IF(LENB(C34)/2<=8,"OK","超過")) -> 限8字 | E34: 小字 | G34: =IF(F34="","限10字",IF(LENB(F34)/2<=10,"OK","超過")) -> 限10字
B38: 款式 4-1（A-4-1） | E38: 款式 4-2（A-4-2） | H38: 款式 4-3（A-4-3）
A39: 副區 | B39: LOGO圖 (多圖用逗號分開) | D39: =IF(C39="","待填","OK") -> 待填 | E39: LOGO圖 (多圖用逗號分開) | G39: =IF(F39="","待填","OK") -> 待填 | H39: LOGO圖 (多圖用逗號分開) | J39: =IF(I39="","待填","OK") -> 待填
B40: 促標 | D40: =IF(C40="","限5字",IF(LENB(C40)/2<=5,"OK","超過")) -> 限5字 | E40: 促標 | G40: =IF(F40="","限5字",IF(LENB(F40)/2<=5,"OK","超過")) -> 限5字 | H40: 促標 | J40: =IF(I40="","限5字",IF(LENB(I40)/2<=5,"OK","超過")) -> 限5字
B41: 品名 | D41: =IF(C41="","限4字",IF(LENB(C41)/2<=4,"OK","超過")) -> 限4字 | E41: 商品圖 (多圖用逗號分開) | G41: =IF(F41="","待填","OK") -> 待填 | H41: 商品圖 (多圖用逗號分開) | J41: =IF(I41="","待填","OK") -> 待填
B42: 品名 | D42: =IF(C42="","限4字",IF(LENB(C42)/2<=4,"OK","超過")) -> 限4字 | E42: 品名 | G42: =IF(F42="","限8字",IF(LENB(F42)/2<=8,"OK","超過")) -> 限8字 | H42: 小字 | J42: =IF(I42="","限10字",IF(LENB(I42)/2<=10,"OK","超過")) -> 限10字
B43: 小字 | D43: =IF(C43="","限5字",IF(LENB(C43)/2<=5,"OK","超過")) -> 限5字 | E43: CTA | F43: 逛逛去 | G43: =IF(F43="","限3字",IF(LENB(F43)/2<=3,"OK","超過")) -> OK | H43: CTA | I43: 逛逛去 | J43: =IF(I43="","限3字",IF(LENB(I43)/2<=3,"OK","超過")) -> OK
B44: 商品圖 (多圖用逗號分開) | D44: =IF(C44="","待填","OK") -> 待填
B45: CTA | C45: 逛逛去 | D45: =IF(C45="","限3字",IF(LENB(C45)/2<=3,"OK","超過")) -> OK
B47: 款式 4-4（A-4-4） | E47: 款式 5-1（A-5-1） | H47: 款式 5-2（A-5-2）
A48: 副區 | B48: LOGO圖 (多圖用逗號分開) | D48: =IF(C48="","待填","OK") -> 待填 | E48: LOGO圖 (多圖用逗號分開) | G48: =IF(F48="","待填","OK") -> 待填 | H48: LOGO圖 (多圖用逗號分開) | J48: =IF(I48="","待填","OK") -> 待填
B49: 促標 | D49: =IF(C49="","限5字",IF(LENB(C49)/2<=5,"OK","超過")) -> 限5字 | E49: 促標 | G49: =IF(F49="","限5字",IF(LENB(F49)/2<=5,"OK","超過")) -> 限5字 | H49: 促標 | J49: =IF(I49="","限5字",IF(LENB(I49)/2<=5,"OK","超過")) -> 限5字
B50: 商品圖 (多圖用逗號分開) | D50: =IF(C50="","待填","OK") -> 待填 | E50: 品名 | G50: =IF(F50="","限4字",IF(LENB(F50)/2<=4,"OK","超過")) -> 限4字 | H50: 圓標 | J50: =IF(I50="","限5字",IF(LENB(I50)/2<=7,"OK","超過")) -> 限5字
B51: CTA | C51: 逛逛去 | D51: =IF(C51="","限3字",IF(LENB(C51)/2<=3,"OK","超過")) -> OK | E51: 品名 | G51: =IF(F51="","限4字",IF(LENB(F51)/2<=4,"OK","超過")) -> 限4字 | H51: 品名 | J51: =IF(I51="","限4字",IF(LENB(I51)/2<=4,"OK","超過")) -> 限4字
...

Sheet 設定
A1: 等級 | B1: MSBN額度 | C1: 資源1 | D1: 資源2 | E1: 資源3 | F1: 資源4 | G1: 資源5 | H1: 資源6 | I1: 資源7 | J1: 資源8 | K1: 資源9 | L1: 資源10 | M1: 資源11 | N1: 資源12 | O1: 類型1 | P1: 類型2 | Q1: 類型3 | R1: 類型4 | S1: 類型5 | T1: 類型6 | U1: 類型7 | V1: 類型8 | W1: 類型9 | X1: 類型10 | Y1: 類型11 | Z1: 類型12 | AB1: key | AC1: 顯示名稱 | AD1: 張數 | AE1: 尺寸 | AF1: 格式 | AG1: 規範字數 | AH1: 提醒 | AI1: 系統排版 | AJ1: 可用
A2: A Brand star (Mega) | B2: 8 | C2: LPBN | O2: 預設 | AB2: LPBN | AC2: LPBN | AD2: 2 | AE2: APP 1200×550 PC 1200×400 | AF2: JPG | AG2: 主標≤8；副標≤7；日期／警語≤14 | AH2: APP、PC 各 1 張 | AI2: LPBN_APP／LPBN_PC | AJ2: 是
A3: A Brand star (Mega) 資交 | B3: 4 | C3: LPBN | O3: 預設 | AB3: DDCard | AC3: DD Card BN (APP) | AD3: 1 | AE3: 531×792 | AF3: JPG | AG3: 主標≤8；副標≤7；日期/警語≤14 | AH3: LOGO、商品圖；CTA 依版型 | AI3: ddcard無logo／ddcard方logo／ddcard橫logo | AJ3: 是
A4: A 精選套裝 | B4: 4 | C4: LPBN | O4: 預設 | AB4: HBN | AC4: HBN (PC) | AD4: 1 | AE4: 1200×360 | AF4: JPG | AG4: 主標≤8；副標≤7；日期/警語≤14 | AH4: 橫式或方形 LOGO 版 | AI4: HBN_橫式LOGO／HBN_方式LOGO | AJ4: 是
A5: A 品牌旗艦MDD | B5: 6 | C5: LPBN | O5: 預設 | AB5: 活動總覽 | AC5: 活動總覽 | AD5: 1 | AE5: 1200x360 | AF5: JPG | AG5: 主標≤8；副標≤7；日期/警語≤14 | AJ5: 否
A6: A 品牌旗艦MDD 資交 | B6: 0 | C6: LPBN | O6: 預設 | AB6: 首頁LOGO牆 | AC6: 首頁 LOGO 牆 | AD6: 1 | AE6: 402×483 | AF6: JPG/PNG | AG6: LOGO／人物或商品圖可縮放 | AH6: LOGO 位於曝品或人物範圍內，可用滑鼠縮放；會呈現曝品圖中第1品。 | AI6: 首頁LOGO牆 | AJ6: 是
A7: B+ BOD A | B7: 6 | C7: LPBN | D7: DDCard | E7: HBN | F7: 活動總覽 | G7: 首頁LOGO牆 | H7: AR | I7: FB_Post | J7: AMS BN | K7: Coin_page | L7: IG | M7: SearchIcon | N7: SearchImage | O7: 預設 | P7: 預設 | Q7: 預設 | R7: 預設 | S7: 預設 | T7: 預設 | U7: 預設 | V7: 預設 | W7: 選配 | X7: 選配 | Y7: 選配 | Z7: 選配 | AB7: AR | AC7: AR | AD7: 1 | AE7: 100×100（依規範） | AF7: JPG/PNG | AG7: 文案≤6 或 LOGO；2擇1 | AH7: 目前系統尚未提供可編輯版型 | AI7: 尚未提供版型 | AJ7: 否
A8: B+ BOD A 資交 | B8: 0 | C8: LPBN | D8: DDCard | E8: HBN | F8: 活動總覽 | G8: 首頁LOGO牆 | H8: AR | I8: FB_Post | J8: AMS BN | K8: Coin_page | L8: IG | M8: SearchIcon | N8: SearchImage | O8: 預設 | P8: 預設 | Q8: 預設 | R8: 預設 | S8: 預設 | T8: 預設 | U8: 預設 | V8: 預設 | W8: 選配 | X8: 選配 | Y8: 選配 | Z8: 選配 | AB8: FB_Post | AC8: FB POST | AD8: 1 | AE8: 1200×630 | AF8: JPG | AG8: 品牌名≤9；主標≤8；副標≤7；日期/警語≤14 | AH8: 方 LOGO／橫 LOGO | AI8: FB_POST_方LOGO／FB_POST_橫LOGO | AJ8: 是
A9: B+ BOD B (Mega) | B9: 6 | C9: LPBN | D9: DDCard | E9: HBN | F9: 活動總覽 | G9: 首頁LOGO牆 | H9: AR | I9: FB_Post | J9: AMS BN | K9: Coin_page | L9: IG | O9: 預設 | P9: 預設 | Q9: 預設 | R9: 預設 | S9: 預設 | T9: 預設 | U9: 選配 | V9: 選配 | W9: 選配 | X9: 選配 | AB9: AMS BN | AC9: AMS BN | AD9: 1 | AE9: 1077×264（依規範） | AF9: JPG | AG9: 依 AMS 規格 | AH9: 目前系統尚未提供可編輯版型 | AI9: 尚未提供版型 | AJ9: 否
A10: B+ 基礎套裝 | B10: 6 | C10: LPBN | D10: DDCard | E10: HBN | F10: 活動總覽 | G10: 首頁LOGO牆 | H10: AR | I10: FB_Post | J10: AMS BN | K10: Coin_page | L10: IG | O10: 預設 | P10: 預設 | Q10: 預設 | R10: 預設 | S10: 預設 | T10: 預設 | U10: 選配 | V10: 選配 | W10: 選配 | X10: 選配 | AB10: Coin_page | AC10: Coin Page BN | AD10: 1 | AE10: 1200×391 | AF10: JPG | AG10: 品牌名≤9；主標≤8；副標≤7；日期/警語≤14 | AH10: 方 LOGO／橫 LOGO | AI10: Coin_pageBN_APP方LOGO／Coin_pageBN_APP橫LOGO | AJ10: 是
A11: B JBP多店 | B11: 3 | C11: LPBN | D11: IG | E11: HBN | F11: DDCard | G11: Coin_page | H11: FB_Post | I11: SCPN | J11: SearchImage | K11: SearchIcon | O11: 預設 | P11: 預設 | Q11: 預設 | R11: 預設 | S11: 預設 | T11: 預設 | U11: 預設 | V11: 預設 | W11: 預設 | AB11: IG | AC11: IG | AD11: 1 | AE11: 900×1600 | AF11: JPG | AG11: 品牌名≤9；主標≤8；副標≤7；日期/警語≤14 | AH11: 方 LOGO／橫 LOGO | AI11: IG方logo排版／IG橫logo排版 | AJ11: 是
A12: B 金牌 (Mega) | B12: 3 | C12: LPBN | D12: DDCard | E12: HBN | F12: 活動總覽 | G12: AR | H12: Coin_page | O12: 預設 | P12: 預設 | Q12: 預設 | R12: 預設 | S12: 預設 | T12: 選配 | AB12: SearchIcon | AC12: Search ICON | AD12: 1 | AE12: 120×120＋84×84 | AF12: PNG | AG12: ICON 文案≤2；或 LOGO／商品圖 | AH12: 120×120 建議 <50KB，另輸出 84×84 | AI12: SearchICON_LOGO／PRODUCT／TEXT | AJ12: 是
AB13: SearchImage | AC13: Search Image | AD13: 1 | AE13: 1125×156 | AF13: JPG/PNG | AG13: 副標≤7；LOGO 1～3 個 | AH13: 依選用版型提供 1～3 個 LOGO | AI13: Search_Image1logo／2logo／3logo | AJ13: 是
AB14: SCPN | AC14: SCBN／SCPN | AD14: 1 | AE14: 1200×200 | AF14: JPG | AG14: 品牌名≤9；副標≤7；CTA | AH14: 商城橫幅 | AI14: SCBN_APP | AJ14: 是

Sheet _BODA_META
A1: BODA_WORKORDER_V2
A2: kind | B2: sourceKey | C2: band | D2: order | E2: family | F2: variant | G2: combo | H2: msbnFile | I2: position | J2: label | K2: address | L2: header | M2: file | N2: locked | O2: hint | P2: targetKey
A3: subarea | B3: msbn-sub:0:0 | C3: 1 | D3: 1 | E3: A | F3: 1 | G3: 1 | I3: 1 | J3: 促標 | K3: D3 | L3: 款式 1-1 | M3: 副區-A-1-1.jpg | N3: 0 | O3: 限5字
A4: subarea | B4: msbn-sub:0:0 | C4: 1 | D4: 1 | E4: A | F4: 1 | G4: 1 | I4: 1 | J4: LOGO圖 | K4: D4 | L4: 款式 1-1 | M4: 副區-A-1-1.jpg | N4: 0 | O4: (圖檔名)
A5: subarea | B5: msbn-sub:0:0 | C5: 1 | D5: 1 | E5: A | F5: 1 | G5: 1 | I5: 1 | J5: 商品圖 | K5: D5 | L5: 款式 1-1 | M5: 副區-A-1-1.jpg | N5: 0 | O5: (圖檔名)
A6: subarea | B6: msbn-sub:0:0 | C6: 1 | D6: 1 | E6: A | F6: 1 | G6: 1 | I6: 1 | J6: 品名 | K6: D6 | L6: 款式 1-1 | M6: 副區-A-1-1.jpg | N6: 0 | O6: 限8字
A7: subarea | B7: msbn-sub:0:0 | C7: 1 | D7: 1 | E7: A | F7: 1 | G7: 1 | I7: 1 | J7: 警語 | K7: D7 | L7: 款式 1-1 | M7: 副區-A-1-1.jpg | N7: 0 | O7: 限10字
A8: subarea | B8: msbn-sub:0:1 | C8: 1 | D8: 2 | E8: A | F8: 1 | G8: 2 | I8: 2 | J8: 促標 | K8: I3 | L8: 款式 1-2 | M8: 副區-A-1-2.jpg | N8: 0 | O8: 限5字
A9: subarea | B9: msbn-sub:0:1 | C9: 1 | D9: 2 | E9: A | F9: 1 | G9: 2 | I9: 2 | J9: LOGO圖 | K9: I4 | L9: 款式 1-2 | M9: 副區-A-1-2.jpg | N9: 0 | O9: (圖檔名)
A10: subarea | B10: msbn-sub:0:1 | C10: 1 | D10: 2 | E10: A | F10: 1 | G10: 2 | I10: 2 | J10: 商品圖 | K10: I5 | L10: 款式 1-2 | M10: 副區-A-1-2.jpg | N10: 0 | O10: (圖檔名)
A11: subarea | B11: msbn-sub:0:1 | C11: 1 | D11: 2 | E11: A | F11: 1 | G11: 2 | I11: 2 | J11: 品名 | K11: I6 | L11: 款式 1-2 | M11: 副區-A-1-2.jpg | N11: 0 | O11: 限8字
A12: subarea | B12: msbn-sub:0:2 | C12: 1 | D12: 3 | E12: A | F12: 1 | G12: 3 | I12: 3 | J12: 促標 | K12: N3 | L12: 款式 1-3 | M12: 副區-A-1-3.jpg | N12: 0 | O12: 限5字
A13: subarea | B13: msbn-sub:0:2 | C13: 1 | D13: 3 | E13: A | F13: 1 | G13: 3 | I13: 3 | J13: LOGO圖 | K13: N4 | L13: 款式 1-3 | M13: 副區-A-1-3.jpg | N13: 0 | O13: (圖檔名)
A14: subarea | B14: msbn-sub:0:2 | C14: 1 | D14: 3 | E14: A | F14: 1 | G14: 3 | I14: 3 | J14: 商品圖 | K14: N5 | L14: 款式 1-3 | M14: 副區-A-1-3.jpg | N14: 0 | O14: (圖檔名)
... A312: subarea | B312: msbn-sub:27:0 | C312: 28 | D312: 65 | E312: D | F312: 4 | G312: 4 | I312: 1 | J312: CTA | K312: D190 | L312: 款式 4-4 | M312: 副區-D-4-4.jpg | N312: 0 | O312: 限3字
A313: subarea | B313: msbn-sub:28:0 | C313: 29 | D313: 66 | E313: E | F313: 1 | G313: 1 | I313: 1 | J313: 促標 | K313: D193 | L313: 款式 1-1 | M313: 副區-E-1-1.jpg | N313: 0
A314: subarea | B314: msbn-sub:28:0 | C314: 29 | D314: 66 | E314: E | F314: 1 | G314: 1 | I314: 1 | J314: LOGO圖 | K314: D194 | L314: 款式 1-1 | M314: 副區-E-1-1.jpg | N314: 0 | O314: (圖檔名)
A315: subarea | B315: msbn-sub:28:0 | C315: 29 | D315: 66 | E315: E | F315: 1 | G315: 1 | I315: 1 | J315: 商品圖 | K315: D195 | L315: 款式 1-1 | M315: 副區-E-1-1.jpg | N315: 0 | O315: (圖檔名)
A316: subarea | B316: msbn-sub:28:0 | C316: 29 | D316: 66 | E316: E | F316: 1 | G316: 1 | I316: 1 | J316: 品名-1 | K316: D196 | L316: 款式 1-1 | M316: 副區-E-1-1.jpg | N316: 0 | O316: 限5字
A317: subarea | B317: msbn-sub:28:0 | C317: 29 | D317: 66 | E317: E | F317: 1 | G317: 1 | I317: 1 | J317: 品名-2 | K317: G196 | L317: 款式 1-1 | M317: 副區-E-1-1.jpg | N317: 0 | O317: 限5字
A318: subarea | B318: msbn-sub:28:0 | C318: 29 | D318: 66 | E318: E | F318: 1 | G318: 1 | I318: 1 | J318: 警語-1 | K318: D197 | L318: 款式 1-1 | M318: 副區-E-1-1.jpg | N318: 0 | O318: 限6字
A319: subarea | B319: msbn-sub:28:0 | C319: 29 | D319: 66 | E319: E | F319: 1 | G319: 1 | I319: 1 | J319: 警語-2 | K319: G197 | L319: 款式 1-1 | M319: 副區-E-1-1.jpg | N319: 0 | O319: 限6字
A320: subarea | B320: msbn-sub:28:0 | C320: 29 | D320: 66 | E320: E | F320: 1 | G320: 1 | I320: 1 | J320: 圓標-1 | K320: D198 | L320: 款式 1-1 | M320: 副區-E-1-1.jpg | N320: 0 | O320: 限7字
A321: subarea | B321: msbn-sub:28:0 | C321: 29 | D321: 66 | E321: E | F321: 1 | G321: 1 | I321: 1 | J321: 圓標-2 | K321: G198 | L321: 款式 1-1 | M321: 副區-E-1-1.jpg | N321: 0 | O321: 限7字
A322: subarea | B322: msbn-sub:28:1 | C322: 29 | D322: 67 | E322: E | F322: 1 | G322: 2 | I322: 2 | J322: 促標 | K322: L193 | L322: 款式 1-2 | M322: 副區-E-1-2.jpg | N322: 0
A323: subarea | B323: msbn-sub:28:1 | C323: 29 | D323: 67 | E323: E | F323: 1 | G323: 2 | I323: 2 | J323: LOGO圖 | K323: L194 | L323: 款式 1-2 | M323: 副區-E-1-2.jpg | N323: 0 | O323: (圖檔名)
A324: subarea | B324: msbn-sub:28:1 | C324: 29 | D324: 67 | E324: E | F324: 1 | G324: 2 | I324: 2 | J324: 商品圖 | K324: L195 | L324: 款式 1-2 | M324: 副區-E-1-2.jpg | N324: 0 | O324: (圖檔名)
A325: subarea | B325: msbn-sub:28:1 | C325: 29 | D325: 67 | E325: E | F325: 1 | G325: 2 | I325: 2 | J325: 品名-1 | K325: L196 | L325: 款式 1-2 | M325: 副區-E-1-2.jpg | N325: 0 | O325: 限5字
A326: subarea | B326: msbn-sub:28:1 | C326: 29 | D326: 67 | E326: E | F326: 1 | G326: 2 | I326: 2 | J326: 品名-2 | K326: O196 | L326: 款式 1-2 | M326: 副區-E-1-2.jpg | N326: 0 | O326: 限5字
A327: subarea | B327: msbn-sub:28:1 | C327: 29 | D327: 67 | E327: E | F327: 1 | G327: 2 | I327: 2 | J327: 警語-1 | K327: L197 | L327: 款式 1-2 | M327: 副區-E-1-2.jpg | N327: 0 | O327: 限6字
A328: subarea | B328: msbn-sub:28:1 | C328: 29 | D328: 67 | E328: E | F328: 1 | G328: 2 | I328: 2 | J328: 警語-2 | K328: O197 | L328: 款式 1-2 | M328: 副區-E-1-2.jpg | N328: 0 | O328: 限6字
A329: subarea | B329: msbn-sub:29:0 | C329: 30 | D329: 68 | E329: E | F329: 1 | G329: 3 | I329: 1 | J329: 促標 | K329: D201 | L329: 款式 1-3 | M329: 副區-E-1-3.jpg | N329: 0
A330: subarea | B330: msbn-sub:29:0 | C330: 30 | D330: 68 | E330: E | F330: 1 | G330: 3 | I330: 1 | J330: LOGO圖 | K330: D202 | L330: 款式 1-3 | M330: 副區-E-1-3.jpg | N330: 0 | O330: (圖檔名)
A331: subarea | B331: msbn-sub:29:0 | C331: 30 | D331: 68 | E331: E | F331: 1 | G331: 3 | I331: 1 | J331: 商品圖 | K331: D203 | L331: 款式 1-3 | M331: 副區-E-1-3.jpg | N331: 0 | O331: (圖檔名)
A332: subarea | B332: msbn-sub:29:0 | C332: 30 | D332: 68 | E332: E | F332: 1 | G332: 3 | I332: 1 | J332: 品名-1 | K332: D204 | L332: 款式 1-3 | M332: 副區-E-1-3.jpg | N332: 0 | O332: 限5字
A333: subarea | B333: msbn-sub:29:0 | C333: 30 | D333: 68 | E333: E | F333: 1 | G333: 3 | I333: 1 | J333: 品名-2 | K333: G204 | L333: 款式 1-3 | M333: 副區-E-1-3.jpg | N333: 0 | O333: 限5字
A334: subarea | B334: msbn-sub:29:1 | C334: 30 | D334: 69 | E334: E | F334: 2 | G334: 1 | I334: 2 | J334: LOGO圖 | K334: L201 | L334: 款式 2-1 | M334: 副區-E-2-1.jpg | N334: 0 | O334: (圖檔名)
A335: subarea | B335: msbn-sub:29:1 | C335: 30 | D335: 69 | E335: E | F335: 2 | G335: 1 | I335: 2 | J335: 商品圖 | K335: L202 | L335: 款式 2-1 | M335: 副區-E-2-1.jpg | N335: 0 | O335: (圖檔名)
A336: subarea | B336: msbn-sub:29:1 | C336: 30 | D336: 69 | E336: E | F336: 2 | G336: 1 | I336: 2 | J336: 品名-1 | K336: L203 | L336: 款式 2-1 | M336: 副區-E-2-1.jpg | N336: 0 | O336: 限5字
A337: subarea | B337: msbn-sub:29:1 | C337: 30 | D337: 69 | E337: E | F337: 2 | G337: 1 | I337: 2 | J337: 品名-2 | K337: O203 | L337: 款式 2-1 | M337: 副區-E-2-1.jpg | N337: 0 | O337: 限5字
...

Sheet _BODA_BOTTOM
A1: BODA_BOTTOM_V1 | B1: MS Layout
A2: group | B2: title | C2: iconAddress | D2: logoAddress | E2: textAddress | F2: countAddress | G2: optional
A3: 1 | B3: 第1顆 | C3: E414 | D3: E415 | E3: C416 | F3: G416 | G3: 0
A4: 2 | B4: 第2顆 | C4: J414 | D4: J415 | E4: H416 | F4: L416 | G4: 0
A5: 3 | B5: 第3顆 | C5: O414 | D5: O415 | E5: M416 | F5: Q416 | G5: 1
A6: 4 | B6: 第4顆 | C6: T414 | D6: T415 | E6: R416 | F6: Y416 | G6: 1
A7: 5 | B7: 第5顆 | C7: AB414 | D7: AB415 | E7: Z416 | F7: AG416 | G7: 1

Sheet _BODA_BOTTOM_STATE
A1: BODA_BOTTOM_STATE_V1 | B1: 1 | C1: JSON chunks
A3: 1 | B3: { "format": "sticky-banner-project", "version": 2, "activeBannerIndex": 0, "sharpen": true, "banners": [ { "slotCount": 5, "activeSlotIndex": 0, "accentColor": "red", "slots": [ { "text": "主會場", "iconId": "bod-logo", "iconText": null }, { "text": "", "iconId": null, "iconText": null }, { "text": "", "iconId": null, "iconText": null }, { "text": "", "iconId": null, "iconText": null }, { "text": "", "iconId": null, "iconText": null } ] } ], "customIcons": [] }
