Workbook

Sheet 設定
A1: 等級 | B1: MSBN額度 | C1: 資源1 | D1: 資源2 | E1: 資源3 | F1: 資源4 | G1: 資源5 | H1: 資源6 | I1: 資源7 | J1: 資源8 | K1: 資源9 | L1: 資源10 | M1: 資源11 | N1: 資源12 | O1: 類型1 | P1: 類型2 | Q1: 類型3 | R1: 類型4 | S1: 類型5 | T1: 類型6 | U1: 類型7 | V1: 類型8 | W1: 類型9 | X1: 類型10 | Y1: 類型11 | Z1: 類型12 | AB1: key | AC1: 顯示名稱 | AD1: 張數 | AE1: 尺寸 | AF1: 格式 | AG1: 規範字數 | AH1: 提醒 | AI1: 系統排版 | AJ1: 可用
A2: A Brand star (Mega) | B2: 8 | AB2: DDCard | AC2: DD Card BN (APP) | AD2: 1 | AE2: 531×792 | AF2: JPG | AG2: 品牌名≤9；主標≤8；副標≤7；日期/警語≤14 | AH2: LOGO、商品圖；CTA 依版型 | AI2: ddcard方logo／ddcard橫logo | AJ2: 是
A3: A Brand star (Mega) 資交 | B3: 4 | AB3: HBN | AC3: HBN (PC) | AD3: 1 | AE3: 1200×360 | AF3: JPG | AG3: 品牌名≤9；主標≤8；副標≤7；日期/警語≤14 | AH3: 橫式或方形 LOGO 版 | AI3: HBN_橫式LOGO／HBN_方式LOGO | AJ3: 是
A4: A 精選套裝 | B4: 4 | AB4: 活動總覽 | AC4: 活動總覽 | AD4: 1 | AE4: 依活動規格 | AF4: JPG/PNG | AG4: 依活動需求 | AH4: 目前系統尚未提供可編輯版型 | AI4: 尚未提供版型 | AJ4: 否
A5: A 品牌旗艦MDD | B5: 6 | AB5: 首頁LOGO牆 | AC5: 首頁 LOGO 牆 | AD5: 1 | AE5: 402×483 | AF5: JPG/PNG | AG5: LOGO／人物或商品圖可縮放 | AH5: LOGO 位於曝品或人物範圍內，可用滑鼠縮放 | AI5: 首頁LOGO牆 | AJ5: 是
A6: A 品牌旗艦MDD 資交 | B6: 0 | AB6: AR | AC6: AR | AD6: 1 | AE6: 100×100（依規範） | AF6: JPG/PNG | AG6: 文案≤6 或 LOGO；2擇1 | AH6: 目前系統尚未提供可編輯版型 | AI6: 尚未提供版型 | AJ6: 否
A7: B+ BOD A | B7: 6 | C7: DDCard | D7: HBN | E7: 活動總覽 | F7: 首頁LOGO牆 | G7: AR | H7: FB_Post | I7: AMS BN | J7: Coin_page | K7: IG | L7: SearchIcon | M7: SearchImage | O7: 預設 | P7: 預設 | Q7: 預設 | R7: 預設 | S7: 預設 | T7: 預設 | U7: 預設 | V7: 選配 | W7: 選配 | X7: 選配 | Y7: 選配 | AB7: FB_Post | AC7: FB POST | AD7: 1 | AE7: 1200×630 | AF7: JPG | AG7: 品牌名≤9；主標≤8；副標≤7；日期/警語≤14 | AH7: 方 LOGO／橫 LOGO | AI7: FB_POST_方LOGO／FB_POST_橫LOGO | AJ7: 是
A8: B+ BOD A 資交 | B8: 0 | C8: DDCard | D8: HBN | E8: 活動總覽 | F8: 首頁LOGO牆 | G8: AR | H8: FB_Post | I8: AMS BN | J8: Coin_page | K8: IG | L8: SearchIcon | M8: SearchImage | O8: 預設 | P8: 預設 | Q8: 預設 | R8: 預設 | S8: 預設 | T8: 預設 | U8: 預設 | V8: 選配 | W8: 選配 | X8: 選配 | Y8: 選配 | AB8: AMS BN | AC8: AMS BN | AD8: 1 | AE8: 1077×264（依規範） | AF8: JPG | AG8: 依 AMS 規格 | AH8: 目前系統尚未提供可編輯版型 | AI8: 尚未提供版型 | AJ8: 否
A9: B+ BOD B (Mega) | B9: 6 | C9: DDCard | D9: HBN | E9: 活動總覽 | F9: 首頁LOGO牆 | G9: AR | H9: FB_Post | I9: AMS BN | J9: Coin_page | K9: IG | O9: 預設 | P9: 預設 | Q9: 預設 | R9: 預設 | S9: 預設 | T9: 選配 | U9: 選配 | V9: 選配 | W9: 選配 | AB9: Coin_page | AC9: Coin Page BN | AD9: 1 | AE9: 1200×391 | AF9: JPG | AG9: 品牌名≤9；主標≤8；副標≤7；日期/警語≤14 | AH9: 方 LOGO／橫 LOGO | AI9: Coin_pageBN_APP方LOGO／Coin_pageBN_APP橫LOGO | AJ9: 是
A10: B+ 基礎套裝 | B10: 6 | C10: DDCard | D10: HBN | E10: 活動總覽 | F10: 首頁LOGO牆 | G10: AR | H10: FB_Post | I10: AMS BN | J10: Coin_page | K10: IG | O10: 預設 | P10: 預設 | Q10: 預設 | R10: 預設 | S10: 預設 | T10: 選配 | U10: 選配 | V10: 選配 | W10: 選配 | AB10: IG | AC10: IG | AD10: 1 | AE10: 900×1600 | AF10: JPG | AG10: 品牌名≤9；主標≤8；副標≤7；日期/警語≤14 | AH10: 方 LOGO／橫 LOGO | AI10: IG方logo排版／IG橫logo排版 | AJ10: 是
A11: B JBP多店 | B11: 3 | C11: IG | D11: HBN | E11: DDCard | F11: Coin_page | G11: FB_Post | H11: SCPN | I11: SearchImage | J11: SearchIcon | O11: 預設 | P11: 預設 | Q11: 預設 | R11: 預設 | S11: 預設 | T11: 預設 | U11: 預設 | V11: 預設 | AB11: SearchIcon | AC11: Search ICON | AD11: 1 | AE11: 120×120＋84×84 | AF11: PNG | AG11: ICON 文案≤2；或 LOGO／商品圖 | AH11: 120×120 建議 <50KB，另輸出 84×84 | AI11: SearchICON_LOGO／PRODUCT／TEXT | AJ11: 是
A12: B 金牌 (Mega) | B12: 3 | C12: DDCard | D12: HBN | E12: 活動總覽 | F12: AR | G12: Coin_page | O12: 預設 | P12: 預設 | Q12: 預設 | R12: 預設 | S12: 選配 | AB12: SearchImage | AC12: Search Image | AD12: 1 | AE12: 1125×156 | AF12: JPG/PNG | AG12: 副標≤7；LOGO 1～3 個 | AH12: 依選用版型提供 1～3 個 LOGO | AI12: Search_Image1logo／2logo／3logo | AJ12: 是
AB13: SCPN | AC13: SCBN／SCPN | AD13: 1 | AE13: 1200×200 | AF13: JPG | AG13: 品牌名≤9；副標≤7；CTA | AH13: 商城橫幅 | AI13: SCBN_APP | AJ13: 是

Sheet _BODA_META
A1: BODA_WORKORDER_V2
A2: kind | B2: sourceKey | C2: band | D2: order | E2: family | F2: variant | G2: combo | H2: msbnFile | I2: position | J2: label | K2: address | L2: header | M2: file | N2: locked | O2: hint | P2: targetKey
A3: subarea | B3: msbn-sub:0:0 | C3: 1 | D3: 1 | E3: A | F3: 1 | G3: 1 | I3: 1 | J3: 促標 | K3: D4 | L3: 款式 1-1 | M3: 副區-A-1-1.jpg | N3: 0 | O3: 限8個字
A4: subarea | B4: msbn-sub:0:0 | C4: 1 | D4: 1 | E4: A | F4: 1 | G4: 1 | I4: 1 | J4: LOGO圖 | K4: D5 | L4: 款式 1-1 | M4: 副區-A-1-1.jpg | N4: 0 | O4: (檔名/券名)
A5: subarea | B5: msbn-sub:0:0 | C5: 1 | D5: 1 | E5: A | F5: 1 | G5: 1 | I5: 1 | J5: 商品 | K5: D6 | L5: 款式 1-1 | M5: 副區-A-1-1.jpg | N5: 0 | O5: (檔名/券名)
A6: subarea | B6: msbn-sub:0:0 | C6: 1 | D6: 1 | E6: A | F6: 1 | G6: 1 | I6: 1 | J6: 品名 | K6: D7 | L6: 款式 1-1 | M6: 副區-A-1-1.jpg | N6: 0 | O6: 限8個字
A7: subarea | B7: msbn-sub:0:0 | C7: 1 | D7: 1 | E7: A | F7: 1 | G7: 1 | I7: 1 | J7: 警語 | K7: D8 | L7: 款式 1-1 | M7: 副區-A-1-1.jpg | N7: 0 | O7: 限10個字
A8: subarea | B8: msbn-sub:0:1 | C8: 1 | D8: 2 | E8: A | F8: 1 | G8: 2 | I8: 2 | J8: 促標 | K8: I4 | L8: 款式 1-2 | M8: 副區-A-1-2.jpg | N8: 0 | O8: 限8個字
A9: subarea | B9: msbn-sub:0:1 | C9: 1 | D9: 2 | E9: A | F9: 1 | G9: 2 | I9: 2 | J9: LOGO圖 | K9: I5 | L9: 款式 1-2 | M9: 副區-A-1-2.jpg | N9: 0 | O9: (檔名/券名)
A10: subarea | B10: msbn-sub:0:1 | C10: 1 | D10: 2 | E10: A | F10: 1 | G10: 2 | I10: 2 | J10: 商品 | K10: I6 | L10: 款式 1-2 | M10: 副區-A-1-2.jpg | N10: 0 | O10: (檔名/券名)
A11: subarea | B11: msbn-sub:0:1 | C11: 1 | D11: 2 | E11: A | F11: 1 | G11: 2 | I11: 2 | J11: 品名 | K11: I7 | L11: 款式 1-2 | M11: 副區-A-1-2.jpg | N11: 0 | O11: 限8個字
A12: subarea | B12: msbn-sub:0:2 | C12: 1 | D12: 3 | E12: A | F12: 1 | G12: 3 | I12: 3 | J12: 促標 | K12: N4 | L12: 款式 1-3 | M12: 副區-A-1-3.jpg | N12: 0 | O12: 限8個字
A13: subarea | B13: msbn-sub:0:2 | C13: 1 | D13: 3 | E13: A | F13: 1 | G13: 3 | I13: 3 | J13: LOGO圖 | K13: N5 | L13: 款式 1-3 | M13: 副區-A-1-3.jpg | N13: 0 | O13: (檔名/券名)
A14: subarea | B14: msbn-sub:0:2 | C14: 1 | D14: 3 | E14: A | F14: 1 | G14: 3 | I14: 3 | J14: 商品 | K14: N6 | L14: 款式 1-3 | M14: 副區-A-1-3.jpg | N14: 0 | O14: (檔名/券名)
... A352: subarea | B352: msbn-sub:31:3 | C352: 32 | D352: 75 | E352: F | F352: 1 | G352: 1 | I352: 4 | J352: 警語 | K352: P258 | L352: 款式 1-1 | M352: 副區-F-1-1.jpg | N352: 0 | O352: 限6個字
A353: msbn | B353: msbn:32 | C353: 33 | D353: 76 | H353: MSBN-A-1-1.jpg | I353: 1 | J353: 促標 | K353: D263 | L353: MSBN-A-1-1 | M353: MSBN-A-1-1.jpg | N353: 0 | O353: 促標最多7字內
A354: msbn | B354: msbn:32 | C354: 33 | D354: 76 | H354: MSBN-A-1-1.jpg | I354: 1 | J354: 商品 | K354: L263 | L354: MSBN-A-1-1 | M354: MSBN-A-1-1.jpg | N354: 0 | O354: (圖檔名)
A355: msbn | B355: msbn:32 | C355: 33 | D355: 76 | H355: MSBN-A-1-1.jpg | I355: 1 | J355: 品名 | K355: D264 | L355: MSBN-A-1-1 | M355: MSBN-A-1-1.jpg | N355: 0 | O355: 品名一排最多8字
A356: msbn | B356: msbn:32 | C356: 33 | D356: 76 | H356: MSBN-A-1-1.jpg | I356: 1 | J356: 代言人圖 | K356: L264 | L356: MSBN-A-1-1 | M356: MSBN-A-1-1.jpg | N356: 0 | O356: (圖檔名)
A357: msbn | B357: msbn:32 | C357: 33 | D357: 76 | H357: MSBN-A-1-1.jpg | I357: 1 | J357: 品名 | K357: D265 | L357: MSBN-A-1-1 | M357: MSBN-A-1-1.jpg | N357: 0 | O357: 品名一排最多8字
A358: msbn | B358: msbn:32 | C358: 33 | D358: 76 | H358: MSBN-A-1-1.jpg | I358: 1 | J358: 圓標 | K358: L265 | L358: MSBN-A-1-1 | M358: MSBN-A-1-1.jpg | N358: 0 | O358: 圓標05字內
A359: msbn | B359: msbn:32 | C359: 33 | D359: 76 | H359: MSBN-A-1-1.jpg | I359: 1 | J359: 警語 | K359: D266 | L359: MSBN-A-1-1 | M359: MSBN-A-1-1.jpg | N359: 0 | O359: 小字最多可9個字內
A360: msbn | B360: msbn:32 | C360: 33 | D360: 76 | H360: MSBN-A-1-1.jpg | I360: 1 | J360: 簽名小字 | K360: L266 | L360: MSBN-A-1-1 | M360: MSBN-A-1-1.jpg | N360: 0 | O360: 每行限5字
A361: msbn | B361: msbn:32 | C361: 33 | D361: 76 | H361: MSBN-A-1-1.jpg | I361: 1 | J361: 簽名小字 | K361: L267 | L361: MSBN-A-1-1 | M361: MSBN-A-1-1.jpg | N361: 0 | O361: 每行限5字
A362: msbn | B362: msbn:32 | C362: 33 | D362: 76 | H362: MSBN-A-1-1.jpg | I362: 1 | J362: 簽名圖 | K362: L268 | L362: MSBN-A-1-1 | M362: MSBN-A-1-1.jpg | N362: 0 | O362: (檔名)
A363: msbn | B363: msbn:32 | C363: 33 | D363: 76 | H363: MSBN-A-1-1.jpg | I363: 1 | J363: CTA | K363: L269 | L363: MSBN-A-1-1 | M363: MSBN-A-1-1.jpg | N363: 0 | O363: 逛逛去
A364: msbn | B364: msbn:33 | C364: 34 | D364: 77 | H364: MSBN-A-1-2.jpg | I364: 1 | J364: 商品 | K364: D272 | L364: MSBN-A-1-2 | M364: MSBN-A-1-2.jpg | N364: 0 | O364: (圖檔名)
... A553: msbn | B553: msbn:52 | C553: 53 | D553: 96 | H553: MSBN-B-4-2.jpg | I553: 4 | J553: 警語 | K553: P433 | L553: MSBN-B-4-2 | M553: MSBN-B-4-2.jpg | N553: 0 | O553: 小字警語6字
A554: msbn | B554: msbn:53 | C554: 54 | D554: 97 | H554: MSBN-C-1-1.jpg | I554: 1 | J554: 促標 | K554: D438 | L554: MSBN-C-1-1 | M554: MSBN-C-1-1.jpg | N554: 0 | O554: 促標最多7字內 | P554: promo
A555: msbn | B555: msbn:53 | C555: 54 | D555: 97 | H555: MSBN-C-1-1.jpg | I555: 1 | J555: 警語 | K555: D439 | L555: MSBN-C-1-1 | M555: MSBN-C-1-1.jpg | N555: 0 | O555: 小字最多可10個字以內 | P555: warn
A556: msbn | B556: msbn:53 | C556: 54 | D556: 97 | H556: MSBN-C-1-1.jpg | I556: 1 | J556: 文案 | K556: D441 | L556: MSBN-C-1-1 | M556: MSBN-C-1-1.jpg | N556: 0 | O556: 文案一排最多6字 | P556: copy2
A557: msbn | B557: msbn:53 | C557: 54 | D557: 97 | H557: MSBN-C-1-1.jpg | I557: 1 | J557: LOGO圖 | K557: L441 | L557: MSBN-C-1-1 | M557: MSBN-C-1-1.jpg | N557: 0 | O557: (檔名/券名) | P557: logoImg
A558: msbn | B558: msbn:53 | C558: 54 | D558: 97 | H558: MSBN-C-1-1.jpg | I558: 1 | J558: 文案 | K558: D442 | L558: MSBN-C-1-1 | M558: MSBN-C-1-1.jpg | N558: 0 | O558: 文案一排最多6字 | P558: copy2
A559: msbn | B559: msbn:53 | C559: 54 | D559: 97 | H559: MSBN-C-1-1.jpg | I559: 1 | J559: 文案 | K559: L442 | L559: MSBN-C-1-1 | M559: MSBN-C-1-1.jpg | N559: 0 | O559: 文案一排最多6字 | P559: copy
A560: msbn | B560: msbn:53 | C560: 54 | D560: 97 | H560: MSBN-C-1-1.jpg | I560: 1 | J560: 文案 | K560: L443 | L560: MSBN-C-1-1 | M560: MSBN-C-1-1.jpg | N560: 0 | O560: 文案一排最多6字 | P560: copy
A561: msbn | B561: msbn:54 | C561: 55 | D561: 98 | H561: MSBN-C-1-2.jpg | I561: 1 | J561: 促標 | K561: D449 | L561: MSBN-C-1-2 | M561: MSBN-C-1-2.jpg | N561: 0 | O561: 促標最多7字內 | P561: promo
A562: msbn | B562: msbn:54 | C562: 55 | D562: 98 | H562: MSBN-C-1-2.jpg | I562: 1 | J562: 警語 | K562: D450 | L562: MSBN-C-1-2 | M562: MSBN-C-1-2.jpg | N562: 0 | O562: 小字最多可10個字以內 | P562: warn
A563: msbn | B563: msbn:54 | C563: 55 | D563: 98 | H563: MSBN-C-1-2.jpg | I563: 1 | J563: 文案 | K563: D452 | L563: MSBN-C-1-2 | M563: MSBN-C-1-2.jpg | N563: 0 | O563: 文案一排最多6字 | P563: copy2
A564: msbn | B564: msbn:54 | C564: 55 | D564: 98 | H564: MSBN-C-1-2.jpg | I564: 1 | J564: LOGO圖 | K564: L452 | L564: MSBN-C-1-2 | M564: MSBN-C-1-2.jpg | N564: 0 | O564: (檔名/券名) | P564: logoImg
A565: msbn | B565: msbn:54 | C565: 55 | D565: 98 | H565: MSBN-C-1-2.jpg | I565: 1 | J565: 文案 | K565: D453 | L565: MSBN-C-1-2 | M565: MSBN-C-1-2.jpg | N565: 0 | O565: 文案一排最多6字 | P565: copy2
...

Sheet _BODA_BOTTOM
A1: BODA_BOTTOM_V1 | B1: MS Layout
A2: group | B2: title | C2: iconAddress | D2: logoAddress | E2: textAddress | F2: countAddress | G2: optional
A3: 1 | B3: 第1顆 | C3: E561 | D3: E562 | E3: C563 | F3: G563 | G3: 0
A4: 2 | B4: 第2顆 | C4: J561 | D4: J562 | E4: H563 | F4: L563 | G4: 0
A5: 3 | B5: 第3顆 | C5: O561 | D5: O562 | E5: M563 | F5: Q563 | G5: 1
A6: 4 | B6: 第4顆 | C6: T561 | D6: T562 | E6: R563 | F6: Y563 | G6: 1
A7: 5 | B7: 第5顆 | C7: AB561 | D7: AB562 | E7: Z563 | F7: AG563 | G7: 1

Sheet _BODA_BOTTOM_STATE

Sheet _BODA_RULES
A1: keyword | B1: replacement | C1: action
A2: 撒 | B2: 自動改成"灑" | C2: replace
A3: 購物金 | B3: 自動改成"優惠券" | C3: replace
A4: 抵用券 | B4: 自動改成"優惠券" | C4: replace
A5: 折價券 | B5: 自動改成"優惠券" | C5: replace
A6: 蝦皮券 | B6: 自動改成"優惠券" | C6: replace
A7: 蝦幣券 | B7: 自動改成"優惠券" | C7: replace
A8: 折扣券 | B8: 自動改成"優惠券" | C8: replace
A9: $蝦幣 | B9: 自動改成"蝦幣" | C9: replace
A10: 蝦幣$ | B10: 自動改成"蝦幣" | C10: replace
A11: \$\d+\s*蝦幣 | B11: 自動改成"蝦幣" | C11: replace
A12: 元 | B12: 直接無法輸入 | C12: block
... A69: 兩 | B69: 自動改成"2" | C69: replace

Sheet 設定 (1)
A1: 等級 | B1: MSBN額度 | C1: 資源1 | D1: 資源2 | E1: 資源3 | F1: 資源4 | G1: 資源5 | H1: 資源6 | I1: 資源7 | J1: 資源8 | K1: 資源9 | L1: 資源10 | M1: 資源11 | N1: 資源12 | O1: 類型1 | P1: 類型2 | Q1: 類型3 | R1: 類型4 | S1: 類型5 | T1: 類型6 | U1: 類型7 | V1: 類型8 | W1: 類型9 | X1: 類型10 | Y1: 類型11 | Z1: 類型12 | AB1: key | AC1: 顯示名稱 | AD1: 張數 | AE1: 尺寸 | AF1: 格式 | AG1: 規範字數 | AH1: 提醒 | AI1: 系統排版 | AJ1: 可用
A2: A Brand star (Mega) | B2: 8 | AB2: DDCard | AC2: DD Card BN (APP) | AD2: 1 | AE2: 531×792 | AF2: JPG | AG2: 品牌名≤9；主標≤8；副標≤7；日期/警語≤14 | AH2: LOGO、商品圖；CTA 依版型 | AI2: ddcard方logo／ddcard橫logo | AJ2: 是
A3: A Brand star (Mega) 資交 | B3: 4 | AB3: HBN | AC3: HBN (PC) | AD3: 1 | AE3: 1200×360 | AF3: JPG | AG3: 品牌名≤9；主標≤8；副標≤7；日期/警語≤14 | AH3: 橫式或方形 LOGO 版 | AI3: HBN_橫式LOGO／HBN_方式LOGO | AJ3: 是
A4: A 精選套裝 | B4: 4 | AB4: 活動總覽 | AC4: 活動總覽 | AD4: 1 | AE4: 依活動規格 | AF4: JPG/PNG | AG4: 依活動需求 | AH4: 目前系統尚未提供可編輯版型 | AI4: 尚未提供版型 | AJ4: 否
A5: A 品牌旗艦MDD | B5: 6 | AB5: 首頁LOGO牆 | AC5: 首頁 LOGO 牆 | AD5: 1 | AE5: 402×483 | AF5: JPG/PNG | AG5: LOGO／人物或商品圖可縮放 | AH5: LOGO 位於曝品或人物範圍內，可用滑鼠縮放 | AI5: 首頁LOGO牆 | AJ5: 是
A6: A 品牌旗艦MDD 資交 | B6: 0 | AB6: AR | AC6: AR | AD6: 1 | AE6: 100×100（依規範） | AF6: JPG/PNG | AG6: 文案≤6 或 LOGO；2擇1 | AH6: 目前系統尚未提供可編輯版型 | AI6: 尚未提供版型 | AJ6: 否
A7: B+ BOD A | B7: 6 | C7: DDCard | D7: HBN | E7: 活動總覽 | F7: 首頁LOGO牆 | G7: AR | H7: FB_Post | I7: AMS BN | J7: Coin_page | K7: IG | L7: SearchIcon | M7: SearchImage | O7: 預設 | P7: 預設 | Q7: 預設 | R7: 預設 | S7: 預設 | T7: 預設 | U7: 預設 | V7: 選配 | W7: 選配 | X7: 選配 | Y7: 選配 | AB7: FB_Post | AC7: FB POST | AD7: 1 | AE7: 1200×630 | AF7: JPG | AG7: 品牌名≤9；主標≤8；副標≤7；日期/警語≤14 | AH7: 方 LOGO／橫 LOGO | AI7: FB_POST_方LOGO／FB_POST_橫LOGO | AJ7: 是
A8: B+ BOD A 資交 | B8: 0 | C8: DDCard | D8: HBN | E8: 活動總覽 | F8: 首頁LOGO牆 | G8: AR | H8: FB_Post | I8: AMS BN | J8: Coin_page | K8: IG | L8: SearchIcon | M8: SearchImage | O8: 預設 | P8: 預設 | Q8: 預設 | R8: 預設 | S8: 預設 | T8: 預設 | U8: 預設 | V8: 選配 | W8: 選配 | X8: 選配 | Y8: 選配 | AB8: AMS BN | AC8: AMS BN | AD8: 1 | AE8: 1077×264（依規範） | AF8: JPG | AG8: 依 AMS 規格 | AH8: 目前系統尚未提供可編輯版型 | AI8: 尚未提供版型 | AJ8: 否
A9: B+ BOD B (Mega) | B9: 6 | C9: DDCard | D9: HBN | E9: 活動總覽 | F9: 首頁LOGO牆 | G9: AR | H9: FB_Post | I9: AMS BN | J9: Coin_page | K9: IG | O9: 預設 | P9: 預設 | Q9: 預設 | R9: 預設 | S9: 預設 | T9: 選配 | U9: 選配 | V9: 選配 | W9: 選配 | AB9: Coin_page | AC9: Coin Page BN | AD9: 1 | AE9: 1200×391 | AF9: JPG | AG9: 品牌名≤9；主標≤8；副標≤7；日期/警語≤14 | AH9: 方 LOGO／橫 LOGO | AI9: Coin_pageBN_APP方LOGO／Coin_pageBN_APP橫LOGO | AJ9: 是
A10: B+ 基礎套裝 | B10: 6 | C10: DDCard | D10: HBN | E10: 活動總覽 | F10: 首頁LOGO牆 | G10: AR | H10: FB_Post | I10: AMS BN | J10: Coin_page | K10: IG | O10: 預設 | P10: 預設 | Q10: 預設 | R10: 預設 | S10: 預設 | T10: 選配 | U10: 選配 | V10: 選配 | W10: 選配 | AB10: IG | AC10: IG | AD10: 1 | AE10: 900×1600 | AF10: JPG | AG10: 品牌名≤9；主標≤8；副標≤7；日期/警語≤14 | AH10: 方 LOGO／橫 LOGO | AI10: IG方logo排版／IG橫logo排版 | AJ10: 是
A11: B JBP多店 | B11: 3 | C11: IG | D11: HBN | E11: DDCard | F11: Coin_page | G11: FB_Post | H11: SCPN | I11: SearchImage | J11: SearchIcon | O11: 預設 | P11: 預設 | Q11: 預設 | R11: 預設 | S11: 預設 | T11: 預設 | U11: 預設 | V11: 預設 | AB11: SearchIcon | AC11: Search ICON | AD11: 1 | AE11: 120×120＋84×84 | AF11: PNG | AG11: ICON 文案≤2；或 LOGO／商品圖 | AH11: 120×120 建議 <50KB，另輸出 84×84 | AI11: SearchICON_LOGO／PRODUCT／TEXT | AJ11: 是
A12: B 金牌 (Mega) | B12: 3 | C12: DDCard | D12: HBN | E12: 活動總覽 | F12: AR | G12: Coin_page | O12: 預設 | P12: 預設 | Q12: 預設 | R12: 預設 | S12: 選配 | AB12: SearchImage | AC12: Search Image | AD12: 1 | AE12: 1125×156 | AF12: JPG/PNG | AG12: 副標≤7；LOGO 1～3 個 | AH12: 依選用版型提供 1～3 個 LOGO | AI12: Search_Image1logo／2logo／3logo | AJ12: 是
AB13: SCPN | AC13: SCBN／SCPN | AD13: 1 | AE13: 1200×200 | AF13: JPG | AG13: 品牌名≤9；副標≤7；CTA | AH13: 商城橫幅 | AI13: SCBN_APP | AJ13: 是

Sheet _BODA_META (1)
A1: BODA_WORKORDER_V2
A2: kind | B2: sourceKey | C2: band | D2: order | E2: family | F2: variant | G2: combo | H2: msbnFile | I2: position | J2: label | K2: address | L2: header | M2: file | N2: locked | O2: hint | P2: targetKey
A3: subarea | B3: msbn-sub:0:0 | C3: 1 | D3: 1 | E3: A | F3: 1 | G3: 1 | I3: 1 | J3: 促標 | K3: D4 | L3: 款式 1-1 | M3: 副區-A-1-1.jpg | N3: 0 | O3: 限8個字
A4: subarea | B4: msbn-sub:0:0 | C4: 1 | D4: 1 | E4: A | F4: 1 | G4: 1 | I4: 1 | J4: LOGO圖 | K4: D5 | L4: 款式 1-1 | M4: 副區-A-1-1.jpg | N4: 0 | O4: (檔名/券名)
A5: subarea | B5: msbn-sub:0:0 | C5: 1 | D5: 1 | E5: A | F5: 1 | G5: 1 | I5: 1 | J5: 商品 | K5: D6 | L5: 款式 1-1 | M5: 副區-A-1-1.jpg | N5: 0 | O5: (檔名/券名)
A6: subarea | B6: msbn-sub:0:0 | C6: 1 | D6: 1 | E6: A | F6: 1 | G6: 1 | I6: 1 | J6: 品名 | K6: D7 | L6: 款式 1-1 | M6: 副區-A-1-1.jpg | N6: 0 | O6: 限8個字
A7: subarea | B7: msbn-sub:0:0 | C7: 1 | D7: 1 | E7: A | F7: 1 | G7: 1 | I7: 1 | J7: 警語 | K7: D8 | L7: 款式 1-1 | M7: 副區-A-1-1.jpg | N7: 0 | O7: 限10個字
A8: subarea | B8: msbn-sub:0:1 | C8: 1 | D8: 2 | E8: A | F8: 1 | G8: 2 | I8: 2 | J8: 促標 | K8: I4 | L8: 款式 1-2 | M8: 副區-A-1-2.jpg | N8: 0 | O8: 限8個字
A9: subarea | B9: msbn-sub:0:1 | C9: 1 | D9: 2 | E9: A | F9: 1 | G9: 2 | I9: 2 | J9: LOGO圖 | K9: I5 | L9: 款式 1-2 | M9: 副區-A-1-2.jpg | N9: 0 | O9: (檔名/券名)
A10: subarea | B10: msbn-sub:0:1 | C10: 1 | D10: 2 | E10: A | F10: 1 | G10: 2 | I10: 2 | J10: 商品 | K10: I6 | L10: 款式 1-2 | M10: 副區-A-1-2.jpg | N10: 0 | O10: (檔名/券名)
A11: subarea | B11: msbn-sub:0:1 | C11: 1 | D11: 2 | E11: A | F11: 1 | G11: 2 | I11: 2 | J11: 品名 | K11: I7 | L11: 款式 1-2 | M11: 副區-A-1-2.jpg | N11: 0 | O11: 限8個字
A12: subarea | B12: msbn-sub:0:2 | C12: 1 | D12: 3 | E12: A | F12: 1 | G12: 3 | I12: 3 | J12: 促標 | K12: N4 | L12: 款式 1-3 | M12: 副區-A-1-3.jpg | N12: 0 | O12: 限8個字
A13: subarea | B13: msbn-sub:0:2 | C13: 1 | D13: 3 | E13: A | F13: 1 | G13: 3 | I13: 3 | J13: LOGO圖 | K13: N5 | L13: 款式 1-3 | M13: 副區-A-1-3.jpg | N13: 0 | O13: (檔名/券名)
A14: subarea | B14: msbn-sub:0:2 | C14: 1 | D14: 3 | E14: A | F14: 1 | G14: 3 | I14: 3 | J14: 商品 | K14: N6 | L14: 款式 1-3 | M14: 副區-A-1-3.jpg | N14: 0 | O14: (檔名/券名)
... A352: subarea | B352: msbn-sub:31:3 | C352: 32 | D352: 75 | E352: F | F352: 1 | G352: 1 | I352: 4 | J352: 警語 | K352: P258 | L352: 款式 1-1 | M352: 副區-F-1-1.jpg | N352: 0 | O352: 限6個字
A353: msbn | B353: msbn:32 | C353: 33 | D353: 76 | H353: MSBN-A-1-1.jpg | I353: 1 | J353: 促標 | K353: D263 | L353: MSBN-A-1-1 | M353: MSBN-A-1-1.jpg | N353: 0 | O353: 促標最多7字內
A354: msbn | B354: msbn:32 | C354: 33 | D354: 76 | H354: MSBN-A-1-1.jpg | I354: 1 | J354: 商品 | K354: H263 | L354: MSBN-A-1-1 | M354: MSBN-A-1-1.jpg | N354: 0 | O354: (圖檔名)
A355: msbn | B355: msbn:32 | C355: 33 | D355: 76 | H355: MSBN-A-1-1.jpg | I355: 1 | J355: 品名 | K355: D264 | L355: MSBN-A-1-1 | M355: MSBN-A-1-1.jpg | N355: 0 | O355: 品名一排最多8字
A356: msbn | B356: msbn:32 | C356: 33 | D356: 76 | H356: MSBN-A-1-1.jpg | I356: 1 | J356: 代言人圖 | K356: H264 | L356: MSBN-A-1-1 | M356: MSBN-A-1-1.jpg | N356: 0 | O356: (圖檔名)
A357: msbn | B357: msbn:32 | C357: 33 | D357: 76 | H357: MSBN-A-1-1.jpg | I357: 1 | J357: 品名 | K357: D265 | L357: MSBN-A-1-1 | M357: MSBN-A-1-1.jpg | N357: 0 | O357: 品名一排最多8字
A358: msbn | B358: msbn:32 | C358: 33 | D358: 76 | H358: MSBN-A-1-1.jpg | I358: 1 | J358: 圓標 | K358: H265 | L358: MSBN-A-1-1 | M358: MSBN-A-1-1.jpg | N358: 0 | O358: 圓標05字內
A359: msbn | B359: msbn:32 | C359: 33 | D359: 76 | H359: MSBN-A-1-1.jpg | I359: 1 | J359: 警語 | K359: D266 | L359: MSBN-A-1-1 | M359: MSBN-A-1-1.jpg | N359: 0 | O359: 小字最多可9個字內
A360: msbn | B360: msbn:32 | C360: 33 | D360: 76 | H360: MSBN-A-1-1.jpg | I360: 1 | J360: 簽名小字 | K360: H266 | L360: MSBN-A-1-1 | M360: MSBN-A-1-1.jpg | N360: 0 | O360: 每行限5字
A361: msbn | B361: msbn:32 | C361: 33 | D361: 76 | H361: MSBN-A-1-1.jpg | I361: 1 | J361: 簽名小字 | K361: H267 | L361: MSBN-A-1-1 | M361: MSBN-A-1-1.jpg | N361: 0 | O361: 每行限5字
A362: msbn | B362: msbn:32 | C362: 33 | D362: 76 | H362: MSBN-A-1-1.jpg | I362: 1 | J362: 簽名圖 | K362: H268 | L362: MSBN-A-1-1 | M362: MSBN-A-1-1.jpg | N362: 0 | O362: (檔名)
A363: msbn | B363: msbn:32 | C363: 33 | D363: 76 | H363: MSBN-A-1-1.jpg | I363: 1 | J363: CTA | K363: H269 | L363: MSBN-A-1-1 | M363: MSBN-A-1-1.jpg | N363: 0 | O363: 逛逛去
A364: msbn | B364: msbn:33 | C364: 34 | D364: 77 | H364: MSBN-A-1-2.jpg | I364: 1 | J364: 商品 | K364: D272 | L364: MSBN-A-1-2 | M364: MSBN-A-1-2.jpg | N364: 0 | O364: (圖檔名)
... A407: msbn | B407: msbn:36 | C407: 37 | D407: 80 | H407: MSBN-A-2-3.jpg | I407: 1 | J407: 圓標 | K407: D303 | L407: MSBN-A-2-3 | M407: MSBN-A-2-3.jpg | N407: 0 | O407: 圓標05字內
A408: msbn | B408: msbn:36 | C408: 37 | D408: 80 | H408: MSBN-A-2-3.jpg | I408: 1 | J408: 色塊 | K408: D304 | L408: MSBN-A-2-3 | M408: MSBN-A-2-3.jpg | N408: 0 | P408: bgColor2
A409: msbn | B409: msbn:36 | C409: 37 | D409: 80 | H409: MSBN-A-2-3.jpg | I409: 1 | J409: 色塊 | K409: D305 | L409: MSBN-A-2-3 | M409: MSBN-A-2-3.jpg | N409: 0 | P409: bgColor
A410: msbn | B410: msbn:36 | C410: 37 | D410: 80 | H410: MSBN-A-2-3.jpg | I410: 2 | J410: 促標 | K410: H299 | L410: MSBN-A-2-3 | M410: MSBN-A-2-3.jpg | N410: 0 | O410: 促標6個字內
A411: msbn | B411: msbn:36 | C411: 37 | D411: 80 | H411: MSBN-A-2-3.jpg | I411: 2 | J411: 商品 | K411: H300 | L411: MSBN-A-2-3 | M411: MSBN-A-2-3.jpg | N411: 0 | O411: (圖檔名)
A412: msbn | B412: msbn:36 | C412: 37 | D412: 80 | H412: MSBN-A-2-3.jpg | I412: 2 | J412: 品名 | K412: H301 | L412: MSBN-A-2-3 | M412: MSBN-A-2-3.jpg | N412: 0 | O412: 品名一排最多8字
A413: msbn | B413: msbn:36 | C413: 37 | D413: 80 | H413: MSBN-A-2-3.jpg | I413: 2 | J413: 品名 | K413: H302 | L413: MSBN-A-2-3 | M413: MSBN-A-2-3.jpg | N413: 0 | O413: 品名一排最多8字
A414: msbn | B414: msbn:36 | C414: 37 | D414: 80 | H414: MSBN-A-2-3.jpg | I414: 2 | J414: 圓標 | K414: H303 | L414: MSBN-A-2-3 | M414: MSBN-A-2-3.jpg | N414: 0 | O414: 圓標05字內
A415: msbn | B415: msbn:36 | C415: 37 | D415: 80 | H415: MSBN-A-2-3.jpg | I415: 2 | J415: 色塊 | K415: H304 | L415: MSBN-A-2-3 | M415: MSBN-A-2-3.jpg | N415: 0 | P415: bgColor2
A416: msbn | B416: msbn:36 | C416: 37 | D416: 80 | H416: MSBN-A-2-3.jpg | I416: 2 | J416: 色塊 | K416: H305 | L416: MSBN-A-2-3 | M416: MSBN-A-2-3.jpg | N416: 0 | P416: bgColor
A417: msbn | B417: msbn:37 | C417: 38 | D417: 81 | H417: MSBN-A-2-4.jpg | I417: 1 | J417: LOGO圖 | K417: D308 | L417: MSBN-A-2-4 | M417: MSBN-A-2-4.jpg | N417: 0 | O417: (檔名/券名)
A418: msbn | B418: msbn:37 | C418: 38 | D418: 81 | H418: MSBN-A-2-4.jpg | I418: 2 | J418: LOGO圖 | K418: H308 | L418: MSBN-A-2-4 | M418: MSBN-A-2-4.jpg | N418: 0 | O418: (檔名/券名)
A419: msbn | B419: msbn:38 | C419: 39 | D419: 82 | H419: MSBN-A-3-1.jpg | I419: 1 | J419: 商品 | K419: D311 | L419: MSBN-A-3-1 | M419: MSBN-A-3-1.jpg | N419: 0 | O419: (圖檔名)
...

Sheet _BODA_BOTTOM (1)
A1: BODA_BOTTOM_V1 | B1: MS Layout
A2: group | B2: title | C2: iconAddress | D2: logoAddress | E2: textAddress | F2: countAddress | G2: optional
A3: 1 | B3: 第1顆 | C3: E490 | D3: E491 | E3: C492 | F3: G492 | G3: 0
A4: 2 | B4: 第2顆 | C4: J490 | D4: J491 | E4: H492 | F4: L492 | G4: 0
A5: 3 | B5: 第3顆 | C5: O490 | D5: O491 | E5: M492 | F5: Q492 | G5: 1
A6: 4 | B6: 第4顆 | C6: T490 | D6: T491 | E6: R492 | F6: Y492 | G6: 1
A7: 5 | B7: 第5顆 | C7: AB490 | D7: AB491 | E7: Z492 | F7: AG492 | G7: 1

Sheet _BODA_BOTTOM_STATE (1)

Sheet _BODA_RULES (1)
A1: keyword | B1: replacement | C1: action
A2: 撒 | B2: 自動改成"灑" | C2: replace
A3: 購物金 | B3: 自動改成"優惠券" | C3: replace
A4: 抵用券 | B4: 自動改成"優惠券" | C4: replace
A5: 折價券 | B5: 自動改成"優惠券" | C5: replace
A6: 蝦皮券 | B6: 自動改成"優惠券" | C6: replace
A7: 蝦幣券 | B7: 自動改成"優惠券" | C7: replace
A8: 折扣券 | B8: 自動改成"優惠券" | C8: replace
A9: $蝦幣 | B9: 自動改成"蝦幣" | C9: replace
A10: 蝦幣$ | B10: 自動改成"蝦幣" | C10: replace
A11: \$\d+\s*蝦幣 | B11: 自動改成"蝦幣" | C11: replace
A12: 元 | B12: 直接無法輸入 | C12: block
... A69: 兩 | B69: 自動改成"2" | C69: replace

Sheet 工單總覽
A1: BODA 工單總覽
A3: 包套(等級) | B3: B JBP多店 | E3: MSBN 額度 | F3: =IFERROR(VLOOKUP(B3,'設定 (2)'!$A$2:$B$12,2,FALSE),0) -> 3 | H3: 輸出時間 | I3: 46267.293
A4: 負責人 | E4: 版本 | F4: V1 | H4: 更新重點
A5: 活動時間 | E5: 美術 Deadline | H5: 總製作張數 | I5: =SUM(C19:C30)+107 -> 115
A6: 工作項目名稱 | E6: 行銷目標
A7: 目標客群
A9: 曝光資源共用文案與色彩
A10: 背景顏色 | B10: #26c6da | E10: 連動規則 | F10: 與「曝光資源」背景色、匯入工單統一背景及 MSBN D 系列卡片背景同步；此處記錄匯出當下色號。
A11: 品牌名 | E11: 上限 9 | F11: 曝光資源品牌名稱；中文 1、英數 0.5。 | I11: =IF(B11="","限9字",IF(LENB(B11)/2<=9,"OK","超過")) -> 限9字
A12: 主標 | E12: 上限 8 | F12: 曝光資源主標；中文 1、英數 0.5。 | I12: =IF(B12="","限8字",IF(LENB(B12)/2<=8,"OK","超過")) -> 限8字
A13: 副標 | E13: 上限 7 | F13: 曝光資源副標；中文 1、英數 0.5。 | I13: =IF(B13="","限7字",IF(LENB(B13)/2<=7,"OK","超過")) -> 限7字
A14: 日期／警語 | E14: 上限 14 | F14: 日期、活動期間或警語；中文 1、英數 0.5。 | I14: =IF(B14="","限14字",IF(LENB(B14)/2<=14,"OK","超過")) -> 限14字
A15: ICON 獨立文案 | E15: 上限 2 | F15: Search ICON 文字版；也可改用 LOGO／商品圖；中文 1、英數 0.5。 | I15: =IF(B15="","限2字",IF(LENB(B15)/2<=2,"OK","超過")) -> 限2字
A17: 製作曝光資源（依包套／等級自動切換；預設張數可手動調整，選配預設為 0）
A18: 版位 | B18: 類型 | C18: 張數 | D18: 尺寸 | E18: 格式 | F18: 規範字數 | G18: 提醒 | H18: 系統排版 | I18: Check
A19: {=IFERROR(INDEX('設定 (2)'!$C$2:$N$12,MATCH($B$3,'設定 (2)'!$A$2:$A$12,0),1),"")} -> IG | B19: {=IFERROR(INDEX('設定 (2)'!$O$2:$Z$12,MATCH($B$3,'設定 (2)'!$A$2:$A$12,0),1),"")} -> 預設 | C19: =IF(A19="","",IF(B19="預設",1,0)) -> 1 | D19: =IF(A19="","",IFERROR(VLOOKUP(A19,'設定 (2)'!$AB$2:$AJ$13,4,FALSE),"")) -> 900×1600 | E19: =IF(A19="","",IFERROR(VLOOKUP(A19,'設定 (2)'!$AB$2:$AJ$13,5,FALSE),"")) -> JPG | F19: =IF(A19="","",IFERROR(VLOOKUP(A19,'設定 (2)'!$AB$2:$AJ$13,6,FALSE),"")) -> 品牌名≤9；主標≤8；副標≤7；日期/警語≤14 | G19: =IF(A19="","",IFERROR(VLOOKUP(A19,'設定 (2)'!$AB$2:$AJ$13,7,FALSE),"")) -> 方 LOGO／橫 LOGO | H19: =IF(A19="","",IFERROR(VLOOKUP(A19,'設定 (2)'!$AB$2:$AJ$13,8,FALSE),"尚未提供版型")) -> IG方logo排版／IG橫logo排版 | I19: =IF(A19="","",IF(C19=0,"未選",IF(H19="尚未提供版型","缺版型","待製作"))) -> 待製作
A20: {=IFERROR(INDEX('設定 (2)'!$C$2:$N$12,MATCH($B$3,'設定 (2)'!$A$2:$A$12,0),2),"")} -> HBN | B20: {=IFERROR(INDEX('設定 (2)'!$O$2:$Z$12,MATCH($B$3,'設定 (2)'!$A$2:$A$12,0),2),"")} -> 預設 | C20: =IF(A20="","",IF(B20="預設",1,0)) -> 1 | D20: =IF(A20="","",IFERROR(VLOOKUP(A20,'設定 (2)'!$AB$2:$AJ$13,4,FALSE),"")) -> 1200×360 | E20: =IF(A20="","",IFERROR(VLOOKUP(A20,'設定 (2)'!$AB$2:$AJ$13,5,FALSE),"")) -> JPG | F20: =IF(A20="","",IFERROR(VLOOKUP(A20,'設定 (2)'!$AB$2:$AJ$13,6,FALSE),"")) -> 品牌名≤9；主標≤8；副標≤7；日期/警語≤14 | G20: =IF(A20="","",IFERROR(VLOOKUP(A20,'設定 (2)'!$AB$2:$AJ$13,7,FALSE),"")) -> 橫式或方形 LOGO 版 | H20: =IF(A20="","",IFERROR(VLOOKUP(A20,'設定 (2)'!$AB$2:$AJ$13,8,FALSE),"尚未提供版型")) -> HBN_橫式LOGO／HBN_方式LOGO | I20: =IF(A20="","",IF(C20=0,"未選",IF(H20="尚未提供版型","缺版型","待製作"))) -> 待製作
A21: {=IFERROR(INDEX('設定 (2)'!$C$2:$N$12,MATCH($B$3,'設定 (2)'!$A$2:$A$12,0),3),"")} -> DDCard | B21: {=IFERROR(INDEX('設定 (2)'!$O$2:$Z$12,MATCH($B$3,'設定 (2)'!$A$2:$A$12,0),3),"")} -> 預設 | C21: =IF(A21="","",IF(B21="預設",1,0)) -> 1 | D21: =IF(A21="","",IFERROR(VLOOKUP(A21,'設定 (2)'!$AB$2:$AJ$13,4,FALSE),"")) -> 531×792 | E21: =IF(A21="","",IFERROR(VLOOKUP(A21,'設定 (2)'!$AB$2:$AJ$13,5,FALSE),"")) -> JPG | F21: =IF(A21="","",IFERROR(VLOOKUP(A21,'設定 (2)'!$AB$2:$AJ$13,6,FALSE),"")) -> 品牌名≤9；主標≤8；副標≤7；日期/警語≤14 | G21: =IF(A21="","",IFERROR(VLOOKUP(A21,'設定 (2)'!$AB$2:$AJ$13,7,FALSE),"")) -> LOGO、商品圖；CTA 依版型 | H21: =IF(A21="","",IFERROR(VLOOKUP(A21,'設定 (2)'!$AB$2:$AJ$13,8,FALSE),"尚未提供版型")) -> ddcard方logo／ddcard橫logo | I21: =IF(A21="","",IF(C21=0,"未選",IF(H21="尚未提供版型","缺版型","待製作"))) -> 待製作
A22: {=IFERROR(INDEX('設定 (2)'!$C$2:$N$12,MATCH($B$3,'設定 (2)'!$A$2:$A$12,0),4),"")} -> Coin_page | B22: {=IFERROR(INDEX('設定 (2)'!$O$2:$Z$12,MATCH($B$3,'設定 (2)'!$A$2:$A$12,0),4),"")} -> 預設 | C22: =IF(A22="","",IF(B22="預設",1,0)) -> 1 | D22: =IF(A22="","",IFERROR(VLOOKUP(A22,'設定 (2)'!$AB$2:$AJ$13,4,FALSE),"")) -> 1200×391 | E22: =IF(A22="","",IFERROR(VLOOKUP(A22,'設定 (2)'!$AB$2:$AJ$13,5,FALSE),"")) -> JPG | F22: =IF(A22="","",IFERROR(VLOOKUP(A22,'設定 (2)'!$AB$2:$AJ$13,6,FALSE),"")) -> 品牌名≤9；主標≤8；副標≤7；日期/警語≤14 | G22: =IF(A22="","",IFERROR(VLOOKUP(A22,'設定 (2)'!$AB$2:$AJ$13,7,FALSE),"")) -> 方 LOGO／橫 LOGO | H22: =IF(A22="","",IFERROR(VLOOKUP(A22,'設定 (2)'!$AB$2:$AJ$13,8,FALSE),"尚未提供版型")) -> Coin_pageBN_APP方LOGO／Coin_pageBN_APP橫LOGO | I22: =IF(A22="","",IF(C22=0,"未選",IF(H22="尚未提供版型","缺版型","待製作"))) -> 待製作
A23: {=IFERROR(INDEX('設定 (2)'!$C$2:$N$12,MATCH($B$3,'設定 (2)'!$A$2:$A$12,0),5),"")} -> FB_Post | B23: {=IFERROR(INDEX('設定 (2)'!$O$2:$Z$12,MATCH($B$3,'設定 (2)'!$A$2:$A$12,0),5),"")} -> 預設 | C23: =IF(A23="","",IF(B23="預設",1,0)) -> 1 | D23: =IF(A23="","",IFERROR(VLOOKUP(A23,'設定 (2)'!$AB$2:$AJ$13,4,FALSE),"")) -> 1200×630 | E23: =IF(A23="","",IFERROR(VLOOKUP(A23,'設定 (2)'!$AB$2:$AJ$13,5,FALSE),"")) -> JPG | F23: =IF(A23="","",IFERROR(VLOOKUP(A23,'設定 (2)'!$AB$2:$AJ$13,6,FALSE),"")) -> 品牌名≤9；主標≤8；副標≤7；日期/警語≤14 | G23: =IF(A23="","",IFERROR(VLOOKUP(A23,'設定 (2)'!$AB$2:$AJ$13,7,FALSE),"")) -> 方 LOGO／橫 LOGO | H23: =IF(A23="","",IFERROR(VLOOKUP(A23,'設定 (2)'!$AB$2:$AJ$13,8,FALSE),"尚未提供版型")) -> FB_POST_方LOGO／FB_POST_橫LOGO | I23: =IF(A23="","",IF(C23=0,"未選",IF(H23="尚未提供版型","缺版型","待製作"))) -> 待製作
A24: {=IFERROR(INDEX('設定 (2)'!$C$2:$N$12,MATCH($B$3,'設定 (2)'!$A$2:$A$12,0),6),"")} -> SCPN | B24: {=IFERROR(INDEX('設定 (2)'!$O$2:$Z$12,MATCH($B$3,'設定 (2)'!$A$2:$A$12,0),6),"")} -> 預設 | C24: =IF(A24="","",IF(B24="預設",1,0)) -> 1 | D24: =IF(A24="","",IFERROR(VLOOKUP(A24,'設定 (2)'!$AB$2:$AJ$13,4,FALSE),"")) -> 1200×200 | E24: =IF(A24="","",IFERROR(VLOOKUP(A24,'設定 (2)'!$AB$2:$AJ$13,5,FALSE),"")) -> JPG | F24: =IF(A24="","",IFERROR(VLOOKUP(A24,'設定 (2)'!$AB$2:$AJ$13,6,FALSE),"")) -> 品牌名≤9；副標≤7；CTA | G24: =IF(A24="","",IFERROR(VLOOKUP(A24,'設定 (2)'!$AB$2:$AJ$13,7,FALSE),"")) -> 商城橫幅 | H24: =IF(A24="","",IFERROR(VLOOKUP(A24,'設定 (2)'!$AB$2:$AJ$13,8,FALSE),"尚未提供版型")) -> SCBN_APP | I24: =IF(A24="","",IF(C24=0,"未選",IF(H24="尚未提供版型","缺版型","待製作"))) -> 待製作
A25: {=IFERROR(INDEX('設定 (2)'!$C$2:$N$12,MATCH($B$3,'設定 (2)'!$A$2:$A$12,0),7),"")} -> SearchImage | B25: {=IFERROR(INDEX('設定 (2)'!$O$2:$Z$12,MATCH($B$3,'設定 (2)'!$A$2:$A$12,0),7),"")} -> 預設 | C25: =IF(A25="","",IF(B25="預設",1,0)) -> 1 | D25: =IF(A25="","",IFERROR(VLOOKUP(A25,'設定 (2)'!$AB$2:$AJ$13,4,FALSE),"")) -> 1125×156 | E25: =IF(A25="","",IFERROR(VLOOKUP(A25,'設定 (2)'!$AB$2:$AJ$13,5,FALSE),"")) -> JPG/PNG | F25: =IF(A25="","",IFERROR(VLOOKUP(A25,'設定 (2)'!$AB$2:$AJ$13,6,FALSE),"")) -> 副標≤7；LOGO 1～3 個 | G25: =IF(A25="","",IFERROR(VLOOKUP(A25,'設定 (2)'!$AB$2:$AJ$13,7,FALSE),"")) -> 依選用版型提供 1～3 個 LOGO | H25: =IF(A25="","",IFERROR(VLOOKUP(A25,'設定 (2)'!$AB$2:$AJ$13,8,FALSE),"尚未提供版型")) -> Search_Image1logo／2logo／3logo | I25: =IF(A25="","",IF(C25=0,"未選",IF(H25="尚未提供版型","缺版型","待製作"))) -> 待製作
A26: {=IFERROR(INDEX('設定 (2)'!$C$2:$N$12,MATCH($B$3,'設定 (2)'!$A$2:$A$12,0),8),"")} -> SearchIcon | B26: {=IFERROR(INDEX('設定 (2)'!$O$2:$Z$12,MATCH($B$3,'設定 (2)'!$A$2:$A$12,0),8),"")} -> 預設 | C26: =IF(A26="","",IF(B26="預設",1,0)) -> 1 | D26: =IF(A26="","",IFERROR(VLOOKUP(A26,'設定 (2)'!$AB$2:$AJ$13,4,FALSE),"")) -> 120×120＋84×84 | E26: =IF(A26="","",IFERROR(VLOOKUP(A26,'設定 (2)'!$AB$2:$AJ$13,5,FALSE),"")) -> PNG | F26: =IF(A26="","",IFERROR(VLOOKUP(A26,'設定 (2)'!$AB$2:$AJ$13,6,FALSE),"")) -> ICON 文案≤2；或 LOGO／商品圖 | G26: =IF(A26="","",IFERROR(VLOOKUP(A26,'設定 (2)'!$AB$2:$AJ$13,7,FALSE),"")) -> 120×120 建議 <50KB，另輸出 84×84 | H26: =IF(A26="","",IFERROR(VLOOKUP(A26,'設定 (2)'!$AB$2:$AJ$13,8,FALSE),"尚未提供版型")) -> SearchICON_LOGO／PRODUCT／TEXT | I26: =IF(A26="","",IF(C26=0,"未選",IF(H26="尚未提供版型","缺版型","待製作"))) -> 待製作
A27: {=IFERROR(INDEX('設定 (2)'!$C$2:$N$12,MATCH($B$3,'設定 (2)'!$A$2:$A$12,0),9),"")} | B27: {=IFERROR(INDEX('設定 (2)'!$O$2:$Z$12,MATCH($B$3,'設定 (2)'!$A$2:$A$12,0),9),"")} | C27: =IF(A27="","",IF(B27="預設",1,0)) | D27: =IF(A27="","",IFERROR(VLOOKUP(A27,'設定 (2)'!$AB$2:$AJ$13,4,FALSE),"")) | E27: =IF(A27="","",IFERROR(VLOOKUP(A27,'設定 (2)'!$AB$2:$AJ$13,5,FALSE),"")) | F27: =IF(A27="","",IFERROR(VLOOKUP(A27,'設定 (2)'!$AB$2:$AJ$13,6,FALSE),"")) | G27: =IF(A27="","",IFERROR(VLOOKUP(A27,'設定 (2)'!$AB$2:$AJ$13,7,FALSE),"")) | H27: =IF(A27="","",IFERROR(VLOOKUP(A27,'設定 (2)'!$AB$2:$AJ$13,8,FALSE),"尚未提供版型")) | I27: =IF(A27="","",IF(C27=0,"未選",IF(H27="尚未提供版型","缺版型","待製作")))
A28: {=IFERROR(INDEX('設定 (2)'!$C$2:$N$12,MATCH($B$3,'設定 (2)'!$A$2:$A$12,0),10),"")} | B28: {=IFERROR(INDEX('設定 (2)'!$O$2:$Z$12,MATCH($B$3,'設定 (2)'!$A$2:$A$12,0),10),"")} | C28: =IF(A28="","",IF(B28="預設",1,0)) | D28: =IF(A28="","",IFERROR(VLOOKUP(A28,'設定 (2)'!$AB$2:$AJ$13,4,FALSE),"")) | E28: =IF(A28="","",IFERROR(VLOOKUP(A28,'設定 (2)'!$AB$2:$AJ$13,5,FALSE),"")) | F28: =IF(A28="","",IFERROR(VLOOKUP(A28,'設定 (2)'!$AB$2:$AJ$13,6,FALSE),"")) | G28: =IF(A28="","",IFERROR(VLOOKUP(A28,'設定 (2)'!$AB$2:$AJ$13,7,FALSE),"")) | H28: =IF(A28="","",IFERROR(VLOOKUP(A28,'設定 (2)'!$AB$2:$AJ$13,8,FALSE),"尚未提供版型")) | I28: =IF(A28="","",IF(C28=0,"未選",IF(H28="尚未提供版型","缺版型","待製作")))
A29: {=IFERROR(INDEX('設定 (2)'!$C$2:$N$12,MATCH($B$3,'設定 (2)'!$A$2:$A$12,0),11),"")} | B29: {=IFERROR(INDEX('設定 (2)'!$O$2:$Z$12,MATCH($B$3,'設定 (2)'!$A$2:$A$12,0),11),"")} | C29: =IF(A29="","",IF(B29="預設",1,0)) | D29: =IF(A29="","",IFERROR(VLOOKUP(A29,'設定 (2)'!$AB$2:$AJ$13,4,FALSE),"")) | E29: =IF(A29="","",IFERROR(VLOOKUP(A29,'設定 (2)'!$AB$2:$AJ$13,5,FALSE),"")) | F29: =IF(A29="","",IFERROR(VLOOKUP(A29,'設定 (2)'!$AB$2:$AJ$13,6,FALSE),"")) | G29: =IF(A29="","",IFERROR(VLOOKUP(A29,'設定 (2)'!$AB$2:$AJ$13,7,FALSE),"")) | H29: =IF(A29="","",IFERROR(VLOOKUP(A29,'設定 (2)'!$AB$2:$AJ$13,8,FALSE),"尚未提供版型")) | I29: =IF(A29="","",IF(C29=0,"未選",IF(H29="尚未提供版型","缺版型","待製作")))
A30: {=IFERROR(INDEX('設定 (2)'!$C$2:$N$12,MATCH($B$3,'設定 (2)'!$A$2:$A$12,0),12),"")} | B30: {=IFERROR(INDEX('設定 (2)'!$O$2:$Z$12,MATCH($B$3,'設定 (2)'!$A$2:$A$12,0),12),"")} | C30: =IF(A30="","",IF(B30="預設",1,0)) | D30: =IF(A30="","",IFERROR(VLOOKUP(A30,'設定 (2)'!$AB$2:$AJ$13,4,FALSE),"")) | E30: =IF(A30="","",IFERROR(VLOOKUP(A30,'設定 (2)'!$AB$2:$AJ$13,5,FALSE),"")) | F30: =IF(A30="","",IFERROR(VLOOKUP(A30,'設定 (2)'!$AB$2:$AJ$13,6,FALSE),"")) | G30: =IF(A30="","",IFERROR(VLOOKUP(A30,'設定 (2)'!$AB$2:$AJ$13,7,FALSE),"")) | H30: =IF(A30="","",IFERROR(VLOOKUP(A30,'設定 (2)'!$AB$2:$AJ$13,8,FALSE),"尚未提供版型")) | I30: =IF(A30="","",IF(C30=0,"未選",IF(H30="尚未提供版型","缺版型","待製作")))
A33: 全版位排版檢查（副區＋MSBN；內容欄與視覺參考請至 MS Layout 查看）
A34: 類型 | B34: 版位名稱 | C34: Band | D34: 位置數 | E34: 素材檔案 | F34: 字數／欄位規則 | G34: 提醒 | H34: MS Layout | I34: Check
A35: 副區 | B35: 副區 一排3（左／中／右） | C35: 1 | D35: 3 | E35: 副區-A-1-1.jpg / 副區-A-1-2.jpg / 副區-A-1-3.jpg | F35: 限8個字；(檔名/券名)；限10個字 | G35: 綠色欄位可填；固定欄位已鎖 | H35: 第 3 列 | I35: 待填
A36: 副區 | B36: 副區 一排3（左／中／右） | C36: 2 | D36: 3 | E36: 副區-A-1-4.jpg / 副區-A-2-1.jpg / 副區-A-2-2.jpg | F36: 限8個字；(檔名/券名)；限10個字；限5個字 | G36: 綠色欄位可填；固定欄位已鎖 | H36: 第 11 列 | I36: 待填
A37: 副區 | B37: 副區 一排3（左／中／右） | C37: 3 | D37: 3 | E37: 副區-A-2-3.jpg / 副區-A-2-4.jpg / 副區-A-3-1.jpg | F37: 限8個字；(檔名/券名)；限10個字；限5個字；(icon圖，無文字) | G37: 綠色欄位可填；固定欄位已鎖 | H37: 第 19 列 | I37: 待填
A38: 副區 | B38: 副區 一排3（左／中／右） | C38: 4 | D38: 3 | E38: 副區-A-3-2.jpg / 副區-A-3-3.jpg / 副區-A-3-4.jpg | F38: 限8個字；(檔名/券名)；(icon圖，無文字)；限10個字 | G38: 綠色欄位可填；固定欄位已鎖 | H38: 第 27 列 | I38: 待填
A39: 副區 | B39: 副區 一排3（左／中／右） | C39: 5 | D39: 3 | E39: 副區-A-4-1.jpg / 副區-A-4-2.jpg / 副區-A-4-3.jpg | F39: 限8個字；(檔名/券名)；限4+4個字；限5個字；限3個字；限10個字 | G39: 綠色欄位可填；固定欄位已鎖 | H39: 第 35 列 | I39: 待填
A40: 副區 | B40: 副區 一排3（左／中／右） | C40: 6 | D40: 3 | E40: 副區-A-4-4.jpg / 副區-A-5-1.jpg / 副區-A-5-2.jpg | F40: 限8個字；(檔名/券名)；限3個字；限4+4個字；限5個字 | G40: 綠色欄位可填；固定欄位已鎖 | H40: 第 43 列 | I40: 待填
A41: 副區 | B41: 副區 一排3（左／中／右） | C41: 7 | D41: 1 | E41: 副區-A-5-3.jpg | F41: 限8個字；(檔名/券名)；限4+4個字；限5個字；(icon圖，無文字) | G41: 綠色欄位可填；固定欄位已鎖 | H41: 第 51 列 | I41: 待填
A42: 副區 | B42: 副區 一排3（左／中／右） | C42: 8 | D42: 3 | E42: 副區-B-1-1.jpg / 副區-B-1-2.jpg / 副區-B-1-3.jpg | F42: 限8個字；(檔名/券名)；限10個字 | G42: 綠色欄位可填；固定欄位已鎖 | H42: 第 59 列 | I42: 待填
A43: 副區 | B43: 副區 一排3（左／中／右） | C43: 9 | D43: 3 | E43: 副區-B-1-4.jpg / 副區-B-2-1.jpg / 副區-B-2-2.jpg | F43: 限8個字；(檔名/券名)；限10個字；限5個字 | G43: 綠色欄位可填；固定欄位已鎖 | H43: 第 67 列 | I43: 待填
A44: 副區 | B44: 副區 一排3（左／中／右） | C44: 10 | D44: 3 | E44: 副區-B-2-3.jpg / 副區-B-2-4.jpg / 副區-B-3-1.jpg | F44: 限8個字；(檔名/券名)；限10個字；限5個字；(icon圖，無文字) | G44: 綠色欄位可填；固定欄位已鎖 | H44: 第 75 列 | I44: 待填
A45: 副區 | B45: 副區 一排3（左／中／右） | C45: 11 | D45: 3 | E45: 副區-B-3-2.jpg / 副區-B-3-3.jpg / 副區-B-3-4.jpg | F45: 限8個字；(檔名/券名)；(icon圖，無文字)；限10個字 | G45: 綠色欄位可填；固定欄位已鎖 | H45: 第 83 列 | I45: 待填
...

Sheet MS Layout 
A1: 素材名稱 | B1: 版位／規格 | C1: Layout（綠色欄位可填；固定欄位與規則已鎖定） | T1: 視覺參考（目前系統實際版位）
C2: 中文 1 字、英數與半形符號 0.5 字；純數字自動以 $／千分位顯示；匯入 BODA 後混合文案也會整理；禁用語會阻擋並標紅 | T2: 圖片僅供版配與欄位位置對照，不代表最終正式稿
A3: 副區 | B3: 副區 一排3（左／中／右） 左：款式 1-1（A-1-1） 中：款式 1-2（A-1-2） 右：款式 1-3（A-1-3） Band 1 | C3: 左 | H3: 中 | M3: 右 | T3: 左 | X3: 中 | AC3: 右
C4: 促標 | G4: =IF(D4="","限8字",IF(LENB(D4)/2<=8,"OK","超過")) -> 限8字 | H4: 促標 | L4: =IF(I4="","限8字",IF(LENB(I4)/2<=8,"OK","超過")) -> 限8字 | M4: 促標 | R4: =IF(N4="","限8字",IF(LENB(N4)/2<=8,"OK","超過")) -> 限8字
C5: LOGO圖 | G5: =IF(D5="","待填","OK") -> 待填 | H5: LOGO圖 | L5: =IF(I5="","待填","OK") -> 待填 | M5: LOGO圖 | R5: =IF(N5="","待填","OK") -> 待填
C6: 商品 (多圖用逗號分開) | G6: =IF(D6="","待填",IF(ISNUMBER(SEARCH(".",D6)),"OK","記得加副檔名")) -> 待填 | H6: 商品 (多圖用逗號分開) | L6: =IF(I6="","待填",IF(ISNUMBER(SEARCH(".",I6)),"OK","記得加副檔名")) -> 待填 | M6: 商品 (多圖用逗號分開) | R6: =IF(N6="","待填",IF(ISNUMBER(SEARCH(".",N6)),"OK","記得加副檔名")) -> 待填
C7: 品名 | G7: =IF(D7="","限8字",IF(LENB(D7)/2<=8,"OK","超過")) -> 限8字 | H7: 品名 | L7: =IF(I7="","限8字",IF(LENB(I7)/2<=8,"OK","超過")) -> 限8字 | M7: 警語 | R7: =IF(N7="","限10字",IF(LENB(N7)/2<=10,"OK","超過")) -> 限10字
C8: 警語 | G8: =IF(D8="","限10字",IF(LENB(D8)/2<=10,"OK","超過")) -> 限10字
A11: 副區 | B11: 副區 一排3（左／中／右） 左：款式 1-4（A-1-4） 中：款式 2-1（A-2-1） 右：款式 2-2（A-2-2） Band 2 | C11: 左 | H11: 中 | M11: 右 | T11: 左 | X11: 中 | AC11: 右
C12: 促標 | G12: =IF(D12="","限8字",IF(LENB(D12)/2<=8,"OK","超過")) -> 限8字 | H12: 促標 | L12: =IF(I12="","限8字",IF(LENB(I12)/2<=8,"OK","超過")) -> 限8字 | M12: 促標 | R12: =IF(N12="","限8字",IF(LENB(N12)/2<=8,"OK","超過")) -> 限8字
C13: LOGO圖 | G13: =IF(D13="","待填","OK") -> 待填 | H13: LOGO圖 | L13: =IF(I13="","待填","OK") -> 待填 | M13: LOGO圖 | R13: =IF(N13="","待填","OK") -> 待填
C14: 商品 (多圖用逗號分開) | G14: =IF(D14="","待填",IF(ISNUMBER(SEARCH(".",D14)),"OK","記得加副檔名")) -> 待填 | H14: 商品 (多圖用逗號分開) | L14: =IF(I14="","待填",IF(ISNUMBER(SEARCH(".",I14)),"OK","記得加副檔名")) -> 待填 | M14: 商品 (多圖用逗號分開) | R14: =IF(N14="","待填",IF(ISNUMBER(SEARCH(".",N14)),"OK","記得加副檔名")) -> 待填
H15: 品名 | L15: =IF(I15="","限8字",IF(LENB(I15)/2<=8,"OK","超過")) -> 限8字 | M15: 品名 | R15: =IF(N15="","限8字",IF(LENB(N15)/2<=8,"OK","超過")) -> 限8字
H16: 警語 | L16: =IF(I16="","限10字",IF(LENB(I16)/2<=10,"OK","超過")) -> 限10字 | M16: 圓標 | R16: =IF(N16="","限5字",IF(LENB(N16)/2<=5,"OK","超過")) -> 限5字
H17: 圓標 | L17: =IF(I17="","限5字",IF(LENB(I17)/2<=5,"OK","超過")) -> 限5字
A19: 副區 | B19: 副區 一排3（左／中／右） 左：款式 2-3（A-2-3） 中：款式 2-4（A-2-4） 右：款式 3-1（A-3-1） Band 3 | C19: 左 | H19: 中 | M19: 右 | T19: 左 | X19: 中 | AC19: 右
C20: 促標 | G20: =IF(D20="","限8字",IF(LENB(D20)/2<=8,"OK","超過")) -> 限8字 | H20: 促標 | L20: =IF(I20="","限8字",IF(LENB(I20)/2<=8,"OK","超過")) -> 限8字 | M20: 促標 | R20: =IF(N20="","限8字",IF(LENB(N20)/2<=8,"OK","超過")) -> 限8字
C21: LOGO圖 | G21: =IF(D21="","待填","OK") -> 待填 | H21: LOGO圖 | L21: =IF(I21="","待填","OK") -> 待填 | M21: LOGO圖 | R21: =IF(N21="","待填","OK") -> 待填
C22: 商品 (多圖用逗號分開) | G22: =IF(D22="","待填",IF(ISNUMBER(SEARCH(".",D22)),"OK","記得加副檔名")) -> 待填 | H22: 商品 (多圖用逗號分開) | L22: =IF(I22="","待填",IF(ISNUMBER(SEARCH(".",I22)),"OK","記得加副檔名")) -> 待填 | M22: 商品 (多圖用逗號分開) | R22: =IF(N22="","待填",IF(ISNUMBER(SEARCH(".",N22)),"OK","記得加副檔名")) -> 待填
C23: 警語 | G23: =IF(D23="","限10字",IF(LENB(D23)/2<=10,"OK","超過")) -> 限10字 | H23: 圓標 | L23: =IF(I23="","限5字",IF(LENB(I23)/2<=5,"OK","超過")) -> 限5字 | M23: 品名 | R23: =IF(N23="","限8字",IF(LENB(N23)/2<=8,"OK","超過")) -> 限8字
C24: 圓標 | G24: =IF(D24="","限5字",IF(LENB(D24)/2<=5,"OK","超過")) -> 限5字 | M24: 警語 | R24: =IF(N24="","限10字",IF(LENB(N24)/2<=10,"OK","超過")) -> 限10字
M25: CTA | N25: 固定 icon（不需填寫） | R25: 鎖定
A27: 副區 | B27: 副區 一排3（左／中／右） 左：款式 3-2（A-3-2） 中：款式 3-3（A-3-3） 右：款式 3-4（A-3-4） Band 4 | C27: 左 | H27: 中 | M27: 右 | T27: 左 | X27: 中 | AC27: 右
C28: 促標 | G28: =IF(D28="","限8字",IF(LENB(D28)/2<=8,"OK","超過")) -> 限8字 | H28: 促標 | L28: =IF(I28="","限8字",IF(LENB(I28)/2<=8,"OK","超過")) -> 限8字 | M28: 促標 | R28: =IF(N28="","限8字",IF(LENB(N28)/2<=8,"OK","超過")) -> 限8字
C29: LOGO圖 | G29: =IF(D29="","待填","OK") -> 待填 | H29: LOGO圖 | L29: =IF(I29="","待填","OK") -> 待填 | M29: LOGO圖 | R29: =IF(N29="","待填","OK") -> 待填
C30: 商品 (多圖用逗號分開) | G30: =IF(D30="","待填",IF(ISNUMBER(SEARCH(".",D30)),"OK","記得加副檔名")) -> 待填 | H30: 商品 (多圖用逗號分開) | L30: =IF(I30="","待填",IF(ISNUMBER(SEARCH(".",I30)),"OK","記得加副檔名")) -> 待填 | M30: 商品 (多圖用逗號分開) | R30: =IF(N30="","待填",IF(ISNUMBER(SEARCH(".",N30)),"OK","記得加副檔名")) -> 待填
C31: 品名 | G31: =IF(D31="","限8字",IF(LENB(D31)/2<=8,"OK","超過")) -> 限8字 | H31: 警語 | L31: =IF(I31="","限10字",IF(LENB(I31)/2<=10,"OK","超過")) -> 限10字 | M31: CTA | N31: 固定 icon（不需填寫） | R31: 鎖定
C32: CTA | D32: 固定 icon（不需填寫） | G32: 鎖定 | H32: CTA | I32: 固定 icon（不需填寫） | L32: 鎖定
A35: 副區 | B35: 副區 一排3（左／中／右） 左：款式 4-1（A-4-1） 中：款式 4-2（A-4-2） 右：款式 4-3（A-4-3） Band 5 | C35: 左 | H35: 中 | M35: 右 | T35: 左 | X35: 中 | AC35: 右
C36: 促標 | G36: =IF(D36="","限8字",IF(LENB(D36)/2<=8,"OK","超過")) -> 限8字 | H36: 促標 | L36: =IF(I36="","限8字",IF(LENB(I36)/2<=8,"OK","超過")) -> 限8字 | M36: 促標 | R36: =IF(N36="","限8字",IF(LENB(N36)/2<=8,"OK","超過")) -> 限8字
C37: LOGO圖 | G37: =IF(D37="","待填","OK") -> 待填 | H37: LOGO圖 | L37: =IF(I37="","待填","OK") -> 待填 | M37: LOGO圖 | R37: =IF(N37="","待填","OK") -> 待填
C38: 商品 (多圖用逗號分開) | G38: =IF(D38="","待填",IF(ISNUMBER(SEARCH(".",D38)),"OK","記得加副檔名")) -> 待填 | H38: 商品 (多圖用逗號分開) | L38: =IF(I38="","待填",IF(ISNUMBER(SEARCH(".",I38)),"OK","記得加副檔名")) -> 待填 | M38: 商品 (多圖用逗號分開) | R38: =IF(N38="","待填",IF(ISNUMBER(SEARCH(".",N38)),"OK","記得加副檔名")) -> 待填
C39: 品名 | G39: =IF(D39="","限4字",IF(LENB(D39)/2<=4,"OK","超過")) -> 限4字 | H39: 品名 | L39: =IF(I39="","限8字",IF(LENB(I39)/2<=8,"OK","超過")) -> 限8字 | M39: 警語 | R39: =IF(N39="","限10字",IF(LENB(N39)/2<=10,"OK","超過")) -> 限10字
C40: 品名 | G40: =IF(D40="","限4字",IF(LENB(D40)/2<=4,"OK","超過")) -> 限4字 | H40: CTA | L40: =IF(I40="","限3字",IF(LENB(I40)/2<=3,"OK","超過")) -> 限3字 | M40: CTA | R40: =IF(N40="","限3字",IF(LENB(N40)/2<=3,"OK","超過")) -> 限3字
C41: 警語 | G41: =IF(D41="","限5字",IF(LENB(D41)/2<=5,"OK","超過")) -> 限5字
C42: CTA | G42: =IF(D42="","限3字",IF(LENB(D42)/2<=3,"OK","超過")) -> 限3字
A44: 副區 | B44: 副區 一排3（左／中／右） 左：款式 4-4（A-4-4） 中：款式 5-1（A-5-1） 右：款式 5-2（A-5-2） Band 6 | C44: 左 | H44: 中 | M44: 右 | T44: 左 | X44: 中 | AC44: 右
C45: 促標 | G45: =IF(D45="","限8字",IF(LENB(D45)/2<=8,"OK","超過")) -> 限8字 | H45: 促標 | L45: =IF(I45="","限8字",IF(LENB(I45)/2<=8,"OK","超過")) -> 限8字 | M45: 促標 | R45: =IF(N45="","限8字",IF(LENB(N45)/2<=8,"OK","超過")) -> 限8字
C46: LOGO圖 | G46: =IF(D46="","待填","OK") -> 待填 | H46: LOGO圖 | L46: =IF(I46="","待填","OK") -> 待填 | M46: LOGO圖 | R46: =IF(N46="","待填","OK") -> 待填
C47: 商品 (多圖用逗號分開) | G47: =IF(D47="","待填",IF(ISNUMBER(SEARCH(".",D47)),"OK","記得加副檔名")) -> 待填 | H47: 商品 (多圖用逗號分開) | L47: =IF(I47="","待填",IF(ISNUMBER(SEARCH(".",I47)),"OK","記得加副檔名")) -> 待填 | M47: 商品 (多圖用逗號分開) | R47: =IF(N47="","待填",IF(ISNUMBER(SEARCH(".",N47)),"OK","記得加副檔名")) -> 待填
...

Sheet 設定 (2)
A1: 等級 | B1: MSBN額度 | C1: 資源1 | D1: 資源2 | E1: 資源3 | F1: 資源4 | G1: 資源5 | H1: 資源6 | I1: 資源7 | J1: 資源8 | K1: 資源9 | L1: 資源10 | M1: 資源11 | N1: 資源12 | O1: 類型1 | P1: 類型2 | Q1: 類型3 | R1: 類型4 | S1: 類型5 | T1: 類型6 | U1: 類型7 | V1: 類型8 | W1: 類型9 | X1: 類型10 | Y1: 類型11 | Z1: 類型12 | AB1: key | AC1: 顯示名稱 | AD1: 張數 | AE1: 尺寸 | AF1: 格式 | AG1: 規範字數 | AH1: 提醒 | AI1: 系統排版 | AJ1: 可用
A2: A Brand star (Mega) | B2: 8 | AB2: DDCard | AC2: DD Card BN (APP) | AD2: 1 | AE2: 531×792 | AF2: JPG | AG2: 品牌名≤9；主標≤8；副標≤7；日期/警語≤14 | AH2: LOGO、商品圖；CTA 依版型 | AI2: ddcard方logo／ddcard橫logo | AJ2: 是
A3: A Brand star (Mega) 資交 | B3: 4 | AB3: HBN | AC3: HBN (PC) | AD3: 1 | AE3: 1200×360 | AF3: JPG | AG3: 品牌名≤9；主標≤8；副標≤7；日期/警語≤14 | AH3: 橫式或方形 LOGO 版 | AI3: HBN_橫式LOGO／HBN_方式LOGO | AJ3: 是
A4: A 精選套裝 | B4: 4 | AB4: 活動總覽 | AC4: 活動總覽 | AD4: 1 | AE4: 依活動規格 | AF4: JPG/PNG | AG4: 依活動需求 | AH4: 目前系統尚未提供可編輯版型 | AI4: 尚未提供版型 | AJ4: 否
A5: A 品牌旗艦MDD | B5: 6 | AB5: 首頁LOGO牆 | AC5: 首頁 LOGO 牆 | AD5: 1 | AE5: 402×483 | AF5: JPG/PNG | AG5: LOGO／人物或商品圖可縮放 | AH5: LOGO 位於曝品或人物範圍內，可用滑鼠縮放 | AI5: 首頁LOGO牆 | AJ5: 是
A6: A 品牌旗艦MDD 資交 | B6: 0 | AB6: AR | AC6: AR | AD6: 1 | AE6: 100×100（依規範） | AF6: JPG/PNG | AG6: 文案≤6 或 LOGO；2擇1 | AH6: 目前系統尚未提供可編輯版型 | AI6: 尚未提供版型 | AJ6: 否
A7: B+ BOD A | B7: 6 | C7: DDCard | D7: HBN | E7: 活動總覽 | F7: 首頁LOGO牆 | G7: AR | H7: FB_Post | I7: AMS BN | J7: Coin_page | K7: IG | L7: SearchIcon | M7: SearchImage | O7: 預設 | P7: 預設 | Q7: 預設 | R7: 預設 | S7: 預設 | T7: 預設 | U7: 預設 | V7: 選配 | W7: 選配 | X7: 選配 | Y7: 選配 | AB7: FB_Post | AC7: FB POST | AD7: 1 | AE7: 1200×630 | AF7: JPG | AG7: 品牌名≤9；主標≤8；副標≤7；日期/警語≤14 | AH7: 方 LOGO／橫 LOGO | AI7: FB_POST_方LOGO／FB_POST_橫LOGO | AJ7: 是
A8: B+ BOD A 資交 | B8: 0 | C8: DDCard | D8: HBN | E8: 活動總覽 | F8: 首頁LOGO牆 | G8: AR | H8: FB_Post | I8: AMS BN | J8: Coin_page | K8: IG | L8: SearchIcon | M8: SearchImage | O8: 預設 | P8: 預設 | Q8: 預設 | R8: 預設 | S8: 預設 | T8: 預設 | U8: 預設 | V8: 選配 | W8: 選配 | X8: 選配 | Y8: 選配 | AB8: AMS BN | AC8: AMS BN | AD8: 1 | AE8: 1077×264（依規範） | AF8: JPG | AG8: 依 AMS 規格 | AH8: 目前系統尚未提供可編輯版型 | AI8: 尚未提供版型 | AJ8: 否
A9: B+ BOD B (Mega) | B9: 6 | C9: DDCard | D9: HBN | E9: 活動總覽 | F9: 首頁LOGO牆 | G9: AR | H9: FB_Post | I9: AMS BN | J9: Coin_page | K9: IG | O9: 預設 | P9: 預設 | Q9: 預設 | R9: 預設 | S9: 預設 | T9: 選配 | U9: 選配 | V9: 選配 | W9: 選配 | AB9: Coin_page | AC9: Coin Page BN | AD9: 1 | AE9: 1200×391 | AF9: JPG | AG9: 品牌名≤9；主標≤8；副標≤7；日期/警語≤14 | AH9: 方 LOGO／橫 LOGO | AI9: Coin_pageBN_APP方LOGO／Coin_pageBN_APP橫LOGO | AJ9: 是
A10: B+ 基礎套裝 | B10: 6 | C10: DDCard | D10: HBN | E10: 活動總覽 | F10: 首頁LOGO牆 | G10: AR | H10: FB_Post | I10: AMS BN | J10: Coin_page | K10: IG | O10: 預設 | P10: 預設 | Q10: 預設 | R10: 預設 | S10: 預設 | T10: 選配 | U10: 選配 | V10: 選配 | W10: 選配 | AB10: IG | AC10: IG | AD10: 1 | AE10: 900×1600 | AF10: JPG | AG10: 品牌名≤9；主標≤8；副標≤7；日期/警語≤14 | AH10: 方 LOGO／橫 LOGO | AI10: IG方logo排版／IG橫logo排版 | AJ10: 是
A11: B JBP多店 | B11: 3 | C11: IG | D11: HBN | E11: DDCard | F11: Coin_page | G11: FB_Post | H11: SCPN | I11: SearchImage | J11: SearchIcon | O11: 預設 | P11: 預設 | Q11: 預設 | R11: 預設 | S11: 預設 | T11: 預設 | U11: 預設 | V11: 預設 | AB11: SearchIcon | AC11: Search ICON | AD11: 1 | AE11: 120×120＋84×84 | AF11: PNG | AG11: ICON 文案≤2；或 LOGO／商品圖 | AH11: 120×120 建議 <50KB，另輸出 84×84 | AI11: SearchICON_LOGO／PRODUCT／TEXT | AJ11: 是
A12: B 金牌 (Mega) | B12: 3 | C12: DDCard | D12: HBN | E12: 活動總覽 | F12: AR | G12: Coin_page | O12: 預設 | P12: 預設 | Q12: 預設 | R12: 預設 | S12: 選配 | AB12: SearchImage | AC12: Search Image | AD12: 1 | AE12: 1125×156 | AF12: JPG/PNG | AG12: 副標≤7；LOGO 1～3 個 | AH12: 依選用版型提供 1～3 個 LOGO | AI12: Search_Image1logo／2logo／3logo | AJ12: 是
AB13: SCPN | AC13: SCBN／SCPN | AD13: 1 | AE13: 1200×200 | AF13: JPG | AG13: 品牌名≤9；副標≤7；CTA | AH13: 商城橫幅 | AI13: SCBN_APP | AJ13: 是

Sheet _BODA_META (2)
A1: BODA_WORKORDER_V2
A2: kind | B2: sourceKey | C2: band | D2: order | E2: family | F2: variant | G2: combo | H2: msbnFile | I2: position | J2: label | K2: address | L2: header | M2: file | N2: locked | O2: hint | P2: targetKey
A3: subarea | B3: msbn-sub:0:0 | C3: 1 | D3: 1 | E3: A | F3: 1 | G3: 1 | I3: 1 | J3: 促標 | K3: D4 | L3: 款式 1-1 | M3: 副區-A-1-1.jpg | N3: 0 | O3: 限8個字
A4: subarea | B4: msbn-sub:0:0 | C4: 1 | D4: 1 | E4: A | F4: 1 | G4: 1 | I4: 1 | J4: LOGO圖 | K4: D5 | L4: 款式 1-1 | M4: 副區-A-1-1.jpg | N4: 0 | O4: (檔名/券名)
A5: subarea | B5: msbn-sub:0:0 | C5: 1 | D5: 1 | E5: A | F5: 1 | G5: 1 | I5: 1 | J5: 商品 | K5: D6 | L5: 款式 1-1 | M5: 副區-A-1-1.jpg | N5: 0 | O5: (檔名/券名)
A6: subarea | B6: msbn-sub:0:0 | C6: 1 | D6: 1 | E6: A | F6: 1 | G6: 1 | I6: 1 | J6: 品名 | K6: D7 | L6: 款式 1-1 | M6: 副區-A-1-1.jpg | N6: 0 | O6: 限8個字
A7: subarea | B7: msbn-sub:0:0 | C7: 1 | D7: 1 | E7: A | F7: 1 | G7: 1 | I7: 1 | J7: 警語 | K7: D8 | L7: 款式 1-1 | M7: 副區-A-1-1.jpg | N7: 0 | O7: 限10個字
A8: subarea | B8: msbn-sub:0:1 | C8: 1 | D8: 2 | E8: A | F8: 1 | G8: 2 | I8: 2 | J8: 促標 | K8: I4 | L8: 款式 1-2 | M8: 副區-A-1-2.jpg | N8: 0 | O8: 限8個字
A9: subarea | B9: msbn-sub:0:1 | C9: 1 | D9: 2 | E9: A | F9: 1 | G9: 2 | I9: 2 | J9: LOGO圖 | K9: I5 | L9: 款式 1-2 | M9: 副區-A-1-2.jpg | N9: 0 | O9: (檔名/券名)
A10: subarea | B10: msbn-sub:0:1 | C10: 1 | D10: 2 | E10: A | F10: 1 | G10: 2 | I10: 2 | J10: 商品 | K10: I6 | L10: 款式 1-2 | M10: 副區-A-1-2.jpg | N10: 0 | O10: (檔名/券名)
A11: subarea | B11: msbn-sub:0:1 | C11: 1 | D11: 2 | E11: A | F11: 1 | G11: 2 | I11: 2 | J11: 品名 | K11: I7 | L11: 款式 1-2 | M11: 副區-A-1-2.jpg | N11: 0 | O11: 限8個字
A12: subarea | B12: msbn-sub:0:2 | C12: 1 | D12: 3 | E12: A | F12: 1 | G12: 3 | I12: 3 | J12: 促標 | K12: N4 | L12: 款式 1-3 | M12: 副區-A-1-3.jpg | N12: 0 | O12: 限8個字
A13: subarea | B13: msbn-sub:0:2 | C13: 1 | D13: 3 | E13: A | F13: 1 | G13: 3 | I13: 3 | J13: LOGO圖 | K13: N5 | L13: 款式 1-3 | M13: 副區-A-1-3.jpg | N13: 0 | O13: (檔名/券名)
A14: subarea | B14: msbn-sub:0:2 | C14: 1 | D14: 3 | E14: A | F14: 1 | G14: 3 | I14: 3 | J14: 商品 | K14: N6 | L14: 款式 1-3 | M14: 副區-A-1-3.jpg | N14: 0 | O14: (檔名/券名)
... A352: subarea | B352: msbn-sub:31:3 | C352: 32 | D352: 75 | E352: F | F352: 1 | G352: 1 | I352: 4 | J352: 警語 | K352: P258 | L352: 款式 1-1 | M352: 副區-F-1-1.jpg | N352: 0 | O352: 限6個字
A353: msbn | B353: msbn:32 | C353: 33 | D353: 76 | H353: MSBN-A-1-1.jpg | I353: 1 | J353: 促標 | K353: D263 | L353: MSBN-A-1-1 | M353: MSBN-A-1-1.jpg | N353: 0 | O353: 促標最多7字內
A354: msbn | B354: msbn:32 | C354: 33 | D354: 76 | H354: MSBN-A-1-1.jpg | I354: 1 | J354: 商品 | K354: L263 | L354: MSBN-A-1-1 | M354: MSBN-A-1-1.jpg | N354: 0 | O354: (圖檔名)
A355: msbn | B355: msbn:32 | C355: 33 | D355: 76 | H355: MSBN-A-1-1.jpg | I355: 1 | J355: 品名 | K355: D264 | L355: MSBN-A-1-1 | M355: MSBN-A-1-1.jpg | N355: 0 | O355: 品名一排最多8字
A356: msbn | B356: msbn:32 | C356: 33 | D356: 76 | H356: MSBN-A-1-1.jpg | I356: 1 | J356: 代言人圖 | K356: L264 | L356: MSBN-A-1-1 | M356: MSBN-A-1-1.jpg | N356: 0 | O356: (圖檔名)
A357: msbn | B357: msbn:32 | C357: 33 | D357: 76 | H357: MSBN-A-1-1.jpg | I357: 1 | J357: 品名 | K357: D265 | L357: MSBN-A-1-1 | M357: MSBN-A-1-1.jpg | N357: 0 | O357: 品名一排最多8字
A358: msbn | B358: msbn:32 | C358: 33 | D358: 76 | H358: MSBN-A-1-1.jpg | I358: 1 | J358: 圓標 | K358: L265 | L358: MSBN-A-1-1 | M358: MSBN-A-1-1.jpg | N358: 0 | O358: 圓標05字內
A359: msbn | B359: msbn:32 | C359: 33 | D359: 76 | H359: MSBN-A-1-1.jpg | I359: 1 | J359: 警語 | K359: D266 | L359: MSBN-A-1-1 | M359: MSBN-A-1-1.jpg | N359: 0 | O359: 小字最多可9個字內
A360: msbn | B360: msbn:32 | C360: 33 | D360: 76 | H360: MSBN-A-1-1.jpg | I360: 1 | J360: 簽名小字 | K360: L266 | L360: MSBN-A-1-1 | M360: MSBN-A-1-1.jpg | N360: 0 | O360: 每行限5字
A361: msbn | B361: msbn:32 | C361: 33 | D361: 76 | H361: MSBN-A-1-1.jpg | I361: 1 | J361: 簽名小字 | K361: L267 | L361: MSBN-A-1-1 | M361: MSBN-A-1-1.jpg | N361: 0 | O361: 每行限5字
A362: msbn | B362: msbn:32 | C362: 33 | D362: 76 | H362: MSBN-A-1-1.jpg | I362: 1 | J362: 簽名圖 | K362: L268 | L362: MSBN-A-1-1 | M362: MSBN-A-1-1.jpg | N362: 0 | O362: (檔名)
A363: msbn | B363: msbn:32 | C363: 33 | D363: 76 | H363: MSBN-A-1-1.jpg | I363: 1 | J363: CTA | K363: L269 | L363: MSBN-A-1-1 | M363: MSBN-A-1-1.jpg | N363: 0 | O363: 逛逛去
A364: msbn | B364: msbn:33 | C364: 34 | D364: 77 | H364: MSBN-A-1-2.jpg | I364: 1 | J364: 商品 | K364: D272 | L364: MSBN-A-1-2 | M364: MSBN-A-1-2.jpg | N364: 0 | O364: (圖檔名)
... A553: msbn | B553: msbn:52 | C553: 53 | D553: 96 | H553: MSBN-B-4-2.jpg | I553: 4 | J553: 警語 | K553: P433 | L553: MSBN-B-4-2 | M553: MSBN-B-4-2.jpg | N553: 0 | O553: 小字警語6字
A554: msbn | B554: msbn:53 | C554: 54 | D554: 97 | H554: MSBN-C-1-1.jpg | I554: 1 | J554: 促標 | K554: D438 | L554: MSBN-C-1-1 | M554: MSBN-C-1-1.jpg | N554: 0 | O554: 促標最多7字內 | P554: promo
A555: msbn | B555: msbn:53 | C555: 54 | D555: 97 | H555: MSBN-C-1-1.jpg | I555: 1 | J555: 警語 | K555: D439 | L555: MSBN-C-1-1 | M555: MSBN-C-1-1.jpg | N555: 0 | O555: 小字最多可10個字以內 | P555: warn
A556: msbn | B556: msbn:53 | C556: 54 | D556: 97 | H556: MSBN-C-1-1.jpg | I556: 1 | J556: 文案 | K556: D441 | L556: MSBN-C-1-1 | M556: MSBN-C-1-1.jpg | N556: 0 | O556: 文案一排最多6字 | P556: copy2
A557: msbn | B557: msbn:53 | C557: 54 | D557: 97 | H557: MSBN-C-1-1.jpg | I557: 1 | J557: LOGO圖 | K557: L441 | L557: MSBN-C-1-1 | M557: MSBN-C-1-1.jpg | N557: 0 | O557: (檔名/券名) | P557: logoImg
A558: msbn | B558: msbn:53 | C558: 54 | D558: 97 | H558: MSBN-C-1-1.jpg | I558: 1 | J558: 文案 | K558: D442 | L558: MSBN-C-1-1 | M558: MSBN-C-1-1.jpg | N558: 0 | O558: 文案一排最多6字 | P558: copy2
A559: msbn | B559: msbn:53 | C559: 54 | D559: 97 | H559: MSBN-C-1-1.jpg | I559: 1 | J559: 文案 | K559: L442 | L559: MSBN-C-1-1 | M559: MSBN-C-1-1.jpg | N559: 0 | O559: 文案一排最多6字 | P559: copy
A560: msbn | B560: msbn:53 | C560: 54 | D560: 97 | H560: MSBN-C-1-1.jpg | I560: 1 | J560: 文案 | K560: L443 | L560: MSBN-C-1-1 | M560: MSBN-C-1-1.jpg | N560: 0 | O560: 文案一排最多6字 | P560: copy
A561: msbn | B561: msbn:54 | C561: 55 | D561: 98 | H561: MSBN-C-1-2.jpg | I561: 1 | J561: 促標 | K561: D449 | L561: MSBN-C-1-2 | M561: MSBN-C-1-2.jpg | N561: 0 | O561: 促標最多7字內 | P561: promo
A562: msbn | B562: msbn:54 | C562: 55 | D562: 98 | H562: MSBN-C-1-2.jpg | I562: 1 | J562: 警語 | K562: D450 | L562: MSBN-C-1-2 | M562: MSBN-C-1-2.jpg | N562: 0 | O562: 小字最多可10個字以內 | P562: warn
A563: msbn | B563: msbn:54 | C563: 55 | D563: 98 | H563: MSBN-C-1-2.jpg | I563: 1 | J563: 文案 | K563: D452 | L563: MSBN-C-1-2 | M563: MSBN-C-1-2.jpg | N563: 0 | O563: 文案一排最多6字 | P563: copy2
A564: msbn | B564: msbn:54 | C564: 55 | D564: 98 | H564: MSBN-C-1-2.jpg | I564: 1 | J564: LOGO圖 | K564: L452 | L564: MSBN-C-1-2 | M564: MSBN-C-1-2.jpg | N564: 0 | O564: (檔名/券名) | P564: logoImg
A565: msbn | B565: msbn:54 | C565: 55 | D565: 98 | H565: MSBN-C-1-2.jpg | I565: 1 | J565: 文案 | K565: D453 | L565: MSBN-C-1-2 | M565: MSBN-C-1-2.jpg | N565: 0 | O565: 文案一排最多6字 | P565: copy2
...

Sheet _BODA_BOTTOM (2)
A1: BODA_BOTTOM_V1 | B1: MS Layout
A2: group | B2: title | C2: iconAddress | D2: logoAddress | E2: textAddress | F2: countAddress | G2: optional
A3: 1 | B3: 第1顆 | C3: E561 | D3: E562 | E3: C563 | F3: G563 | G3: 0
A4: 2 | B4: 第2顆 | C4: J561 | D4: J562 | E4: H563 | F4: L563 | G4: 0
A5: 3 | B5: 第3顆 | C5: O561 | D5: O562 | E5: M563 | F5: Q563 | G5: 1
A6: 4 | B6: 第4顆 | C6: T561 | D6: T562 | E6: R563 | F6: Y563 | G6: 1
A7: 5 | B7: 第5顆 | C7: AB561 | D7: AB562 | E7: Z563 | F7: AG563 | G7: 1

Sheet _BODA_BOTTOM_STATE (2)

Sheet _BODA_RULES (2)
A1: keyword | B1: replacement | C1: action
A2: 撒 | B2: 自動改成"灑" | C2: replace
A3: 購物金 | B3: 自動改成"優惠券" | C3: replace
A4: 抵用券 | B4: 自動改成"優惠券" | C4: replace
A5: 折價券 | B5: 自動改成"優惠券" | C5: replace
A6: 蝦皮券 | B6: 自動改成"優惠券" | C6: replace
A7: 蝦幣券 | B7: 自動改成"優惠券" | C7: replace
A8: 折扣券 | B8: 自動改成"優惠券" | C8: replace
A9: $蝦幣 | B9: 自動改成"蝦幣" | C9: replace
A10: 蝦幣$ | B10: 自動改成"蝦幣" | C10: replace
A11: \$\d+\s*蝦幣 | B11: 自動改成"蝦幣" | C11: replace
A12: 元 | B12: 直接無法輸入 | C12: block
... A69: 兩 | B69: 自動改成"2" | C69: replace
